Workbook
Name BankTbl: Sync!$A$6:$D$15
Name CustTbl: Sync!$F$6:$G$205
Name SuppTbl: Sync!$I$6:$J$105
Name AcctTbl: Sync!$L$6:$M$55
Name StaffTbl: Sync!$O$6:$P$55
Name CustCodes: Sync!$F$6:$F$205
Name SuppCodes: Sync!$I$6:$I$105
Name AcctCodes: Sync!$L$6:$L$55
Name StaffCodes: Sync!$O$6:$O$55
Name ListBanks: OFFSET(Sync!$AT$6,0,0,MAX(COUNTIF(Sync!$AT$6:$AT$15,"?*"),1),1)
Name ListPartyTypes: OFFSET(Sync!$AO$6,0,0,MAX(COUNTIF(Sync!$AO$6:$AO$25,"?*"),1),1)
Name ListTxnTypes: OFFSET(Sync!$AQ$6,0,0,MAX(COUNTIF(Sync!$AQ$6:$AQ$19,"?*"),1),1)
Name CalcBank: Calc!$G$9:$G$2008
Name CalcKey: Calc!$H$9:$H$2008
Name CalcRankKey: Calc!$J$9:$J$2008
Name CalcNormDate: Calc!$E$9:$E$2008
Name CalcTime: Calc!$F$9:$F$2008
Name CalcMonth: Calc!$K$9:$K$2008
Name CalcDep: Calc!$L$9:$L$2008
Name CalcWit: Calc!$M$9:$M$2008
Name EntryDates: Entry!$C$9:$C$2008
Name EntryTimes: Entry!$D$9:$D$2008
Name EntryBanks: Entry!$E$9:$E$2008
Name EntryParty: Entry!$G$9:$G$2008
Name EntryPartyName: Entry!$H$9:$H$2008
Name EntryPartyType: Entry!$I$9:$I$2008
Name EntryTxnType: Entry!$J$9:$J$2008
Name EntryDep: Entry!$K$9:$K$2008
Name EntryWit: Entry!$L$9:$L$2008
Name EntryMan: Entry!$M$9:$M$2008
Name EntryTxnID: Entry!$B$9:$B$2008
Name EntryNotes: Entry!$P$9:$P$2008

Sheet Entry
A1: =IF(Sync!$AJ$6="","مازندشت",Sync!$AJ$6)&" — "&IF(Sync!$AJ$9="","سورتینگ و بسته‌بندی مرکبات",Sync!$AJ$9)
A2: =IF(Sync!$AJ$7="","باغدشت، بخش مرکزی، شهرستان قائم‌شهر، استان مازندران، ایران",Sync!$AJ$7)&" | MAZANDASHT · CITRUS SORTING & PACKING"
A3: ثبت تراکنش‌های بانکی — ورود داده (Entry)
A4: ستون‌های زرد = ورود دستی شما | ستون‌های خاکستری = خودکار. تاریخ: 1405/07/10 (یا 14050710) — ساعت: 09:30 (یا 9:30) — بانک و نوع‌ها از کشویی انتخاب شوند — کد طرف حساب را تایپ کنید (مثل C001 یا S001 یا X001) تا نامش بیاید.
A5: تعداد ردیف ثبت‌شده | D5: جمع واریز (ریال) | G5: جمع برداشت (ریال) | J5: تعداد √ منطبق | L5: تعداد × مغایر | N5: ظرفیت باقی‌مانده
A6: =COUNTA($C$9:$C$2008) | D6: =SUM($K$9:$K$2008) | G6: =SUM($L$9:$L$2008) | J6: =COUNTIF($O$9:$O$2008,"√") | L6: =COUNTIF($O$9:$O$2008,"×") | N6: =2000-COUNTA($C$9:$C$2008)
A7: ردیف | B7: شناسه | C7: تاریخ | D7: ساعت | E7: بانک | F7: نام بانک | G7: کد طرف حساب | H7: نام طرف حساب | I7: نوع طرف حساب | J7: نوع تراکنش | K7: مبلغ واریز (ریال) | L7: مبلغ برداشت (ریال) | M7: موجودی بانک (ریال) | N7: موجودی سیستم (ریال) | O7: وضعیت | P7: توضیحات
A8: No. | B8: TxnID | C8: Date | D8: Time | E8: Bank | F8: Bank Name | G8: Party Code | H8: Party | I8: Party Type | J8: Txn Type | K8: Deposit | L8: Withdrawal | M8: Bank Balance | N8: System Balance | O8: Status | P8: Notes
A9: =IF($C9="","",COUNTA($C$9:$C9)) | B9: =IF($C9="","","TXN-"&RIGHT("0000"&1,4)) | C9: 1405/07/01 | D9: 08:30 | E9: BANK01 – ملت — جاری شرکت | F9: =IF($E9="","",IFERROR(IF(VLOOKUP(LEFT(UPPER(TRIM($E9)),6),BankTbl,2,0)="","(بدون عنوان)",VLOOKUP(LEFT(UPPER(TRIM($E9)),6),BankTbl,2,0)),"بانک ناشناخته")) | G9: C001 | H9: =IF($G9="","",IFERROR(VLOOKUP($G9,CustTbl,2,0),IFERROR(VLOOKUP($G9,SuppTbl,2,0),IFERROR(VLOOKUP($G9,AcctTbl,2,0),IFERROR(VLOOKUP($G9,StaffTbl,2,0),"کد ناشناخته"))))) | I9: مشتری عمده | J9: واریز | K9: 250000000 | M9: 750000000 | N9: =IF(OR($C9="",$E9="",Calc!$H9=""),"",IFERROR(VLOOKUP(LEFT(UPPER(TRIM($E9)),6),BankTbl,3,0),0)+SUMIFS(CalcDep,CalcBank,LEFT(UPPER(TRIM($E9)),6),CalcKey,"<="&Calc!$H9)-SUMIFS(CalcWit,CalcBank,LEFT(UPPER(TRIM($E9)),6),CalcKey,"<="&Calc!$H9)) | O9: =IF(OR($C9="",$M9=""),"",IF($N9="","؟",IF(ROUND($M9-$N9,0)=0,"√","×"))) | P9: واریز بابت خرید مرکبات (ردیف نمونه)
A10: =IF($C10="","",COUNTA($C$9:$C10)) | B10: =IF($C10="","","TXN-"&RIGHT("0000"&2,4)) | C10: 1405/07/01 | D10: 10:15 | E10: BANK01 – ملت — جاری شرکت | F10: =IF($E10="","",IFERROR(IF(VLOOKUP(LEFT(UPPER(TRIM($E10)),6),BankTbl,2,0)="","(بدون عنوان)",VLOOKUP(LEFT(UPPER(TRIM($E10)),6),BankTbl,2,0)),"بانک ناشناخته")) | G10: X001 | H10: =IF($G10="","",IFERROR(VLOOKUP($G10,CustTbl,2,0),IFERROR(VLOOKUP($G10,SuppTbl,2,0),IFERROR(VLOOKUP($G10,AcctTbl,2,0),IFERROR(VLOOKUP($G10,StaffTbl,2,0),"کد ناشناخته"))))) | I10: حساب اداری/داخلی | J10: برداشت | L10: 1200000 | M10: 748800000 | N10: =IF(OR($C10="",$E10="",Calc!$H10=""),"",IFERROR(VLOOKUP(LEFT(UPPER(TRIM($E10)),6),BankTbl,3,0),0)+SUMIFS(CalcDep,CalcBank,LEFT(UPPER(TRIM($E10)),6),CalcKey,"<="&Calc!$H10)-SUMIFS(CalcWit,CalcBank,LEFT(UPPER(TRIM($E10)),6),CalcKey,"<="&Calc!$H10)) | O10: =IF(OR($C10="",$M10=""),"",IF($N10="","؟",IF(ROUND($M10-$N10,0)=0,"√","×"))) | P10: کارمزد بانکی (نمونه)
A11: =IF($C11="","",COUNTA($C$9:$C11)) | B11: =IF($C11="","","TXN-"&RIGHT("0000"&3,4)) | C11: 1405/07/02 | D11: 09:00 | E11: BANK01 – ملت — جاری شرکت | F11: =IF($E11="","",IFERROR(IF(VLOOKUP(LEFT(UPPER(TRIM($E11)),6),BankTbl,2,0)="","(بدون عنوان)",VLOOKUP(LEFT(UPPER(TRIM($E11)),6),BankTbl,2,0)),"بانک ناشناخته")) | G11: S002 | H11: =IF($G11="","",IFERROR(VLOOKUP($G11,CustTbl,2,0),IFERROR(VLOOKUP($G11,SuppTbl,2,0),IFERROR(VLOOKUP($G11,AcctTbl,2,0),IFERROR(VLOOKUP($G11,StaffTbl,2,0),"کد ناشناخته"))))) | I11: حجره‌دار میدان بار | J11: برداشت | L11: 80000000 | M11: 668800000 | N11: =IF(OR($C11="",$E11="",Calc!$H11=""),"",IFERROR(VLOOKUP(LEFT(UPPER(TRIM($E11)),6),BankTbl,3,0),0)+SUMIFS(CalcDep,CalcBank,LEFT(UPPER(TRIM($E11)),6),CalcKey,"<="&Calc!$H11)-SUMIFS(CalcWit,CalcBank,LEFT(UPPER(TRIM($E11)),6),CalcKey,"<="&Calc!$H11)) | O11: =IF(OR($C11="",$M11=""),"",IF($N11="","؟",IF(ROUND($M11-$N11,0)=0,"√","×"))) | P11: خرید پرتقال از میدان بار (نمونه)
A12: =IF($C12="","",COUNTA($C$9:$C12)) | B12: =IF($C12="","","TXN-"&RIGHT("0000"&4,4)) | C12: 1405/07/02 | D12: 12:45 | E12: BANK02 – صادرات — جاری شرکت | F12: =IF($E12="","",IFERROR(IF(VLOOKUP(LEFT(UPPER(TRIM($E12)),6),BankTbl,2,0)="","(بدون عنوان)",VLOOKUP(LEFT(UPPER(TRIM($E12)),6),BankTbl,2,0)),"بانک ناشناخته")) | G12: C002 | H12: =IF($G12="","",IFERROR(VLOOKUP($G12,CustTbl,2,0),IFERROR(VLOOKUP($G12,SuppTbl,2,0),IFERROR(VLOOKUP($G12,AcctTbl,2,0),IFERROR(VLOOKUP($G12,StaffTbl,2,0),"کد ناشناخته"))))) | I12: مشتری صادراتی | J12: واریز | K12: 90000000 | M12: 215000000 | N12: =IF(OR($C12="",$E12="",Calc!$H12=""),"",IFERROR(VLOOKUP(LEFT(UPPER(TRIM($E12)),6),BankTbl,3,0),0)+SUMIFS(CalcDep,CalcBank,LEFT(UPPER(TRIM($E12)),6),CalcKey,"<="&Calc!$H12)-SUMIFS(CalcWit,CalcBank,LEFT(UPPER(TRIM($E12)),6),CalcKey,"<="&Calc!$H12)) | O12: =IF(OR($C12="",$M12=""),"",IF($N12="","؟",IF(ROUND($M12-$N12,0)=0,"√","×"))) | P12: واریز مشتری — مغایرت عمدی برای نمایش × (نمونه)
A13: =IF($C13="","",COUNTA($C$9:$C13)) | B13: =IF($C13="","","TXN-"&RIGHT("0000"&5,4)) | C13: 1405/07/03 | D13: 11:20 | E13: BANK02 – صادرات — جاری شرکت | F13: =IF($E13="","",IFERROR(IF(VLOOKUP(LEFT(UPPER(TRIM($E13)),6),BankTbl,2,0)="","(بدون عنوان)",VLOOKUP(LEFT(UPPER(TRIM($E13)),6),BankTbl,2,0)),"بانک ناشناخته")) | G13: X003 | H13: =IF($G13="","",IFERROR(VLOOKUP($G13,CustTbl,2,0),IFERROR(VLOOKUP($G13,SuppTbl,2,0),IFERROR(VLOOKUP($G13,AcctTbl,2,0),IFERROR(VLOOKUP($G13,StaffTbl,2,0),"کد ناشناخته"))))) | I13: حساب اداری/داخلی | J13: برداشت | L13: 15000000 | N13: =IF(OR($C13="",$E13="",Calc!$H13=""),"",IFERROR(VLOOKUP(LEFT(UPPER(TRIM($E13)),6),BankTbl,3,0),0)+SUMIFS(CalcDep,CalcBank,LEFT(UPPER(TRIM($E13)),6),CalcKey,"<="&Calc!$H13)-SUMIFS(CalcWit,CalcBank,LEFT(UPPER(TRIM($E13)),6),CalcKey,"<="&Calc!$H13)) | O13: =IF(OR($C13="",$M13=""),"",IF($N13="","؟",IF(ROUND($M13-$N13,0)=0,"√","×"))) | P13: برداشت نقدی به صندوق — بدون کنترل مانده (نمونه)
A14: =IF($C14="","",COUNTA($C$9:$C14)) | B14: =IF($C14="","","TXN-"&RIGHT("0000"&6,4)) | C14: 1405/07/01 | D14: 08:30 | E14: BANK01 – ملت — جاری شرکت | F14: =IF($E14="","",IFERROR(IF(VLOOKUP(LEFT(UPPER(TRIM($E14)),6),BankTbl,2,0)="","(بدون عنوان)",VLOOKUP(LEFT(UPPER(TRIM($E14)),6),BankTbl,2,0)),"بانک ناشناخته")) | G14: C001 | H14: =IF($G14="","",IFERROR(VLOOKUP($G14,CustTbl,2,0),IFERROR(VLOOKUP($G14,SuppTbl,2,0),IFERROR(VLOOKUP($G14,AcctTbl,2,0),IFERROR(VLOOKUP($G14,StaffTbl,2,0),"کد ناشناخته"))))) | I14: مشتری عمده | J14: واریز | K14: 250000000 | M14: 750000000 | N14: =IF(OR($C14="",$E14="",Calc!$H14=""),"",IFERROR(VLOOKUP(LEFT(UPPER(TRIM($E14)),6),BankTbl,3,0),0)+SUMIFS(CalcDep,CalcBank,LEFT(UPPER(TRIM($E14)),6),CalcKey,"<="&Calc!$H14)-SUMIFS(CalcWit,CalcBank,LEFT(UPPER(TRIM($E14)),6),CalcKey,"<="&Calc!$H14)) | O14: =IF(OR($C14="",$M14=""),"",IF($N14="","؟",IF(ROUND($M14-$N14,0)=0,"√","×"))) | P14: ردیف تکراری — اثر آن را بر ستون وضعیت ببینید (نمونه)
A15: =IF($C15="","",COUNTA($C$9:$C15)) | B15: =IF($C15="","","TXN-"&RIGHT("0000"&7,4)) | F15: =IF($E15="","",IFERROR(IF(VLOOKUP(LEFT(UPPER(TRIM($E15)),6),BankTbl,2,0)="","(بدون عنوان)",VLOOKUP(LEFT(UPPER(TRIM($E15)),6),BankTbl,2,0)),"بانک ناشناخته")) | H15: =IF($G15="","",IFERROR(VLOOKUP($G15,CustTbl,2,0),IFERROR(VLOOKUP($G15,SuppTbl,2,0),IFERROR(VLOOKUP($G15,AcctTbl,2,0),IFERROR(VLOOKUP($G15,StaffTbl,2,0),"کد ناشناخته"))))) | N15: =IF(OR($C15="",$E15="",Calc!$H15=""),"",IFERROR(VLOOKUP(LEFT(UPPER(TRIM($E15)),6),BankTbl,3,0),0)+SUMIFS(CalcDep,CalcBank,LEFT(UPPER(TRIM($E15)),6),CalcKey,"<="&Calc!$H15)-SUMIFS(CalcWit,CalcBank,LEFT(UPPER(TRIM($E15)),6),CalcKey,"<="&Calc!$H15)) | O15: =IF(OR($C15="",$M15=""),"",IF($N15="","؟",IF(ROUND($M15-$N15,0)=0,"√","×")))
A16: =IF($C16="","",COUNTA($C$9:$C16)) | B16: =IF($C16="","","TXN-"&RIGHT("0000"&8,4)) | F16: =IF($E16="","",IFERROR(IF(VLOOKUP(LEFT(UPPER(TRIM($E16)),6),BankTbl,2,0)="","(بدون عنوان)",VLOOKUP(LEFT(UPPER(TRIM($E16)),6),BankTbl,2,0)),"بانک ناشناخته")) | H16: =IF($G16="","",IFERROR(VLOOKUP($G16,CustTbl,2,0),IFERROR(VLOOKUP($G16,SuppTbl,2,0),IFERROR(VLOOKUP($G16,AcctTbl,2,0),IFERROR(VLOOKUP($G16,StaffTbl,2,0),"کد ناشناخته"))))) | N16: =IF(OR($C16="",$E16="",Calc!$H16=""),"",IFERROR(VLOOKUP(LEFT(UPPER(TRIM($E16)),6),BankTbl,3,0),0)+SUMIFS(CalcDep,CalcBank,LEFT(UPPER(TRIM($E16)),6),CalcKey,"<="&Calc!$H16)-SUMIFS(CalcWit,CalcBank,LEFT(UPPER(TRIM($E16)),6),CalcKey,"<="&Calc!$H16)) | O16: =IF(OR($C16="",$M16=""),"",IF($N16="","؟",IF(ROUND($M16-$N16,0)=0,"√","×")))
A17: =IF($C17="","",COUNTA($C$9:$C17)) | B17: =IF($C17="","","TXN-"&RIGHT("0000"&9,4)) | F17: =IF($E17="","",IFERROR(IF(VLOOKUP(LEFT(UPPER(TRIM($E17)),6),BankTbl,2,0)="","(بدون عنوان)",VLOOKUP(LEFT(UPPER(TRIM($E17)),6),BankTbl,2,0)),"بانک ناشناخته")) | H17: =IF($G17="","",IFERROR(VLOOKUP($G17,CustTbl,2,0),IFERROR(VLOOKUP($G17,SuppTbl,2,0),IFERROR(VLOOKUP($G17,AcctTbl,2,0),IFERROR(VLOOKUP($G17,StaffTbl,2,0),"کد ناشناخته"))))) | N17: =IF(OR($C17="",$E17="",Calc!$H17=""),"",IFERROR(VLOOKUP(LEFT(UPPER(TRIM($E17)),6),BankTbl,3,0),0)+SUMIFS(CalcDep,CalcBank,LEFT(UPPER(TRIM($E17)),6),CalcKey,"<="&Calc!$H17)-SUMIFS(CalcWit,CalcBank,LEFT(UPPER(TRIM($E17)),6),CalcKey,"<="&Calc!$H17)) | O17: =IF(OR($C17="",$M17=""),"",IF($N17="","؟",IF(ROUND($M17-$N17,0)=0,"√","×")))
A18: =IF($C18="","",COUNTA($C$9:$C18)) | B18: =IF($C18="","","TXN-"&RIGHT("0000"&10,4)) | F18: =IF($E18="","",IFERROR(IF(VLOOKUP(LEFT(UPPER(TRIM($E18)),6),BankTbl,2,0)="","(بدون عنوان)",VLOOKUP(LEFT(UPPER(TRIM($E18)),6),BankTbl,2,0)),"بانک ناشناخته")) | H18: =IF($G18="","",IFERROR(VLOOKUP($G18,CustTbl,2,0),IFERROR(VLOOKUP($G18,SuppTbl,2,0),IFERROR(VLOOKUP($G18,AcctTbl,2,0),IFERROR(VLOOKUP($G18,StaffTbl,2,0),"کد ناشناخته"))))) | N18: =IF(OR($C18="",$E18="",Calc!$H18=""),"",IFERROR(VLOOKUP(LEFT(UPPER(TRIM($E18)),6),BankTbl,3,0),0)+SUMIFS(CalcDep,CalcBank,LEFT(UPPER(TRIM($E18)),6),CalcKey,"<="&Calc!$H18)-SUMIFS(CalcWit,CalcBank,LEFT(UPPER(TRIM($E18)),6),CalcKey,"<="&Calc!$H18)) | O18: =IF(OR($C18="",$M18=""),"",IF($N18="","؟",IF(ROUND($M18-$N18,0)=0,"√","×")))
A19: =IF($C19="","",COUNTA($C$9:$C19)) | B19: =IF($C19="","","TXN-"&RIGHT("0000"&11,4)) | F19: =IF($E19="","",IFERROR(IF(VLOOKUP(LEFT(UPPER(TRIM($E19)),6),BankTbl,2,0)="","(بدون عنوان)",VLOOKUP(LEFT(UPPER(TRIM($E19)),6),BankTbl,2,0)),"بانک ناشناخته")) | H19: =IF($G19="","",IFERROR(VLOOKUP($G19,CustTbl,2,0),IFERROR(VLOOKUP($G19,SuppTbl,2,0),IFERROR(VLOOKUP($G19,AcctTbl,2,0),IFERROR(VLOOKUP($G19,StaffTbl,2,0),"کد ناشناخته"))))) | N19: =IF(OR($C19="",$E19="",Calc!$H19=""),"",IFERROR(VLOOKUP(LEFT(UPPER(TRIM($E19)),6),BankTbl,3,0),0)+SUMIFS(CalcDep,CalcBank,LEFT(UPPER(TRIM($E19)),6),CalcKey,"<="&Calc!$H19)-SUMIFS(CalcWit,CalcBank,LEFT(UPPER(TRIM($E19)),6),CalcKey,"<="&Calc!$H19)) | O19: =IF(OR($C19="",$M19=""),"",IF($N19="","؟",IF(ROUND($M19-$N19,0)=0,"√","×")))
A20: =IF($C20="","",COUNTA($C$9:$C20)) | B20: =IF($C20="","","TXN-"&RIGHT("0000"&12,4)) | F20: =IF($E20="","",IFERROR(IF(VLOOKUP(LEFT(UPPER(TRIM($E20)),6),BankTbl,2,0)="","(بدون عنوان)",VLOOKUP(LEFT(UPPER(TRIM($E20)),6),BankTbl,2,0)),"بانک ناشناخته")) | H20: =IF($G20="","",IFERROR(VLOOKUP($G20,CustTbl,2,0),IFERROR(VLOOKUP($G20,SuppTbl,2,0),IFERROR(VLOOKUP($G20,AcctTbl,2,0),IFERROR(VLOOKUP($G20,StaffTbl,2,0),"کد ناشناخته"))))) | N20: =IF(OR($C20="",$E20="",Calc!$H20=""),"",IFERROR(VLOOKUP(LEFT(UPPER(TRIM($E20)),6),BankTbl,3,0),0)+SUMIFS(CalcDep,CalcBank,LEFT(UPPER(TRIM($E20)),6),CalcKey,"<="&Calc!$H20)-SUMIFS(CalcWit,CalcBank,LEFT(UPPER(TRIM($E20)),6),CalcKey,"<="&Calc!$H20)) | O20: =IF(OR($C20="",$M20=""),"",IF($N20="","؟",IF(ROUND($M20-$N20,0)=0,"√","×")))
A21: =IF($C21="","",COUNTA($C$9:$C21)) | B21: =IF($C21="","","TXN-"&RIGHT("0000"&13,4)) | F21: =IF($E21="","",IFERROR(IF(VLOOKUP(LEFT(UPPER(TRIM($E21)),6),BankTbl,2,0)="","(بدون عنوان)",VLOOKUP(LEFT(UPPER(TRIM($E21)),6),BankTbl,2,0)),"بانک ناشناخته")) | H21: =IF($G21="","",IFERROR(VLOOKUP($G21,CustTbl,2,0),IFERROR(VLOOKUP($G21,SuppTbl,2,0),IFERROR(VLOOKUP($G21,AcctTbl,2,0),IFERROR(VLOOKUP($G21,StaffTbl,2,0),"کد ناشناخته"))))) | N21: =IF(OR($C21="",$E21="",Calc!$H21=""),"",IFERROR(VLOOKUP(LEFT(UPPER(TRIM($E21)),6),BankTbl,3,0),0)+SUMIFS(CalcDep,CalcBank,LEFT(UPPER(TRIM($E21)),6),CalcKey,"<="&Calc!$H21)-SUMIFS(CalcWit,CalcBank,LEFT(UPPER(TRIM($E21)),6),CalcKey,"<="&Calc!$H21)) | O21: =IF(OR($C21="",$M21=""),"",IF($N21="","؟",IF(ROUND($M21-$N21,0)=0,"√","×")))
A22: =IF($C22="","",COUNTA($C$9:$C22)) | B22: =IF($C22="","","TXN-"&RIGHT("0000"&14,4)) | F22: =IF($E22="","",IFERROR(IF(VLOOKUP(LEFT(UPPER(TRIM($E22)),6),BankTbl,2,0)="","(بدون عنوان)",VLOOKUP(LEFT(UPPER(TRIM($E22)),6),BankTbl,2,0)),"بانک ناشناخته")) | H22: =IF($G22="","",IFERROR(VLOOKUP($G22,CustTbl,2,0),IFERROR(VLOOKUP($G22,SuppTbl,2,0),IFERROR(VLOOKUP($G22,AcctTbl,2,0),IFERROR(VLOOKUP($G22,StaffTbl,2,0),"کد ناشناخته"))))) | N22: =IF(OR($C22="",$E22="",Calc!$H22=""),"",IFERROR(VLOOKUP(LEFT(UPPER(TRIM($E22)),6),BankTbl,3,0),0)+SUMIFS(CalcDep,CalcBank,LEFT(UPPER(TRIM($E22)),6),CalcKey,"<="&Calc!$H22)-SUMIFS(CalcWit,CalcBank,LEFT(UPPER(TRIM($E22)),6),CalcKey,"<="&Calc!$H22)) | O22: =IF(OR($C22="",$M22=""),"",IF($N22="","؟",IF(ROUND($M22-$N22,0)=0,"√","×")))
A23: =IF($C23="","",COUNTA($C$9:$C23)) | B23: =IF($C23="","","TXN-"&RIGHT("0000"&15,4)) | F23: =IF($E23="","",IFERROR(IF(VLOOKUP(LEFT(UPPER(TRIM($E23)),6),BankTbl,2,0)="","(بدون عنوان)",VLOOKUP(LEFT(UPPER(TRIM($E23)),6),BankTbl,2,0)),"بانک ناشناخته")) | H23: =IF($G23="","",IFERROR(VLOOKUP($G23,CustTbl,2,0),IFERROR(VLOOKUP($G23,SuppTbl,2,0),IFERROR(VLOOKUP($G23,AcctTbl,2,0),IFERROR(VLOOKUP($G23,StaffTbl,2,0),"کد ناشناخته"))))) | N23: =IF(OR($C23="",$E23="",Calc!$H23=""),"",IFERROR(VLOOKUP(LEFT(UPPER(TRIM($E23)),6),BankTbl,3,0),0)+SUMIFS(CalcDep,CalcBank,LEFT(UPPER(TRIM($E23)),6),CalcKey,"<="&Calc!$H23)-SUMIFS(CalcWit,CalcBank,LEFT(UPPER(TRIM($E23)),6),CalcKey,"<="&Calc!$H23)) | O23: =IF(OR($C23="",$M23=""),"",IF($N23="","؟",IF(ROUND($M23-$N23,0)=0,"√","×")))
A24: =IF($C24="","",COUNTA($C$9:$C24)) | B24: =IF($C24="","","TXN-"&RIGHT("0000"&16,4)) | F24: =IF($E24="","",IFERROR(IF(VLOOKUP(LEFT(UPPER(TRIM($E24)),6),BankTbl,2,0)="","(بدون عنوان)",VLOOKUP(LEFT(UPPER(TRIM($E24)),6),BankTbl,2,0)),"بانک ناشناخته")) | H24: =IF($G24="","",IFERROR(VLOOKUP($G24,CustTbl,2,0),IFERROR(VLOOKUP($G24,SuppTbl,2,0),IFERROR(VLOOKUP($G24,AcctTbl,2,0),IFERROR(VLOOKUP($G24,StaffTbl,2,0),"کد ناشناخته"))))) | N24: =IF(OR($C24="",$E24="",Calc!$H24=""),"",IFERROR(VLOOKUP(LEFT(UPPER(TRIM($E24)),6),BankTbl,3,0),0)+SUMIFS(CalcDep,CalcBank,LEFT(UPPER(TRIM($E24)),6),CalcKey,"<="&Calc!$H24)-SUMIFS(CalcWit,CalcBank,LEFT(UPPER(TRIM($E24)),6),CalcKey,"<="&Calc!$H24)) | O24: =IF(OR($C24="",$M24=""),"",IF($N24="","؟",IF(ROUND($M24-$N24,0)=0,"√","×")))
A25: =IF($C25="","",COUNTA($C$9:$C25)) | B25: =IF($C25="","","TXN-"&RIGHT("0000"&17,4)) | F25: =IF($E25="","",IFERROR(IF(VLOOKUP(LEFT(UPPER(TRIM($E25)),6),BankTbl,2,0)="","(بدون عنوان)",VLOOKUP(LEFT(UPPER(TRIM($E25)),6),BankTbl,2,0)),"بانک ناشناخته")) | H25: =IF($G25="","",IFERROR(VLOOKUP($G25,CustTbl,2,0),IFERROR(VLOOKUP($G25,SuppTbl,2,0),IFERROR(VLOOKUP($G25,AcctTbl,2,0),IFERROR(VLOOKUP($G25,StaffTbl,2,0),"کد ناشناخته"))))) | N25: =IF(OR($C25="",$E25="",Calc!$H25=""),"",IFERROR(VLOOKUP(LEFT(UPPER(TRIM($E25)),6),BankTbl,3,0),0)+SUMIFS(CalcDep,CalcBank,LEFT(UPPER(TRIM($E25)),6),CalcKey,"<="&Calc!$H25)-SUMIFS(CalcWit,CalcBank,LEFT(UPPER(TRIM($E25)),6),CalcKey,"<="&Calc!$H25)) | O25: =IF(OR($C25="",$M25=""),"",IF($N25="","؟",IF(ROUND($M25-$N25,0)=0,"√","×")))
A26: =IF($C26="","",COUNTA($C$9:$C26)) | B26: =IF($C26="","","TXN-"&RIGHT("0000"&18,4)) | F26: =IF($E26="","",IFERROR(IF(VLOOKUP(LEFT(UPPER(TRIM($E26)),6),BankTbl,2,0)="","(بدون عنوان)",VLOOKUP(LEFT(UPPER(TRIM($E26)),6),BankTbl,2,0)),"بانک ناشناخته")) | H26: =IF($G26="","",IFERROR(VLOOKUP($G26,CustTbl,2,0),IFERROR(VLOOKUP($G26,SuppTbl,2,0),IFERROR(VLOOKUP($G26,AcctTbl,2,0),IFERROR(VLOOKUP($G26,StaffTbl,2,0),"کد ناشناخته"))))) | N26: =IF(OR($C26="",$E26="",Calc!$H26=""),"",IFERROR(VLOOKUP(LEFT(UPPER(TRIM($E26)),6),BankTbl,3,0),0)+SUMIFS(CalcDep,CalcBank,LEFT(UPPER(TRIM($E26)),6),CalcKey,"<="&Calc!$H26)-SUMIFS(CalcWit,CalcBank,LEFT(UPPER(TRIM($E26)),6),CalcKey,"<="&Calc!$H26)) | O26: =IF(OR($C26="",$M26=""),"",IF($N26="","؟",IF(ROUND($M26-$N26,0)=0,"√","×")))
A27: =IF($C27="","",COUNTA($C$9:$C27)) | B27: =IF($C27="","","TXN-"&RIGHT("0000"&19,4)) | F27: =IF($E27="","",IFERROR(IF(VLOOKUP(LEFT(UPPER(TRIM($E27)),6),BankTbl,2,0)="","(بدون عنوان)",VLOOKUP(LEFT(UPPER(TRIM($E27)),6),BankTbl,2,0)),"بانک ناشناخته")) | H27: =IF($G27="","",IFERROR(VLOOKUP($G27,CustTbl,2,0),IFERROR(VLOOKUP($G27,SuppTbl,2,0),IFERROR(VLOOKUP($G27,AcctTbl,2,0),IFERROR(VLOOKUP($G27,StaffTbl,2,0),"کد ناشناخته"))))) | N27: =IF(OR($C27="",$E27="",Calc!$H27=""),"",IFERROR(VLOOKUP(LEFT(UPPER(TRIM($E27)),6),BankTbl,3,0),0)+SUMIFS(CalcDep,CalcBank,LEFT(UPPER(TRIM($E27)),6),CalcKey,"<="&Calc!$H27)-SUMIFS(CalcWit,CalcBank,LEFT(UPPER(TRIM($E27)),6),CalcKey,"<="&Calc!$H27)) | O27: =IF(OR($C27="",$M27=""),"",IF($N27="","؟",IF(ROUND($M27-$N27,0)=0,"√","×")))
A28: =IF($C28="","",COUNTA($C$9:$C28)) | B28: =IF($C28="","","TXN-"&RIGHT("0000"&20,4)) | F28: =IF($E28="","",IFERROR(IF(VLOOKUP(LEFT(UPPER(TRIM($E28)),6),BankTbl,2,0)="","(بدون عنوان)",VLOOKUP(LEFT(UPPER(TRIM($E28)),6),BankTbl,2,0)),"بانک ناشناخته")) | H28: =IF($G28="","",IFERROR(VLOOKUP($G28,CustTbl,2,0),IFERROR(VLOOKUP($G28,SuppTbl,2,0),IFERROR(VLOOKUP($G28,AcctTbl,2,0),IFERROR(VLOOKUP($G28,StaffTbl,2,0),"کد ناشناخته"))))) | N28: =IF(OR($C28="",$E28="",Calc!$H28=""),"",IFERROR(VLOOKUP(LEFT(UPPER(TRIM($E28)),6),BankTbl,3,0),0)+SUMIFS(CalcDep,CalcBank,LEFT(UPPER(TRIM($E28)),6),CalcKey,"<="&Calc!$H28)-SUMIFS(CalcWit,CalcBank,LEFT(UPPER(TRIM($E28)),6),CalcKey,"<="&Calc!$H28)) | O28: =IF(OR($C28="",$M28=""),"",IF($N28="","؟",IF(ROUND($M28-$N28,0)=0,"√","×")))
A29: =IF($C29="","",COUNTA($C$9:$C29)) | B29: =IF($C29="","","TXN-"&RIGHT("0000"&21,4)) | F29: =IF($E29="","",IFERROR(IF(VLOOKUP(LEFT(UPPER(TRIM($E29)),6),BankTbl,2,0)="","(بدون عنوان)",VLOOKUP(LEFT(UPPER(TRIM($E29)),6),BankTbl,2,0)),"بانک ناشناخته")) | H29: =IF($G29="","",IFERROR(VLOOKUP($G29,CustTbl,2,0),IFERROR(VLOOKUP($G29,SuppTbl,2,0),IFERROR(VLOOKUP($G29,AcctTbl,2,0),IFERROR(VLOOKUP($G29,StaffTbl,2,0),"کد ناشناخته"))))) | N29: =IF(OR($C29="",$E29="",Calc!$H29=""),"",IFERROR(VLOOKUP(LEFT(UPPER(TRIM($E29)),6),BankTbl,3,0),0)+SUMIFS(CalcDep,CalcBank,LEFT(UPPER(TRIM($E29)),6),CalcKey,"<="&Calc!$H29)-SUMIFS(CalcWit,CalcBank,LEFT(UPPER(TRIM($E29)),6),CalcKey,"<="&Calc!$H29)) | O29: =IF(OR($C29="",$M29=""),"",IF($N29="","؟",IF(ROUND($M29-$N29,0)=0,"√","×")))
A30: =IF($C30="","",COUNTA($C$9:$C30)) | B30: =IF($C30="","","TXN-"&RIGHT("0000"&22,4)) | F30: =IF($E30="","",IFERROR(IF(VLOOKUP(LEFT(UPPER(TRIM($E30)),6),BankTbl,2,0)="","(بدون عنوان)",VLOOKUP(LEFT(UPPER(TRIM($E30)),6),BankTbl,2,0)),"بانک ناشناخته")) | H30: =IF($G30="","",IFERROR(VLOOKUP($G30,CustTbl,2,0),IFERROR(VLOOKUP($G30,SuppTbl,2,0),IFERROR(VLOOKUP($G30,AcctTbl,2,0),IFERROR(VLOOKUP($G30,StaffTbl,2,0),"کد ناشناخته"))))) | N30: =IF(OR($C30="",$E30="",Calc!$H30=""),"",IFERROR(VLOOKUP(LEFT(UPPER(TRIM($E30)),6),BankTbl,3,0),0)+SUMIFS(CalcDep,CalcBank,LEFT(UPPER(TRIM($E30)),6),CalcKey,"<="&Calc!$H30)-SUMIFS(CalcWit,CalcBank,LEFT(UPPER(TRIM($E30)),6),CalcKey,"<="&Calc!$H30)) | O30: =IF(OR($C30="",$M30=""),"",IF($N30="","؟",IF(ROUND($M30-$N30,0)=0,"√","×")))
A31: =IF($C31="","",COUNTA($C$9:$C31)) | B31: =IF($C31="","","TXN-"&RIGHT("0000"&23,4)) | F31: =IF($E31="","",IFERROR(IF(VLOOKUP(LEFT(UPPER(TRIM($E31)),6),BankTbl,2,0)="","(بدون عنوان)",VLOOKUP(LEFT(UPPER(TRIM($E31)),6),BankTbl,2,0)),"بانک ناشناخته")) | H31: =IF($G31="","",IFERROR(VLOOKUP($G31,CustTbl,2,0),IFERROR(VLOOKUP($G31,SuppTbl,2,0),IFERROR(VLOOKUP($G31,AcctTbl,2,0),IFERROR(VLOOKUP($G31,StaffTbl,2,0),"کد ناشناخته"))))) | N31: =IF(OR($C31="",$E31="",Calc!$H31=""),"",IFERROR(VLOOKUP(LEFT(UPPER(TRIM($E31)),6),BankTbl,3,0),0)+SUMIFS(CalcDep,CalcBank,LEFT(UPPER(TRIM($E31)),6),CalcKey,"<="&Calc!$H31)-SUMIFS(CalcWit,CalcBank,LEFT(UPPER(TRIM($E31)),6),CalcKey,"<="&Calc!$H31)) | O31: =IF(OR($C31="",$M31=""),"",IF($N31="","؟",IF(ROUND($M31-$N31,0)=0,"√","×")))
A32: =IF($C32="","",COUNTA($C$9:$C32)) | B32: =IF($C32="","","TXN-"&RIGHT("0000"&24,4)) | F32: =IF($E32="","",IFERROR(IF(VLOOKUP(LEFT(UPPER(TRIM($E32)),6),BankTbl,2,0)="","(بدون عنوان)",VLOOKUP(LEFT(UPPER(TRIM($E32)),6),BankTbl,2,0)),"بانک ناشناخته")) | H32: =IF($G32="","",IFERROR(VLOOKUP($G32,CustTbl,2,0),IFERROR(VLOOKUP($G32,SuppTbl,2,0),IFERROR(VLOOKUP($G32,AcctTbl,2,0),IFERROR(VLOOKUP($G32,StaffTbl,2,0),"کد ناشناخته"))))) | N32: =IF(OR($C32="",$E32="",Calc!$H32=""),"",IFERROR(VLOOKUP(LEFT(UPPER(TRIM($E32)),6),BankTbl,3,0),0)+SUMIFS(CalcDep,CalcBank,LEFT(UPPER(TRIM($E32)),6),CalcKey,"<="&Calc!$H32)-SUMIFS(CalcWit,CalcBank,LEFT(UPPER(TRIM($E32)),6),CalcKey,"<="&Calc!$H32)) | O32: =IF(OR($C32="",$M32=""),"",IF($N32="","؟",IF(ROUND($M32-$N32,0)=0,"√","×")))
A33: =IF($C33="","",COUNTA($C$9:$C33)) | B33: =IF($C33="","","TXN-"&RIGHT("0000"&25,4)) | F33: =IF($E33="","",IFERROR(IF(VLOOKUP(LEFT(UPPER(TRIM($E33)),6),BankTbl,2,0)="","(بدون عنوان)",VLOOKUP(LEFT(UPPER(TRIM($E33)),6),BankTbl,2,0)),"بانک ناشناخته")) | H33: =IF($G33="","",IFERROR(VLOOKUP($G33,CustTbl,2,0),IFERROR(VLOOKUP($G33,SuppTbl,2,0),IFERROR(VLOOKUP($G33,AcctTbl,2,0),IFERROR(VLOOKUP($G33,StaffTbl,2,0),"کد ناشناخته"))))) | N33: =IF(OR($C33="",$E33="",Calc!$H33=""),"",IFERROR(VLOOKUP(LEFT(UPPER(TRIM($E33)),6),BankTbl,3,0),0)+SUMIFS(CalcDep,CalcBank,LEFT(UPPER(TRIM($E33)),6),CalcKey,"<="&Calc!$H33)-SUMIFS(CalcWit,CalcBank,LEFT(UPPER(TRIM($E33)),6),CalcKey,"<="&Calc!$H33)) | O33: =IF(OR($C33="",$M33=""),"",IF($N33="","؟",IF(ROUND($M33-$N33,0)=0,"√","×")))
A34: =IF($C34="","",COUNTA($C$9:$C34)) | B34: =IF($C34="","","TXN-"&RIGHT("0000"&26,4)) | F34: =IF($E34="","",IFERROR(IF(VLOOKUP(LEFT(UPPER(TRIM($E34)),6),BankTbl,2,0)="","(بدون عنوان)",VLOOKUP(LEFT(UPPER(TRIM($E34)),6),BankTbl,2,0)),"بانک ناشناخته")) | H34: =IF($G34="","",IFERROR(VLOOKUP($G34,CustTbl,2,0),IFERROR(VLOOKUP($G34,SuppTbl,2,0),IFERROR(VLOOKUP($G34,AcctTbl,2,0),IFERROR(VLOOKUP($G34,StaffTbl,2,0),"کد ناشناخته"))))) | N34: =IF(OR($C34="",$E34="",Calc!$H34=""),"",IFERROR(VLOOKUP(LEFT(UPPER(TRIM($E34)),6),BankTbl,3,0),0)+SUMIFS(CalcDep,CalcBank,LEFT(UPPER(TRIM($E34)),6),CalcKey,"<="&Calc!$H34)-SUMIFS(CalcWit,CalcBank,LEFT(UPPER(TRIM($E34)),6),CalcKey,"<="&Calc!$H34)) | O34: =IF(OR($C34="",$M34=""),"",IF($N34="","؟",IF(ROUND($M34-$N34,0)=0,"√","×")))
A35: =IF($C35="","",COUNTA($C$9:$C35)) | B35: =IF($C35="","","TXN-"&RIGHT("0000"&27,4)) | F35: =IF($E35="","",IFERROR(IF(VLOOKUP(LEFT(UPPER(TRIM($E35)),6),BankTbl,2,0)="","(بدون عنوان)",VLOOKUP(LEFT(UPPER(TRIM($E35)),6),BankTbl,2,0)),"بانک ناشناخته")) | H35: =IF($G35="","",IFERROR(VLOOKUP($G35,CustTbl,2,0),IFERROR(VLOOKUP($G35,SuppTbl,2,0),IFERROR(VLOOKUP($G35,AcctTbl,2,0),IFERROR(VLOOKUP($G35,StaffTbl,2,0),"کد ناشناخته"))))) | N35: =IF(OR($C35="",$E35="",Calc!$H35=""),"",IFERROR(VLOOKUP(LEFT(UPPER(TRIM($E35)),6),BankTbl,3,0),0)+SUMIFS(CalcDep,CalcBank,LEFT(UPPER(TRIM($E35)),6),CalcKey,"<="&Calc!$H35)-SUMIFS(CalcWit,CalcBank,LEFT(UPPER(TRIM($E35)),6),CalcKey,"<="&Calc!$H35)) | O35: =IF(OR($C35="",$M35=""),"",IF($N35="","؟",IF(ROUND($M35-$N35,0)=0,"√","×")))
A36: =IF($C36="","",COUNTA($C$9:$C36)) | B36: =IF($C36="","","TXN-"&RIGHT("0000"&28,4)) | F36: =IF($E36="","",IFERROR(IF(VLOOKUP(LEFT(UPPER(TRIM($E36)),6),BankTbl,2,0)="","(بدون عنوان)",VLOOKUP(LEFT(UPPER(TRIM($E36)),6),BankTbl,2,0)),"بانک ناشناخته")) | H36: =IF($G36="","",IFERROR(VLOOKUP($G36,CustTbl,2,0),IFERROR(VLOOKUP($G36,SuppTbl,2,0),IFERROR(VLOOKUP($G36,AcctTbl,2,0),IFERROR(VLOOKUP($G36,StaffTbl,2,0),"کد ناشناخته"))))) | N36: =IF(OR($C36="",$E36="",Calc!$H36=""),"",IFERROR(VLOOKUP(LEFT(UPPER(TRIM($E36)),6),BankTbl,3,0),0)+SUMIFS(CalcDep,CalcBank,LEFT(UPPER(TRIM($E36)),6),CalcKey,"<="&Calc!$H36)-SUMIFS(CalcWit,CalcBank,LEFT(UPPER(TRIM($E36)),6),CalcKey,"<="&Calc!$H36)) | O36: =IF(OR($C36="",$M36=""),"",IF($N36="","؟",IF(ROUND($M36-$N36,0)=0,"√","×")))
A37: =IF($C37="","",COUNTA($C$9:$C37)) | B37: =IF($C37="","","TXN-"&RIGHT("0000"&29,4)) | F37: =IF($E37="","",IFERROR(IF(VLOOKUP(LEFT(UPPER(TRIM($E37)),6),BankTbl,2,0)="","(بدون عنوان)",VLOOKUP(LEFT(UPPER(TRIM($E37)),6),BankTbl,2,0)),"بانک ناشناخته")) | H37: =IF($G37="","",IFERROR(VLOOKUP($G37,CustTbl,2,0),IFERROR(VLOOKUP($G37,SuppTbl,2,0),IFERROR(VLOOKUP($G37,AcctTbl,2,0),IFERROR(VLOOKUP($G37,StaffTbl,2,0),"کد ناشناخته"))))) | N37: =IF(OR($C37="",$E37="",Calc!$H37=""),"",IFERROR(VLOOKUP(LEFT(UPPER(TRIM($E37)),6),BankTbl,3,0),0)+SUMIFS(CalcDep,CalcBank,LEFT(UPPER(TRIM($E37)),6),CalcKey,"<="&Calc!$H37)-SUMIFS(CalcWit,CalcBank,LEFT(UPPER(TRIM($E37)),6),CalcKey,"<="&Calc!$H37)) | O37: =IF(OR($C37="",$M37=""),"",IF($N37="","؟",IF(ROUND($M37-$N37,0)=0,"√","×")))
A38: =IF($C38="","",COUNTA($C$9:$C38)) | B38: =IF($C38="","","TXN-"&RIGHT("0000"&30,4)) | F38: =IF($E38="","",IFERROR(IF(VLOOKUP(LEFT(UPPER(TRIM($E38)),6),BankTbl,2,0)="","(بدون عنوان)",VLOOKUP(LEFT(UPPER(TRIM($E38)),6),BankTbl,2,0)),"بانک ناشناخته")) | H38: =IF($G38="","",IFERROR(VLOOKUP($G38,CustTbl,2,0),IFERROR(VLOOKUP($G38,SuppTbl,2,0),IFERROR(VLOOKUP($G38,AcctTbl,2,0),IFERROR(VLOOKUP($G38,StaffTbl,2,0),"کد ناشناخته"))))) | N38: =IF(OR($C38="",$E38="",Calc!$H38=""),"",IFERROR(VLOOKUP(LEFT(UPPER(TRIM($E38)),6),BankTbl,3,0),0)+SUMIFS(CalcDep,CalcBank,LEFT(UPPER(TRIM($E38)),6),CalcKey,"<="&Calc!$H38)-SUMIFS(CalcWit,CalcBank,LEFT(UPPER(TRIM($E38)),6),CalcKey,"<="&Calc!$H38)) | O38: =IF(OR($C38="",$M38=""),"",IF($N38="","؟",IF(ROUND($M38-$N38,0)=0,"√","×")))
A39: =IF($C39="","",COUNTA($C$9:$C39)) | B39: =IF($C39="","","TXN-"&RIGHT("0000"&31,4)) | F39: =IF($E39="","",IFERROR(IF(VLOOKUP(LEFT(UPPER(TRIM($E39)),6),BankTbl,2,0)="","(بدون عنوان)",VLOOKUP(LEFT(UPPER(TRIM($E39)),6),BankTbl,2,0)),"بانک ناشناخته")) | H39: =IF($G39="","",IFERROR(VLOOKUP($G39,CustTbl,2,0),IFERROR(VLOOKUP($G39,SuppTbl,2,0),IFERROR(VLOOKUP($G39,AcctTbl,2,0),IFERROR(VLOOKUP($G39,StaffTbl,2,0),"کد ناشناخته"))))) | N39: =IF(OR($C39="",$E39="",Calc!$H39=""),"",IFERROR(VLOOKUP(LEFT(UPPER(TRIM($E39)),6),BankTbl,3,0),0)+SUMIFS(CalcDep,CalcBank,LEFT(UPPER(TRIM($E39)),6),CalcKey,"<="&Calc!$H39)-SUMIFS(CalcWit,CalcBank,LEFT(UPPER(TRIM($E39)),6),CalcKey,"<="&Calc!$H39)) | O39: =IF(OR($C39="",$M39=""),"",IF($N39="","؟",IF(ROUND($M39-$N39,0)=0,"√","×")))
A40: =IF($C40="","",COUNTA($C$9:$C40)) | B40: =IF($C40="","","TXN-"&RIGHT("0000"&32,4)) | F40: =IF($E40="","",IFERROR(IF(VLOOKUP(LEFT(UPPER(TRIM($E40)),6),BankTbl,2,0)="","(بدون عنوان)",VLOOKUP(LEFT(UPPER(TRIM($E40)),6),BankTbl,2,0)),"بانک ناشناخته")) | H40: =IF($G40="","",IFERROR(VLOOKUP($G40,CustTbl,2,0),IFERROR(VLOOKUP($G40,SuppTbl,2,0),IFERROR(VLOOKUP($G40,AcctTbl,2,0),IFERROR(VLOOKUP($G40,StaffTbl,2,0),"کد ناشناخته"))))) | N40: =IF(OR($C40="",$E40="",Calc!$H40=""),"",IFERROR(VLOOKUP(LEFT(UPPER(TRIM($E40)),6),BankTbl,3,0),0)+SUMIFS(CalcDep,CalcBank,LEFT(UPPER(TRIM($E40)),6),CalcKey,"<="&Calc!$H40)-SUMIFS(CalcWit,CalcBank,LEFT(UPPER(TRIM($E40)),6),CalcKey,"<="&Calc!$H40)) | O40: =IF(OR($C40="",$M40=""),"",IF($N40="","؟",IF(ROUND($M40-$N40,0)=0,"√","×")))
...

Sheet Bank1
A1: =IF(Sync!$AJ$6="","مازندشت",Sync!$AJ$6)&" — "&IF(Sync!$AJ$9="","سورتینگ و بسته‌بندی مرکبات",Sync!$AJ$9)
A2: =IF(Sync!$AJ$7="","باغدشت، بخش مرکزی، شهرستان قائم‌شهر، استان مازندران، ایران",Sync!$AJ$7)&" | MAZANDASHT · CITRUS SORTING & PACKING"
A3: =IFERROR("صورت حساب بانکی — "&IF(VLOOKUP("BANK01",BankTbl,2,0)="","(بدون عنوان)",VLOOKUP("BANK01",BankTbl,2,0)),"صورت حساب بانکی") | I3: ="کد حساب: BANK01"
A4: =IF(COUNTIFS(CalcBank,"BANK01")>500,"× ظرفیت 500 ردیف این برگه پر شده — آخرین ردیف را به پایین کپی کنید","") | I4: مشخصات رسمی زیر، دستی وارد می‌شود (زردرنگ).
A5: کد حساب: | C5: BANK01 | H5: نام رسمی بانک:
A6: عنوان نمایشی: | C6: =IFERROR(IF(VLOOKUP("BANK01",BankTbl,2,0)="","(بدون عنوان)",VLOOKUP("BANK01",BankTbl,2,0)),"—") | H6: شعبه:
A7: مانده اولیه (ریال): | C7: =IFERROR(VLOOKUP("BANK01",BankTbl,3,0),0) | H7: شماره حساب:
A8: وضعیت فعال: | C8: =IFERROR(IF(VLOOKUP("BANK01",BankTbl,4,0)=0,"—",VLOOKUP("BANK01",BankTbl,4,0)),"—") | H8: شماره شبا (۲۴ رقم):
A9: این چهار سلول از فایل مادر خوانده می‌شوند؛ برای تغییر: Mazandasht_INFO.xlsx ← شیت Banks. مشخصات رسمی (زردرنگ) دستی وارد می‌شود. | H9: صاحب حساب:
H10: تلفن شعبه:
A12: جمع واریز (ریال) | C12: جمع برداشت (ریال) | E12: مانده نهایی سیستم | G12: آخرین موجودی بانک | I12: وضعیت مغایرت | K12: تعداد تراکنش | M12: ردیف تکراری | O12: آخرین تاریخ
A13: =SUM($H$17:$H$516) | C13: =SUM($I$17:$I$516) | E13: =IFERROR(LOOKUP(9.99E+307,$J$17:$J$516),$C$7) | G13: =IFERROR(LOOKUP(9.99E+307,$K$17:$K$516),"—") | I13: =IF(NOT(ISNUMBER($G$13)),"— بدون کنترل",IF(ROUND($G$13-$E$13,0)=0,"√ منطبق","× مغایرت ("&TEXT(ROUND($G$13-$E$13,0),"#,##0")&" ریال)")) | K13: =COUNT($A$17:$A$516) | M13: =COUNTIF($M$17:$M$516,"تکرار") | O13: =IF(COUNT($A$17:$A$516)=0,"—",INDEX($B$17:$B$516,COUNT($A$17:$A$516)))
A15: ردیف | B15: تاریخ | C15: ساعت | D15: کد طرف | E15: طرف حساب | F15: نوع طرف حساب | G15: نوع تراکنش | H15: واریز (ریال) | I15: برداشت (ریال) | J15: مانده سیستم (ریال) | K15: موجودی بانک (ریال) | L15: وضعیت | M15: کنترل تکرار | N15: توضیحات | O15: شناسه
A16: No. | B16: Date | C16: Time | D16: Party Code | E16: Party | F16: Party Type | G16: Txn Type | H16: Deposit | I16: Withdrawal | J16: System Balance | K16: Bank Balance | L16: Status | M16: Dup Check | N16: Notes | O16: TxnID
A17: =IF($B17="","",1) | B17: =IF($P17="","",IF(INDEX(CalcNormDate,$P17)=0,"",INDEX(CalcNormDate,$P17))) | C17: =IF($P17="","",IF(INDEX(CalcTime,$P17)=0,"",INDEX(CalcTime,$P17))) | D17: =IF($P17="","",IF(INDEX(EntryParty,$P17)=0,"",INDEX(EntryParty,$P17))) | E17: =IF($P17="","",IF(INDEX(EntryPartyName,$P17)=0,"",INDEX(EntryPartyName,$P17))) | F17: =IF($P17="","",IF(INDEX(EntryPartyType,$P17)=0,"",INDEX(EntryPartyType,$P17))) | G17: =IF($P17="","",IF(INDEX(EntryTxnType,$P17)=0,"",INDEX(EntryTxnType,$P17))) | H17: =IF($P17="","",IF(INDEX(EntryDep,$P17)=0,"",INDEX(EntryDep,$P17))) | I17: =IF($P17="","",IF(INDEX(EntryWit,$P17)=0,"",INDEX(EntryWit,$P17))) | J17: =IF($B17="","",IF($A17=1,$C$7,IF(J16="",0,J16))+IF($H17="",0,$H17)-IF($I17="",0,$I17)) | K17: =IF($P17="","",IF(INDEX(EntryMan,$P17)=0,"",INDEX(EntryMan,$P17))) | L17: =IF($B17="","",IF($K17="","—",IF(ROUND($K17-$J17,0)=0,"√","×"))) | M17: =IF($B17="","",IF(COUNTIFS(EntryDates,$B17,CalcTime,$C17,CalcBank,$C$5,EntryParty,$D17,EntryDep,$H17,EntryWit,$I17)>1,"تکرار","")) | N17: =IF($P17="","",IF(INDEX(EntryNotes,$P17)=0,"",INDEX(EntryNotes,$P17))) | O17: =IF($P17="","",IF(INDEX(EntryTxnID,$P17)=0,"",INDEX(EntryTxnID,$P17))) | P17: =IFERROR(MATCH($C$5&"|"&RIGHT("000000"&1,6),CalcRankKey,0),"")
A18: =IF($B18="","",2) | B18: =IF($P18="","",IF(INDEX(CalcNormDate,$P18)=0,"",INDEX(CalcNormDate,$P18))) | C18: =IF($P18="","",IF(INDEX(CalcTime,$P18)=0,"",INDEX(CalcTime,$P18))) | D18: =IF($P18="","",IF(INDEX(EntryParty,$P18)=0,"",INDEX(EntryParty,$P18))) | E18: =IF($P18="","",IF(INDEX(EntryPartyName,$P18)=0,"",INDEX(EntryPartyName,$P18))) | F18: =IF($P18="","",IF(INDEX(EntryPartyType,$P18)=0,"",INDEX(EntryPartyType,$P18))) | G18: =IF($P18="","",IF(INDEX(EntryTxnType,$P18)=0,"",INDEX(EntryTxnType,$P18))) | H18: =IF($P18="","",IF(INDEX(EntryDep,$P18)=0,"",INDEX(EntryDep,$P18))) | I18: =IF($P18="","",IF(INDEX(EntryWit,$P18)=0,"",INDEX(EntryWit,$P18))) | J18: =IF($B18="","",IF($A18=1,$C$7,IF(J17="",0,J17))+IF($H18="",0,$H18)-IF($I18="",0,$I18)) | K18: =IF($P18="","",IF(INDEX(EntryMan,$P18)=0,"",INDEX(EntryMan,$P18))) | L18: =IF($B18="","",IF($K18="","—",IF(ROUND($K18-$J18,0)=0,"√","×"))) | M18: =IF($B18="","",IF(COUNTIFS(EntryDates,$B18,CalcTime,$C18,CalcBank,$C$5,EntryParty,$D18,EntryDep,$H18,EntryWit,$I18)>1,"تکرار","")) | N18: =IF($P18="","",IF(INDEX(EntryNotes,$P18)=0,"",INDEX(EntryNotes,$P18))) | O18: =IF($P18="","",IF(INDEX(EntryTxnID,$P18)=0,"",INDEX(EntryTxnID,$P18))) | P18: =IFERROR(MATCH($C$5&"|"&RIGHT("000000"&2,6),CalcRankKey,0),"")
A19: =IF($B19="","",3) | B19: =IF($P19="","",IF(INDEX(CalcNormDate,$P19)=0,"",INDEX(CalcNormDate,$P19))) | C19: =IF($P19="","",IF(INDEX(CalcTime,$P19)=0,"",INDEX(CalcTime,$P19))) | D19: =IF($P19="","",IF(INDEX(EntryParty,$P19)=0,"",INDEX(EntryParty,$P19))) | E19: =IF($P19="","",IF(INDEX(EntryPartyName,$P19)=0,"",INDEX(EntryPartyName,$P19))) | F19: =IF($P19="","",IF(INDEX(EntryPartyType,$P19)=0,"",INDEX(EntryPartyType,$P19))) | G19: =IF($P19="","",IF(INDEX(EntryTxnType,$P19)=0,"",INDEX(EntryTxnType,$P19))) | H19: =IF($P19="","",IF(INDEX(EntryDep,$P19)=0,"",INDEX(EntryDep,$P19))) | I19: =IF($P19="","",IF(INDEX(EntryWit,$P19)=0,"",INDEX(EntryWit,$P19))) | J19: =IF($B19="","",IF($A19=1,$C$7,IF(J18="",0,J18))+IF($H19="",0,$H19)-IF($I19="",0,$I19)) | K19: =IF($P19="","",IF(INDEX(EntryMan,$P19)=0,"",INDEX(EntryMan,$P19))) | L19: =IF($B19="","",IF($K19="","—",IF(ROUND($K19-$J19,0)=0,"√","×"))) | M19: =IF($B19="","",IF(COUNTIFS(EntryDates,$B19,CalcTime,$C19,CalcBank,$C$5,EntryParty,$D19,EntryDep,$H19,EntryWit,$I19)>1,"تکرار","")) | N19: =IF($P19="","",IF(INDEX(EntryNotes,$P19)=0,"",INDEX(EntryNotes,$P19))) | O19: =IF($P19="","",IF(INDEX(EntryTxnID,$P19)=0,"",INDEX(EntryTxnID,$P19))) | P19: =IFERROR(MATCH($C$5&"|"&RIGHT("000000"&3,6),CalcRankKey,0),"")
A20: =IF($B20="","",4) | B20: =IF($P20="","",IF(INDEX(CalcNormDate,$P20)=0,"",INDEX(CalcNormDate,$P20))) | C20: =IF($P20="","",IF(INDEX(CalcTime,$P20)=0,"",INDEX(CalcTime,$P20))) | D20: =IF($P20="","",IF(INDEX(EntryParty,$P20)=0,"",INDEX(EntryParty,$P20))) | E20: =IF($P20="","",IF(INDEX(EntryPartyName,$P20)=0,"",INDEX(EntryPartyName,$P20))) | F20: =IF($P20="","",IF(INDEX(EntryPartyType,$P20)=0,"",INDEX(EntryPartyType,$P20))) | G20: =IF($P20="","",IF(INDEX(EntryTxnType,$P20)=0,"",INDEX(EntryTxnType,$P20))) | H20: =IF($P20="","",IF(INDEX(EntryDep,$P20)=0,"",INDEX(EntryDep,$P20))) | I20: =IF($P20="","",IF(INDEX(EntryWit,$P20)=0,"",INDEX(EntryWit,$P20))) | J20: =IF($B20="","",IF($A20=1,$C$7,IF(J19="",0,J19))+IF($H20="",0,$H20)-IF($I20="",0,$I20)) | K20: =IF($P20="","",IF(INDEX(EntryMan,$P20)=0,"",INDEX(EntryMan,$P20))) | L20: =IF($B20="","",IF($K20="","—",IF(ROUND($K20-$J20,0)=0,"√","×"))) | M20: =IF($B20="","",IF(COUNTIFS(EntryDates,$B20,CalcTime,$C20,CalcBank,$C$5,EntryParty,$D20,EntryDep,$H20,EntryWit,$I20)>1,"تکرار","")) | N20: =IF($P20="","",IF(INDEX(EntryNotes,$P20)=0,"",INDEX(EntryNotes,$P20))) | O20: =IF($P20="","",IF(INDEX(EntryTxnID,$P20)=0,"",INDEX(EntryTxnID,$P20))) | P20: =IFERROR(MATCH($C$5&"|"&RIGHT("000000"&4,6),CalcRankKey,0),"")
A21: =IF($B21="","",5) | B21: =IF($P21="","",IF(INDEX(CalcNormDate,$P21)=0,"",INDEX(CalcNormDate,$P21))) | C21: =IF($P21="","",IF(INDEX(CalcTime,$P21)=0,"",INDEX(CalcTime,$P21))) | D21: =IF($P21="","",IF(INDEX(EntryParty,$P21)=0,"",INDEX(EntryParty,$P21))) | E21: =IF($P21="","",IF(INDEX(EntryPartyName,$P21)=0,"",INDEX(EntryPartyName,$P21))) | F21: =IF($P21="","",IF(INDEX(EntryPartyType,$P21)=0,"",INDEX(EntryPartyType,$P21))) | G21: =IF($P21="","",IF(INDEX(EntryTxnType,$P21)=0,"",INDEX(EntryTxnType,$P21))) | H21: =IF($P21="","",IF(INDEX(EntryDep,$P21)=0,"",INDEX(EntryDep,$P21))) | I21: =IF($P21="","",IF(INDEX(EntryWit,$P21)=0,"",INDEX(EntryWit,$P21))) | J21: =IF($B21="","",IF($A21=1,$C$7,IF(J20="",0,J20))+IF($H21="",0,$H21)-IF($I21="",0,$I21)) | K21: =IF($P21="","",IF(INDEX(EntryMan,$P21)=0,"",INDEX(EntryMan,$P21))) | L21: =IF($B21="","",IF($K21="","—",IF(ROUND($K21-$J21,0)=0,"√","×"))) | M21: =IF($B21="","",IF(COUNTIFS(EntryDates,$B21,CalcTime,$C21,CalcBank,$C$5,EntryParty,$D21,EntryDep,$H21,EntryWit,$I21)>1,"تکرار","")) | N21: =IF($P21="","",IF(INDEX(EntryNotes,$P21)=0,"",INDEX(EntryNotes,$P21))) | O21: =IF($P21="","",IF(INDEX(EntryTxnID,$P21)=0,"",INDEX(EntryTxnID,$P21))) | P21: =IFERROR(MATCH($C$5&"|"&RIGHT("000000"&5,6),CalcRankKey,0),"")
A22: =IF($B22="","",6) | B22: =IF($P22="","",IF(INDEX(CalcNormDate,$P22)=0,"",INDEX(CalcNormDate,$P22))) | C22: =IF($P22="","",IF(INDEX(CalcTime,$P22)=0,"",INDEX(CalcTime,$P22))) | D22: =IF($P22="","",IF(INDEX(EntryParty,$P22)=0,"",INDEX(EntryParty,$P22))) | E22: =IF($P22="","",IF(INDEX(EntryPartyName,$P22)=0,"",INDEX(EntryPartyName,$P22))) | F22: =IF($P22="","",IF(INDEX(EntryPartyType,$P22)=0,"",INDEX(EntryPartyType,$P22))) | G22: =IF($P22="","",IF(INDEX(EntryTxnType,$P22)=0,"",INDEX(EntryTxnType,$P22))) | H22: =IF($P22="","",IF(INDEX(EntryDep,$P22)=0,"",INDEX(EntryDep,$P22))) | I22: =IF($P22="","",IF(INDEX(EntryWit,$P22)=0,"",INDEX(EntryWit,$P22))) | J22: =IF($B22="","",IF($A22=1,$C$7,IF(J21="",0,J21))+IF($H22="",0,$H22)-IF($I22="",0,$I22)) | K22: =IF($P22="","",IF(INDEX(EntryMan,$P22)=0,"",INDEX(EntryMan,$P22))) | L22: =IF($B22="","",IF($K22="","—",IF(ROUND($K22-$J22,0)=0,"√","×"))) | M22: =IF($B22="","",IF(COUNTIFS(EntryDates,$B22,CalcTime,$C22,CalcBank,$C$5,EntryParty,$D22,EntryDep,$H22,EntryWit,$I22)>1,"تکرار","")) | N22: =IF($P22="","",IF(INDEX(EntryNotes,$P22)=0,"",INDEX(EntryNotes,$P22))) | O22: =IF($P22="","",IF(INDEX(EntryTxnID,$P22)=0,"",INDEX(EntryTxnID,$P22))) | P22: =IFERROR(MATCH($C$5&"|"&RIGHT("000000"&6,6),CalcRankKey,0),"")
A23: =IF($B23="","",7) | B23: =IF($P23="","",IF(INDEX(CalcNormDate,$P23)=0,"",INDEX(CalcNormDate,$P23))) | C23: =IF($P23="","",IF(INDEX(CalcTime,$P23)=0,"",INDEX(CalcTime,$P23))) | D23: =IF($P23="","",IF(INDEX(EntryParty,$P23)=0,"",INDEX(EntryParty,$P23))) | E23: =IF($P23="","",IF(INDEX(EntryPartyName,$P23)=0,"",INDEX(EntryPartyName,$P23))) | F23: =IF($P23="","",IF(INDEX(EntryPartyType,$P23)=0,"",INDEX(EntryPartyType,$P23))) | G23: =IF($P23="","",IF(INDEX(EntryTxnType,$P23)=0,"",INDEX(EntryTxnType,$P23))) | H23: =IF($P23="","",IF(INDEX(EntryDep,$P23)=0,"",INDEX(EntryDep,$P23))) | I23: =IF($P23="","",IF(INDEX(EntryWit,$P23)=0,"",INDEX(EntryWit,$P23))) | J23: =IF($B23="","",IF($A23=1,$C$7,IF(J22="",0,J22))+IF($H23="",0,$H23)-IF($I23="",0,$I23)) | K23: =IF($P23="","",IF(INDEX(EntryMan,$P23)=0,"",INDEX(EntryMan,$P23))) | L23: =IF($B23="","",IF($K23="","—",IF(ROUND($K23-$J23,0)=0,"√","×"))) | M23: =IF($B23="","",IF(COUNTIFS(EntryDates,$B23,CalcTime,$C23,CalcBank,$C$5,EntryParty,$D23,EntryDep,$H23,EntryWit,$I23)>1,"تکرار","")) | N23: =IF($P23="","",IF(INDEX(EntryNotes,$P23)=0,"",INDEX(EntryNotes,$P23))) | O23: =IF($P23="","",IF(INDEX(EntryTxnID,$P23)=0,"",INDEX(EntryTxnID,$P23))) | P23: =IFERROR(MATCH($C$5&"|"&RIGHT("000000"&7,6),CalcRankKey,0),"")
A24: =IF($B24="","",8) | B24: =IF($P24="","",IF(INDEX(CalcNormDate,$P24)=0,"",INDEX(CalcNormDate,$P24))) | C24: =IF($P24="","",IF(INDEX(CalcTime,$P24)=0,"",INDEX(CalcTime,$P24))) | D24: =IF($P24="","",IF(INDEX(EntryParty,$P24)=0,"",INDEX(EntryParty,$P24))) | E24: =IF($P24="","",IF(INDEX(EntryPartyName,$P24)=0,"",INDEX(EntryPartyName,$P24))) | F24: =IF($P24="","",IF(INDEX(EntryPartyType,$P24)=0,"",INDEX(EntryPartyType,$P24))) | G24: =IF($P24="","",IF(INDEX(EntryTxnType,$P24)=0,"",INDEX(EntryTxnType,$P24))) | H24: =IF($P24="","",IF(INDEX(EntryDep,$P24)=0,"",INDEX(EntryDep,$P24))) | I24: =IF($P24="","",IF(INDEX(EntryWit,$P24)=0,"",INDEX(EntryWit,$P24))) | J24: =IF($B24="","",IF($A24=1,$C$7,IF(J23="",0,J23))+IF($H24="",0,$H24)-IF($I24="",0,$I24)) | K24: =IF($P24="","",IF(INDEX(EntryMan,$P24)=0,"",INDEX(EntryMan,$P24))) | L24: =IF($B24="","",IF($K24="","—",IF(ROUND($K24-$J24,0)=0,"√","×"))) | M24: =IF($B24="","",IF(COUNTIFS(EntryDates,$B24,CalcTime,$C24,CalcBank,$C$5,EntryParty,$D24,EntryDep,$H24,EntryWit,$I24)>1,"تکرار","")) | N24: =IF($P24="","",IF(INDEX(EntryNotes,$P24)=0,"",INDEX(EntryNotes,$P24))) | O24: =IF($P24="","",IF(INDEX(EntryTxnID,$P24)=0,"",INDEX(EntryTxnID,$P24))) | P24: =IFERROR(MATCH($C$5&"|"&RIGHT("000000"&8,6),CalcRankKey,0),"")
A25: =IF($B25="","",9) | B25: =IF($P25="","",IF(INDEX(CalcNormDate,$P25)=0,"",INDEX(CalcNormDate,$P25))) | C25: =IF($P25="","",IF(INDEX(CalcTime,$P25)=0,"",INDEX(CalcTime,$P25))) | D25: =IF($P25="","",IF(INDEX(EntryParty,$P25)=0,"",INDEX(EntryParty,$P25))) | E25: =IF($P25="","",IF(INDEX(EntryPartyName,$P25)=0,"",INDEX(EntryPartyName,$P25))) | F25: =IF($P25="","",IF(INDEX(EntryPartyType,$P25)=0,"",INDEX(EntryPartyType,$P25))) | G25: =IF($P25="","",IF(INDEX(EntryTxnType,$P25)=0,"",INDEX(EntryTxnType,$P25))) | H25: =IF($P25="","",IF(INDEX(EntryDep,$P25)=0,"",INDEX(EntryDep,$P25))) | I25: =IF($P25="","",IF(INDEX(EntryWit,$P25)=0,"",INDEX(EntryWit,$P25))) | J25: =IF($B25="","",IF($A25=1,$C$7,IF(J24="",0,J24))+IF($H25="",0,$H25)-IF($I25="",0,$I25)) | K25: =IF($P25="","",IF(INDEX(EntryMan,$P25)=0,"",INDEX(EntryMan,$P25))) | L25: =IF($B25="","",IF($K25="","—",IF(ROUND($K25-$J25,0)=0,"√","×"))) | M25: =IF($B25="","",IF(COUNTIFS(EntryDates,$B25,CalcTime,$C25,CalcBank,$C$5,EntryParty,$D25,EntryDep,$H25,EntryWit,$I25)>1,"تکرار","")) | N25: =IF($P25="","",IF(INDEX(EntryNotes,$P25)=0,"",INDEX(EntryNotes,$P25))) | O25: =IF($P25="","",IF(INDEX(EntryTxnID,$P25)=0,"",INDEX(EntryTxnID,$P25))) | P25: =IFERROR(MATCH($C$5&"|"&RIGHT("000000"&9,6),CalcRankKey,0),"")
A26: =IF($B26="","",10) | B26: =IF($P26="","",IF(INDEX(CalcNormDate,$P26)=0,"",INDEX(CalcNormDate,$P26))) | C26: =IF($P26="","",IF(INDEX(CalcTime,$P26)=0,"",INDEX(CalcTime,$P26))) | D26: =IF($P26="","",IF(INDEX(EntryParty,$P26)=0,"",INDEX(EntryParty,$P26))) | E26: =IF($P26="","",IF(INDEX(EntryPartyName,$P26)=0,"",INDEX(EntryPartyName,$P26))) | F26: =IF($P26="","",IF(INDEX(EntryPartyType,$P26)=0,"",INDEX(EntryPartyType,$P26))) | G26: =IF($P26="","",IF(INDEX(EntryTxnType,$P26)=0,"",INDEX(EntryTxnType,$P26))) | H26: =IF($P26="","",IF(INDEX(EntryDep,$P26)=0,"",INDEX(EntryDep,$P26))) | I26: =IF($P26="","",IF(INDEX(EntryWit,$P26)=0,"",INDEX(EntryWit,$P26))) | J26: =IF($B26="","",IF($A26=1,$C$7,IF(J25="",0,J25))+IF($H26="",0,$H26)-IF($I26="",0,$I26)) | K26: =IF($P26="","",IF(INDEX(EntryMan,$P26)=0,"",INDEX(EntryMan,$P26))) | L26: =IF($B26="","",IF($K26="","—",IF(ROUND($K26-$J26,0)=0,"√","×"))) | M26: =IF($B26="","",IF(COUNTIFS(EntryDates,$B26,CalcTime,$C26,CalcBank,$C$5,EntryParty,$D26,EntryDep,$H26,EntryWit,$I26)>1,"تکرار","")) | N26: =IF($P26="","",IF(INDEX(EntryNotes,$P26)=0,"",INDEX(EntryNotes,$P26))) | O26: =IF($P26="","",IF(INDEX(EntryTxnID,$P26)=0,"",INDEX(EntryTxnID,$P26))) | P26: =IFERROR(MATCH($C$5&"|"&RIGHT("000000"&10,6),CalcRankKey,0),"")
A27: =IF($B27="","",11) | B27: =IF($P27="","",IF(INDEX(CalcNormDate,$P27)=0,"",INDEX(CalcNormDate,$P27))) | C27: =IF($P27="","",IF(INDEX(CalcTime,$P27)=0,"",INDEX(CalcTime,$P27))) | D27: =IF($P27="","",IF(INDEX(EntryParty,$P27)=0,"",INDEX(EntryParty,$P27))) | E27: =IF($P27="","",IF(INDEX(EntryPartyName,$P27)=0,"",INDEX(EntryPartyName,$P27))) | F27: =IF($P27="","",IF(INDEX(EntryPartyType,$P27)=0,"",INDEX(EntryPartyType,$P27))) | G27: =IF($P27="","",IF(INDEX(EntryTxnType,$P27)=0,"",INDEX(EntryTxnType,$P27))) | H27: =IF($P27="","",IF(INDEX(EntryDep,$P27)=0,"",INDEX(EntryDep,$P27))) | I27: =IF($P27="","",IF(INDEX(EntryWit,$P27)=0,"",INDEX(EntryWit,$P27))) | J27: =IF($B27="","",IF($A27=1,$C$7,IF(J26="",0,J26))+IF($H27="",0,$H27)-IF($I27="",0,$I27)) | K27: =IF($P27="","",IF(INDEX(EntryMan,$P27)=0,"",INDEX(EntryMan,$P27))) | L27: =IF($B27="","",IF($K27="","—",IF(ROUND($K27-$J27,0)=0,"√","×"))) | M27: =IF($B27="","",IF(COUNTIFS(EntryDates,$B27,CalcTime,$C27,CalcBank,$C$5,EntryParty,$D27,EntryDep,$H27,EntryWit,$I27)>1,"تکرار","")) | N27: =IF($P27="","",IF(INDEX(EntryNotes,$P27)=0,"",INDEX(EntryNotes,$P27))) | O27: =IF($P27="","",IF(INDEX(EntryTxnID,$P27)=0,"",INDEX(EntryTxnID,$P27))) | P27: =IFERROR(MATCH($C$5&"|"&RIGHT("000000"&11,6),CalcRankKey,0),"")
A28: =IF($B28="","",12) | B28: =IF($P28="","",IF(INDEX(CalcNormDate,$P28)=0,"",INDEX(CalcNormDate,$P28))) | C28: =IF($P28="","",IF(INDEX(CalcTime,$P28)=0,"",INDEX(CalcTime,$P28))) | D28: =IF($P28="","",IF(INDEX(EntryParty,$P28)=0,"",INDEX(EntryParty,$P28))) | E28: =IF($P28="","",IF(INDEX(EntryPartyName,$P28)=0,"",INDEX(EntryPartyName,$P28))) | F28: =IF($P28="","",IF(INDEX(EntryPartyType,$P28)=0,"",INDEX(EntryPartyType,$P28))) | G28: =IF($P28="","",IF(INDEX(EntryTxnType,$P28)=0,"",INDEX(EntryTxnType,$P28))) | H28: =IF($P28="","",IF(INDEX(EntryDep,$P28)=0,"",INDEX(EntryDep,$P28))) | I28: =IF($P28="","",IF(INDEX(EntryWit,$P28)=0,"",INDEX(EntryWit,$P28))) | J28: =IF($B28="","",IF($A28=1,$C$7,IF(J27="",0,J27))+IF($H28="",0,$H28)-IF($I28="",0,$I28)) | K28: =IF($P28="","",IF(INDEX(EntryMan,$P28)=0,"",INDEX(EntryMan,$P28))) | L28: =IF($B28="","",IF($K28="","—",IF(ROUND($K28-$J28,0)=0,"√","×"))) | M28: =IF($B28="","",IF(COUNTIFS(EntryDates,$B28,CalcTime,$C28,CalcBank,$C$5,EntryParty,$D28,EntryDep,$H28,EntryWit,$I28)>1,"تکرار","")) | N28: =IF($P28="","",IF(INDEX(EntryNotes,$P28)=0,"",INDEX(EntryNotes,$P28))) | O28: =IF($P28="","",IF(INDEX(EntryTxnID,$P28)=0,"",INDEX(EntryTxnID,$P28))) | P28: =IFERROR(MATCH($C$5&"|"&RIGHT("000000"&12,6),CalcRankKey,0),"")
A29: =IF($B29="","",13) | B29: =IF($P29="","",IF(INDEX(CalcNormDate,$P29)=0,"",INDEX(CalcNormDate,$P29))) | C29: =IF($P29="","",IF(INDEX(CalcTime,$P29)=0,"",INDEX(CalcTime,$P29))) | D29: =IF($P29="","",IF(INDEX(EntryParty,$P29)=0,"",INDEX(EntryParty,$P29))) | E29: =IF($P29="","",IF(INDEX(EntryPartyName,$P29)=0,"",INDEX(EntryPartyName,$P29))) | F29: =IF($P29="","",IF(INDEX(EntryPartyType,$P29)=0,"",INDEX(EntryPartyType,$P29))) | G29: =IF($P29="","",IF(INDEX(EntryTxnType,$P29)=0,"",INDEX(EntryTxnType,$P29))) | H29: =IF($P29="","",IF(INDEX(EntryDep,$P29)=0,"",INDEX(EntryDep,$P29))) | I29: =IF($P29="","",IF(INDEX(EntryWit,$P29)=0,"",INDEX(EntryWit,$P29))) | J29: =IF($B29="","",IF($A29=1,$C$7,IF(J28="",0,J28))+IF($H29="",0,$H29)-IF($I29="",0,$I29)) | K29: =IF($P29="","",IF(INDEX(EntryMan,$P29)=0,"",INDEX(EntryMan,$P29))) | L29: =IF($B29="","",IF($K29="","—",IF(ROUND($K29-$J29,0)=0,"√","×"))) | M29: =IF($B29="","",IF(COUNTIFS(EntryDates,$B29,CalcTime,$C29,CalcBank,$C$5,EntryParty,$D29,EntryDep,$H29,EntryWit,$I29)>1,"تکرار","")) | N29: =IF($P29="","",IF(INDEX(EntryNotes,$P29)=0,"",INDEX(EntryNotes,$P29))) | O29: =IF($P29="","",IF(INDEX(EntryTxnID,$P29)=0,"",INDEX(EntryTxnID,$P29))) | P29: =IFERROR(MATCH($C$5&"|"&RIGHT("000000"&13,6),CalcRankKey,0),"")
A30: =IF($B30="","",14) | B30: =IF($P30="","",IF(INDEX(CalcNormDate,$P30)=0,"",INDEX(CalcNormDate,$P30))) | C30: =IF($P30="","",IF(INDEX(CalcTime,$P30)=0,"",INDEX(CalcTime,$P30))) | D30: =IF($P30="","",IF(INDEX(EntryParty,$P30)=0,"",INDEX(EntryParty,$P30))) | E30: =IF($P30="","",IF(INDEX(EntryPartyName,$P30)=0,"",INDEX(EntryPartyName,$P30))) | F30: =IF($P30="","",IF(INDEX(EntryPartyType,$P30)=0,"",INDEX(EntryPartyType,$P30))) | G30: =IF($P30="","",IF(INDEX(EntryTxnType,$P30)=0,"",INDEX(EntryTxnType,$P30))) | H30: =IF($P30="","",IF(INDEX(EntryDep,$P30)=0,"",INDEX(EntryDep,$P30))) | I30: =IF($P30="","",IF(INDEX(EntryWit,$P30)=0,"",INDEX(EntryWit,$P30))) | J30: =IF($B30="","",IF($A30=1,$C$7,IF(J29="",0,J29))+IF($H30="",0,$H30)-IF($I30="",0,$I30)) | K30: =IF($P30="","",IF(INDEX(EntryMan,$P30)=0,"",INDEX(EntryMan,$P30))) | L30: =IF($B30="","",IF($K30="","—",IF(ROUND($K30-$J30,0)=0,"√","×"))) | M30: =IF($B30="","",IF(COUNTIFS(EntryDates,$B30,CalcTime,$C30,CalcBank,$C$5,EntryParty,$D30,EntryDep,$H30,EntryWit,$I30)>1,"تکرار","")) | N30: =IF($P30="","",IF(INDEX(EntryNotes,$P30)=0,"",INDEX(EntryNotes,$P30))) | O30: =IF($P30="","",IF(INDEX(EntryTxnID,$P30)=0,"",INDEX(EntryTxnID,$P30))) | P30: =IFERROR(MATCH($C$5&"|"&RIGHT("000000"&14,6),CalcRankKey,0),"")
A31: =IF($B31="","",15) | B31: =IF($P31="","",IF(INDEX(CalcNormDate,$P31)=0,"",INDEX(CalcNormDate,$P31))) | C31: =IF($P31="","",IF(INDEX(CalcTime,$P31)=0,"",INDEX(CalcTime,$P31))) | D31: =IF($P31="","",IF(INDEX(EntryParty,$P31)=0,"",INDEX(EntryParty,$P31))) | E31: =IF($P31="","",IF(INDEX(EntryPartyName,$P31)=0,"",INDEX(EntryPartyName,$P31))) | F31: =IF($P31="","",IF(INDEX(EntryPartyType,$P31)=0,"",INDEX(EntryPartyType,$P31))) | G31: =IF($P31="","",IF(INDEX(EntryTxnType,$P31)=0,"",INDEX(EntryTxnType,$P31))) | H31: =IF($P31="","",IF(INDEX(EntryDep,$P31)=0,"",INDEX(EntryDep,$P31))) | I31: =IF($P31="","",IF(INDEX(EntryWit,$P31)=0,"",INDEX(EntryWit,$P31))) | J31: =IF($B31="","",IF($A31=1,$C$7,IF(J30="",0,J30))+IF($H31="",0,$H31)-IF($I31="",0,$I31)) | K31: =IF($P31="","",IF(INDEX(EntryMan,$P31)=0,"",INDEX(EntryMan,$P31))) | L31: =IF($B31="","",IF($K31="","—",IF(ROUND($K31-$J31,0)=0,"√","×"))) | M31: =IF($B31="","",IF(COUNTIFS(EntryDates,$B31,CalcTime,$C31,CalcBank,$C$5,EntryParty,$D31,EntryDep,$H31,EntryWit,$I31)>1,"تکرار","")) | N31: =IF($P31="","",IF(INDEX(EntryNotes,$P31)=0,"",INDEX(EntryNotes,$P31))) | O31: =IF($P31="","",IF(INDEX(EntryTxnID,$P31)=0,"",INDEX(EntryTxnID,$P31))) | P31: =IFERROR(MATCH($C$5&"|"&RIGHT("000000"&15,6),CalcRankKey,0),"")
A32: =IF($B32="","",16) | B32: =IF($P32="","",IF(INDEX(CalcNormDate,$P32)=0,"",INDEX(CalcNormDate,$P32))) | C32: =IF($P32="","",IF(INDEX(CalcTime,$P32)=0,"",INDEX(CalcTime,$P32))) | D32: =IF($P32="","",IF(INDEX(EntryParty,$P32)=0,"",INDEX(EntryParty,$P32))) | E32: =IF($P32="","",IF(INDEX(EntryPartyName,$P32)=0,"",INDEX(EntryPartyName,$P32))) | F32: =IF($P32="","",IF(INDEX(EntryPartyType,$P32)=0,"",INDEX(EntryPartyType,$P32))) | G32: =IF($P32="","",IF(INDEX(EntryTxnType,$P32)=0,"",INDEX(EntryTxnType,$P32))) | H32: =IF($P32="","",IF(INDEX(EntryDep,$P32)=0,"",INDEX(EntryDep,$P32))) | I32: =IF($P32="","",IF(INDEX(EntryWit,$P32)=0,"",INDEX(EntryWit,$P32))) | J32: =IF($B32="","",IF($A32=1,$C$7,IF(J31="",0,J31))+IF($H32="",0,$H32)-IF($I32="",0,$I32)) | K32: =IF($P32="","",IF(INDEX(EntryMan,$P32)=0,"",INDEX(EntryMan,$P32))) | L32: =IF($B32="","",IF($K32="","—",IF(ROUND($K32-$J32,0)=0,"√","×"))) | M32: =IF($B32="","",IF(COUNTIFS(EntryDates,$B32,CalcTime,$C32,CalcBank,$C$5,EntryParty,$D32,EntryDep,$H32,EntryWit,$I32)>1,"تکرار","")) | N32: =IF($P32="","",IF(INDEX(EntryNotes,$P32)=0,"",INDEX(EntryNotes,$P32))) | O32: =IF($P32="","",IF(INDEX(EntryTxnID,$P32)=0,"",INDEX(EntryTxnID,$P32))) | P32: =IFERROR(MATCH($C$5&"|"&RIGHT("000000"&16,6),CalcRankKey,0),"")
A33: =IF($B33="","",17) | B33: =IF($P33="","",IF(INDEX(CalcNormDate,$P33)=0,"",INDEX(CalcNormDate,$P33))) | C33: =IF($P33="","",IF(INDEX(CalcTime,$P33)=0,"",INDEX(CalcTime,$P33))) | D33: =IF($P33="","",IF(INDEX(EntryParty,$P33)=0,"",INDEX(EntryParty,$P33))) | E33: =IF($P33="","",IF(INDEX(EntryPartyName,$P33)=0,"",INDEX(EntryPartyName,$P33))) | F33: =IF($P33="","",IF(INDEX(EntryPartyType,$P33)=0,"",INDEX(EntryPartyType,$P33))) | G33: =IF($P33="","",IF(INDEX(EntryTxnType,$P33)=0,"",INDEX(EntryTxnType,$P33))) | H33: =IF($P33="","",IF(INDEX(EntryDep,$P33)=0,"",INDEX(EntryDep,$P33))) | I33: =IF($P33="","",IF(INDEX(EntryWit,$P33)=0,"",INDEX(EntryWit,$P33))) | J33: =IF($B33="","",IF($A33=1,$C$7,IF(J32="",0,J32))+IF($H33="",0,$H33)-IF($I33="",0,$I33)) | K33: =IF($P33="","",IF(INDEX(EntryMan,$P33)=0,"",INDEX(EntryMan,$P33))) | L33: =IF($B33="","",IF($K33="","—",IF(ROUND($K33-$J33,0)=0,"√","×"))) | M33: =IF($B33="","",IF(COUNTIFS(EntryDates,$B33,CalcTime,$C33,CalcBank,$C$5,EntryParty,$D33,EntryDep,$H33,EntryWit,$I33)>1,"تکرار","")) | N33: =IF($P33="","",IF(INDEX(EntryNotes,$P33)=0,"",INDEX(EntryNotes,$P33))) | O33: =IF($P33="","",IF(INDEX(EntryTxnID,$P33)=0,"",INDEX(EntryTxnID,$P33))) | P33: =IFERROR(MATCH($C$5&"|"&RIGHT("000000"&17,6),CalcRankKey,0),"")
A34: =IF($B34="","",18) | B34: =IF($P34="","",IF(INDEX(CalcNormDate,$P34)=0,"",INDEX(CalcNormDate,$P34))) | C34: =IF($P34="","",IF(INDEX(CalcTime,$P34)=0,"",INDEX(CalcTime,$P34))) | D34: =IF($P34="","",IF(INDEX(EntryParty,$P34)=0,"",INDEX(EntryParty,$P34))) | E34: =IF($P34="","",IF(INDEX(EntryPartyName,$P34)=0,"",INDEX(EntryPartyName,$P34))) | F34: =IF($P34="","",IF(INDEX(EntryPartyType,$P34)=0,"",INDEX(EntryPartyType,$P34))) | G34: =IF($P34="","",IF(INDEX(EntryTxnType,$P34)=0,"",INDEX(EntryTxnType,$P34))) | H34: =IF($P34="","",IF(INDEX(EntryDep,$P34)=0,"",INDEX(EntryDep,$P34))) | I34: =IF($P34="","",IF(INDEX(EntryWit,$P34)=0,"",INDEX(EntryWit,$P34))) | J34: =IF($B34="","",IF($A34=1,$C$7,IF(J33="",0,J33))+IF($H34="",0,$H34)-IF($I34="",0,$I34)) | K34: =IF($P34="","",IF(INDEX(EntryMan,$P34)=0,"",INDEX(EntryMan,$P34))) | L34: =IF($B34="","",IF($K34="","—",IF(ROUND($K34-$J34,0)=0,"√","×"))) | M34: =IF($B34="","",IF(COUNTIFS(EntryDates,$B34,CalcTime,$C34,CalcBank,$C$5,EntryParty,$D34,EntryDep,$H34,EntryWit,$I34)>1,"تکرار","")) | N34: =IF($P34="","",IF(INDEX(EntryNotes,$P34)=0,"",INDEX(EntryNotes,$P34))) | O34: =IF($P34="","",IF(INDEX(EntryTxnID,$P34)=0,"",INDEX(EntryTxnID,$P34))) | P34: =IFERROR(MATCH($C$5&"|"&RIGHT("000000"&18,6),CalcRankKey,0),"")
A35: =IF($B35="","",19) | B35: =IF($P35="","",IF(INDEX(CalcNormDate,$P35)=0,"",INDEX(CalcNormDate,$P35))) | C35: =IF($P35="","",IF(INDEX(CalcTime,$P35)=0,"",INDEX(CalcTime,$P35))) | D35: =IF($P35="","",IF(INDEX(EntryParty,$P35)=0,"",INDEX(EntryParty,$P35))) | E35: =IF($P35="","",IF(INDEX(EntryPartyName,$P35)=0,"",INDEX(EntryPartyName,$P35))) | F35: =IF($P35="","",IF(INDEX(EntryPartyType,$P35)=0,"",INDEX(EntryPartyType,$P35))) | G35: =IF($P35="","",IF(INDEX(EntryTxnType,$P35)=0,"",INDEX(EntryTxnType,$P35))) | H35: =IF($P35="","",IF(INDEX(EntryDep,$P35)=0,"",INDEX(EntryDep,$P35))) | I35: =IF($P35="","",IF(INDEX(EntryWit,$P35)=0,"",INDEX(EntryWit,$P35))) | J35: =IF($B35="","",IF($A35=1,$C$7,IF(J34="",0,J34))+IF($H35="",0,$H35)-IF($I35="",0,$I35)) | K35: =IF($P35="","",IF(INDEX(EntryMan,$P35)=0,"",INDEX(EntryMan,$P35))) | L35: =IF($B35="","",IF($K35="","—",IF(ROUND($K35-$J35,0)=0,"√","×"))) | M35: =IF($B35="","",IF(COUNTIFS(EntryDates,$B35,CalcTime,$C35,CalcBank,$C$5,EntryParty,$D35,EntryDep,$H35,EntryWit,$I35)>1,"تکرار","")) | N35: =IF($P35="","",IF(INDEX(EntryNotes,$P35)=0,"",INDEX(EntryNotes,$P35))) | O35: =IF($P35="","",IF(INDEX(EntryTxnID,$P35)=0,"",INDEX(EntryTxnID,$P35))) | P35: =IFERROR(MATCH($C$5&"|"&RIGHT("000000"&19,6),CalcRankKey,0),"")
A36: =IF($B36="","",20) | B36: =IF($P36="","",IF(INDEX(CalcNormDate,$P36)=0,"",INDEX(CalcNormDate,$P36))) | C36: =IF($P36="","",IF(INDEX(CalcTime,$P36)=0,"",INDEX(CalcTime,$P36))) | D36: =IF($P36="","",IF(INDEX(EntryParty,$P36)=0,"",INDEX(EntryParty,$P36))) | E36: =IF($P36="","",IF(INDEX(EntryPartyName,$P36)=0,"",INDEX(EntryPartyName,$P36))) | F36: =IF($P36="","",IF(INDEX(EntryPartyType,$P36)=0,"",INDEX(EntryPartyType,$P36))) | G36: =IF($P36="","",IF(INDEX(EntryTxnType,$P36)=0,"",INDEX(EntryTxnType,$P36))) | H36: =IF($P36="","",IF(INDEX(EntryDep,$P36)=0,"",INDEX(EntryDep,$P36))) | I36: =IF($P36="","",IF(INDEX(EntryWit,$P36)=0,"",INDEX(EntryWit,$P36))) | J36: =IF($B36="","",IF($A36=1,$C$7,IF(J35="",0,J35))+IF($H36="",0,$H36)-IF($I36="",0,$I36)) | K36: =IF($P36="","",IF(INDEX(EntryMan,$P36)=0,"",INDEX(EntryMan,$P36))) | L36: =IF($B36="","",IF($K36="","—",IF(ROUND($K36-$J36,0)=0,"√","×"))) | M36: =IF($B36="","",IF(COUNTIFS(EntryDates,$B36,CalcTime,$C36,CalcBank,$C$5,EntryParty,$D36,EntryDep,$H36,EntryWit,$I36)>1,"تکرار","")) | N36: =IF($P36="","",IF(INDEX(EntryNotes,$P36)=0,"",INDEX(EntryNotes,$P36))) | O36: =IF($P36="","",IF(INDEX(EntryTxnID,$P36)=0,"",INDEX(EntryTxnID,$P36))) | P36: =IFERROR(MATCH($C$5&"|"&RIGHT("000000"&20,6),CalcRankKey,0),"")
A37: =IF($B37="","",21) | B37: =IF($P37="","",IF(INDEX(CalcNormDate,$P37)=0,"",INDEX(CalcNormDate,$P37))) | C37: =IF($P37="","",IF(INDEX(CalcTime,$P37)=0,"",INDEX(CalcTime,$P37))) | D37: =IF($P37="","",IF(INDEX(EntryParty,$P37)=0,"",INDEX(EntryParty,$P37))) | E37: =IF($P37="","",IF(INDEX(EntryPartyName,$P37)=0,"",INDEX(EntryPartyName,$P37))) | F37: =IF($P37="","",IF(INDEX(EntryPartyType,$P37)=0,"",INDEX(EntryPartyType,$P37))) | G37: =IF($P37="","",IF(INDEX(EntryTxnType,$P37)=0,"",INDEX(EntryTxnType,$P37))) | H37: =IF($P37="","",IF(INDEX(EntryDep,$P37)=0,"",INDEX(EntryDep,$P37))) | I37: =IF($P37="","",IF(INDEX(EntryWit,$P37)=0,"",INDEX(EntryWit,$P37))) | J37: =IF($B37="","",IF($A37=1,$C$7,IF(J36="",0,J36))+IF($H37="",0,$H37)-IF($I37="",0,$I37)) | K37: =IF($P37="","",IF(INDEX(EntryMan,$P37)=0,"",INDEX(EntryMan,$P37))) | L37: =IF($B37="","",IF($K37="","—",IF(ROUND($K37-$J37,0)=0,"√","×"))) | M37: =IF($B37="","",IF(COUNTIFS(EntryDates,$B37,CalcTime,$C37,CalcBank,$C$5,EntryParty,$D37,EntryDep,$H37,EntryWit,$I37)>1,"تکرار","")) | N37: =IF($P37="","",IF(INDEX(EntryNotes,$P37)=0,"",INDEX(EntryNotes,$P37))) | O37: =IF($P37="","",IF(INDEX(EntryTxnID,$P37)=0,"",INDEX(EntryTxnID,$P37))) | P37: =IFERROR(MATCH($C$5&"|"&RIGHT("000000"&21,6),CalcRankKey,0),"")
A38: =IF($B38="","",22) | B38: =IF($P38="","",IF(INDEX(CalcNormDate,$P38)=0,"",INDEX(CalcNormDate,$P38))) | C38: =IF($P38="","",IF(INDEX(CalcTime,$P38)=0,"",INDEX(CalcTime,$P38))) | D38: =IF($P38="","",IF(INDEX(EntryParty,$P38)=0,"",INDEX(EntryParty,$P38))) | E38: =IF($P38="","",IF(INDEX(EntryPartyName,$P38)=0,"",INDEX(EntryPartyName,$P38))) | F38: =IF($P38="","",IF(INDEX(EntryPartyType,$P38)=0,"",INDEX(EntryPartyType,$P38))) | G38: =IF($P38="","",IF(INDEX(EntryTxnType,$P38)=0,"",INDEX(EntryTxnType,$P38))) | H38: =IF($P38="","",IF(INDEX(EntryDep,$P38)=0,"",INDEX(EntryDep,$P38))) | I38: =IF($P38="","",IF(INDEX(EntryWit,$P38)=0,"",INDEX(EntryWit,$P38))) | J38: =IF($B38="","",IF($A38=1,$C$7,IF(J37="",0,J37))+IF($H38="",0,$H38)-IF($I38="",0,$I38)) | K38: =IF($P38="","",IF(INDEX(EntryMan,$P38)=0,"",INDEX(EntryMan,$P38))) | L38: =IF($B38="","",IF($K38="","—",IF(ROUND($K38-$J38,0)=0,"√","×"))) | M38: =IF($B38="","",IF(COUNTIFS(EntryDates,$B38,CalcTime,$C38,CalcBank,$C$5,EntryParty,$D38,EntryDep,$H38,EntryWit,$I38)>1,"تکرار","")) | N38: =IF($P38="","",IF(INDEX(EntryNotes,$P38)=0,"",INDEX(EntryNotes,$P38))) | O38: =IF($P38="","",IF(INDEX(EntryTxnID,$P38)=0,"",INDEX(EntryTxnID,$P38))) | P38: =IFERROR(MATCH($C$5&"|"&RIGHT("000000"&22,6),CalcRankKey,0),"")
A39: =IF($B39="","",23) | B39: =IF($P39="","",IF(INDEX(CalcNormDate,$P39)=0,"",INDEX(CalcNormDate,$P39))) | C39: =IF($P39="","",IF(INDEX(CalcTime,$P39)=0,"",INDEX(CalcTime,$P39))) | D39: =IF($P39="","",IF(INDEX(EntryParty,$P39)=0,"",INDEX(EntryParty,$P39))) | E39: =IF($P39="","",IF(INDEX(EntryPartyName,$P39)=0,"",INDEX(EntryPartyName,$P39))) | F39: =IF($P39="","",IF(INDEX(EntryPartyType,$P39)=0,"",INDEX(EntryPartyType,$P39))) | G39: =IF($P39="","",IF(INDEX(EntryTxnType,$P39)=0,"",INDEX(EntryTxnType,$P39))) | H39: =IF($P39="","",IF(INDEX(EntryDep,$P39)=0,"",INDEX(EntryDep,$P39))) | I39: =IF($P39="","",IF(INDEX(EntryWit,$P39)=0,"",INDEX(EntryWit,$P39))) | J39: =IF($B39="","",IF($A39=1,$C$7,IF(J38="",0,J38))+IF($H39="",0,$H39)-IF($I39="",0,$I39)) | K39: =IF($P39="","",IF(INDEX(EntryMan,$P39)=0,"",INDEX(EntryMan,$P39))) | L39: =IF($B39="","",IF($K39="","—",IF(ROUND($K39-$J39,0)=0,"√","×"))) | M39: =IF($B39="","",IF(COUNTIFS(EntryDates,$B39,CalcTime,$C39,CalcBank,$C$5,EntryParty,$D39,EntryDep,$H39,EntryWit,$I39)>1,"تکرار","")) | N39: =IF($P39="","",IF(INDEX(EntryNotes,$P39)=0,"",INDEX(EntryNotes,$P39))) | O39: =IF($P39="","",IF(INDEX(EntryTxnID,$P39)=0,"",INDEX(EntryTxnID,$P39))) | P39: =IFERROR(MATCH($C$5&"|"&RIGHT("000000"&23,6),CalcRankKey,0),"")
