Workbook
Name SellerTbl: Sync!$A$6:$B$105
Name SellerCodes: Sync!$A$6:$A$105
Name SellerList: OFFSET(Sync!$R$6,0,0,MAX(COUNTIF(Sync!$R$6:$R$105,"?*"),1),1)
Name ProdTbl: Sync!$E$6:$I$105
Name ProdCodes: Sync!$E$6:$E$105
Name ProdList: OFFSET(Sync!$V$6,0,0,MAX(COUNTIF(Sync!$V$6:$V$105,"?*"),1),1)
Name BasketTbl: Sync!$K$6:$L$35
Name SCNormDate: Calc!$E$10:$E$2009
Name SCYM: Calc!$F$10:$F$2009
Name SCSeller: Calc!$G$10:$G$2009
Name SCInv: Calc!$H$10:$H$2009
Name SCWSent: Calc!$I$10:$I$2009
Name SCWSold: Calc!$J$10:$J$2009
Name SCAmount: Calc!$K$10:$K$2009
Name SCWProd: Calc!$L$10:$L$2009
Name SCItems: Calc!$M$10:$M$2009
Name SalesDate: Entry!$B$10:$B$2009
Name SalesSellerCell: Entry!$D$10:$D$2009
Name SalesSellerName: Entry!$E$10:$E$2009
Name SalesWSent: Entry!$F$10:$F$2009
Name SalesWSold: Entry!$G$10:$G$2009
Name SalesAmount: Entry!$H$10:$H$2009

Sheet Entry
A1: =IF(Sync!$N$6="","مازندشت",Sync!$N$6)&" — "&IF(Sync!$N$9="","سورتینگ و بسته‌بندی مرکبات",Sync!$N$9) | I1: MAZANDASHT · CITRUS SORTING & PACKING | ناحیه فقط-اکسل
A2: =IF(Sync!$N$7="","باغدشت، بخش مرکزی، شهرستان قائم‌شهر، استان مازندران، ایران",Sync!$N$7)&" | MAZANDASHT · CITRUS SORTING & PACKING"
A3: فروش محصولات به فروشندگان — ورود داده (Entry) | I3: ۱۵ ردیف محصول — ناحیه فقط-اکسل (خارج از چاپ)
A4: ستون‌های زرد = ورود دستی شما | ستون‌های خاکستری = خودکار. تاریخ: 1405/07/10 (یا 14050710) — کد فروشنده را تایپ کنید (مثل SL001) یا از کشویی انتخاب کنید؛ نامش خودکار می‌آید. | I4: برای هر فاکتور تا ۱۵ نوع محصول: محصول را از کشویی انتخاب کنید تا نوع سبد و نوع مرکبات خودکار نوشته شود، سپس تعداد سبد و وزن را وارد کنید. این ستون‌ها با دکمه +/─ بالای ستون‌ها جمع می‌شوند.
A5: تعداد فاکتور | C5: جمع وزن ارسالی (kg) | E5: جمع وزن فروش (kg) | G5: جمع مبلغ صافی (ریال) | I5: تعداد × اختلاف وزن | K5: ظرفیت باقی‌مانده
A6: =COUNTA($B$10:$B$2009) | C6: =SUM($F$10:$F$2009) | E6: =SUM($G$10:$G$2009) | G6: =SUM($H$10:$H$2009) | I6: =COUNTIF($J$10:$J$2009,"×") | K6: =2000-COUNTA($B$10:$B$2009)
A7: مشخصات فاکتور — محدوده چاپ | I7: کنترل وزن — فقط اکسل (چاپ نمی‌شود) | M7: ردیف محصول 1 | R7: ردیف محصول 2 | W7: ردیف محصول 3 | AB7: ردیف محصول 4 | AG7: ردیف محصول 5 | AL7: ردیف محصول 6 | AQ7: ردیف محصول 7 | AV7: ردیف محصول 8 | BA7: ردیف محصول 9 | BF7: ردیف محصول 10 | BK7: ردیف محصول 11 | BP7: ردیف محصول 12 | BU7: ردیف محصول 13 | BZ7: ردیف محصول 14 | CE7: ردیف محصول 15
A8: ردیف | B8: تاریخ | C8: شماره فاکتور | D8: کد فروشنده | E8: نام فروشنده | F8: وزن ارسالی (kg) | G8: وزن فروش (kg) | H8: مبلغ صافی (ریال) | I8: اختلاف وزن | J8: وضعیت ۱٪ | K8: جمع وزن محصولات | L8: اختلاف با ارسالی | M8: محصول 1 | N8: نوع سبد | O8: نوع مرکبات | P8: تعداد سبد | Q8: وزن (kg) | R8: محصول 2 | S8: نوع سبد | T8: نوع مرکبات | U8: تعداد سبد | V8: وزن (kg) | W8: محصول 3 | X8: نوع سبد | Y8: نوع مرکبات | Z8: تعداد سبد | AA8: وزن (kg) | AB8: محصول 4 | AC8: نوع سبد | AD8: نوع مرکبات | AE8: تعداد سبد | AF8: وزن (kg) | AG8: محصول 5 | AH8: نوع سبد | AI8: نوع مرکبات | AJ8: تعداد سبد | AK8: وزن (kg) | AL8: محصول 6 | AM8: نوع سبد | AN8: نوع مرکبات | AO8: تعداد سبد | AP8: وزن (kg) | AQ8: محصول 7 | AR8: نوع سبد | AS8: نوع مرکبات | AT8: تعداد سبد | AU8: وزن (kg) | AV8: محصول 8 | AW8: نوع سبد | AX8: نوع مرکبات | AY8: تعداد سبد | AZ8: وزن (kg) | BA8: محصول 9 | BB8: نوع سبد | BC8: نوع مرکبات | BD8: تعداد سبد | BE8: وزن (kg) | BF8: محصول 10 | BG8: نوع سبد | BH8: نوع مرکبات | BI8: تعداد سبد | BJ8: وزن (kg) | BK8: محصول 11 | BL8: نوع سبد | BM8: نوع مرکبات | BN8: تعداد سبد | BO8: وزن (kg) | BP8: محصول 12 | BQ8: نوع سبد | BR8: نوع مرکبات | BS8: تعداد سبد | BT8: وزن (kg) | BU8: محصول 13 | BV8: نوع سبد | BW8: نوع مرکبات | BX8: تعداد سبد | BY8: وزن (kg) | BZ8: محصول 14 | CA8: نوع سبد | CB8: نوع مرکبات | CC8: تعداد سبد | CD8: وزن (kg) | CE8: محصول 15 | CF8: نوع سبد | CG8: نوع مرکبات | CH8: تعداد سبد | CI8: وزن (kg)
A9: No. | B9: Date | C9: Invoice No. | D9: Seller Code | E9: Seller | F9: Sent Wt | G9: Sold Wt | H9: Net Amount | I9: Wt Diff | J9: 1% Status | K9: Products Wt | L9: Sent−Prod | M9: Product 1 | N9: Basket | O9: Citrus | P9: Count | Q9: Weight | R9: Product 2 | S9: Basket | T9: Citrus | U9: Count | V9: Weight | W9: Product 3 | X9: Basket | Y9: Citrus | Z9: Count | AA9: Weight | AB9: Product 4 | AC9: Basket | AD9: Citrus | AE9: Count | AF9: Weight | AG9: Product 5 | AH9: Basket | AI9: Citrus | AJ9: Count | AK9: Weight | AL9: Product 6 | AM9: Basket | AN9: Citrus | AO9: Count | AP9: Weight | AQ9: Product 7 | AR9: Basket | AS9: Citrus | AT9: Count | AU9: Weight | AV9: Product 8 | AW9: Basket | AX9: Citrus | AY9: Count | AZ9: Weight | BA9: Product 9 | BB9: Basket | BC9: Citrus | BD9: Count | BE9: Weight | BF9: Product 10 | BG9: Basket | BH9: Citrus | BI9: Count | BJ9: Weight | BK9: Product 11 | BL9: Basket | BM9: Citrus | BN9: Count | BO9: Weight | BP9: Product 12 | BQ9: Basket | BR9: Citrus | BS9: Count | BT9: Weight | BU9: Product 13 | BV9: Basket | BW9: Citrus | BX9: Count | BY9: Weight | BZ9: Product 14 | CA9: Basket | CB9: Citrus | CC9: Count | CD9: Weight | CE9: Product 15 | CF9: Basket | CG9: Citrus | CH9: Count | CI9: Weight
A10: =IF($B10="","",COUNTA($B$10:$B10)) | B10: 1405/07/05 | C10: 1001 | D10: SL001 – حاج رضا محمدی (نمونه — حجره‌دار تهران) | E10: =IF($D10="","",IFERROR(VLOOKUP(IF(ISNUMBER(FIND(" – ",$D10)),LEFT($D10,FIND(" – ",$D10)-1),$D10),SellerTbl,2,0),"کد ناشناخته")) | F10: 12000 | G10: 11950 | H10: 950000000 | I10: =IF(OR($F10="",$G10=""),"",$F10-$G10) | J10: =IF($I10="","",IF(ABS($I10)<=0.01*$F10,"√","×")) | K10: =IF(COUNT($Q10,$V10,$AA10,$AF10,$AK10,$AP10,$AU10,$AZ10,$BE10,$BJ10,$BO10,$BT10,$BY10,$CD10,$CI10)=0,"",SUM($Q10,$V10,$AA10,$AF10,$AK10,$AP10,$AU10,$AZ10,$BE10,$BJ10,$BO10,$BT10,$BY10,$CD10,$CI10)) | L10: =IF(OR($F10="",$K10=""),"",$F10-$K10) | M10: PS01 – پرتقال درجه ۱ — بسته‌بندی | N10: =IF($M10="","",IFERROR(VLOOKUP(IFERROR(VLOOKUP(IF(ISNUMBER(FIND(" – ",$M10)),LEFT($M10,FIND(" – ",$M10)-1),$M10),ProdTbl,5,0),""),BasketTbl,2,0),"کد ناشناخته")) | O10: =IF($M10="","",IFERROR(VLOOKUP(IF(ISNUMBER(FIND(" – ",$M10)),LEFT($M10,FIND(" – ",$M10)-1),$M10),ProdTbl,3,0),"کد ناشناخته")) | P10: 600 | Q10: 6000 | R10: PS02 – پرتقال درجه ۲ — عمومی | S10: =IF($R10="","",IFERROR(VLOOKUP(IFERROR(VLOOKUP(IF(ISNUMBER(FIND(" – ",$R10)),LEFT($R10,FIND(" – ",$R10)-1),$R10),ProdTbl,5,0),""),BasketTbl,2,0),"کد ناشناخته")) | T10: =IF($R10="","",IFERROR(VLOOKUP(IF(ISNUMBER(FIND(" – ",$R10)),LEFT($R10,FIND(" – ",$R10)-1),$R10),ProdTbl,3,0),"کد ناشناخته")) | U10: 595 | V10: 5950 | X10: =IF($W10="","",IFERROR(VLOOKUP(IFERROR(VLOOKUP(IF(ISNUMBER(FIND(" – ",$W10)),LEFT($W10,FIND(" – ",$W10)-1),$W10),ProdTbl,5,0),""),BasketTbl,2,0),"کد ناشناخته")) | Y10: =IF($W10="","",IFERROR(VLOOKUP(IF(ISNUMBER(FIND(" – ",$W10)),LEFT($W10,FIND(" – ",$W10)-1),$W10),ProdTbl,3,0),"کد ناشناخته")) | AC10: =IF($AB10="","",IFERROR(VLOOKUP(IFERROR(VLOOKUP(IF(ISNUMBER(FIND(" – ",$AB10)),LEFT($AB10,FIND(" – ",$AB10)-1),$AB10),ProdTbl,5,0),""),BasketTbl,2,0),"کد ناشناخته")) | AD10: =IF($AB10="","",IFERROR(VLOOKUP(IF(ISNUMBER(FIND(" – ",$AB10)),LEFT($AB10,FIND(" – ",$AB10)-1),$AB10),ProdTbl,3,0),"کد ناشناخته")) | AH10: =IF($AG10="","",IFERROR(VLOOKUP(IFERROR(VLOOKUP(IF(ISNUMBER(FIND(" – ",$AG10)),LEFT($AG10,FIND(" – ",$AG10)-1),$AG10),ProdTbl,5,0),""),BasketTbl,2,0),"کد ناشناخته")) | AI10: =IF($AG10="","",IFERROR(VLOOKUP(IF(ISNUMBER(FIND(" – ",$AG10)),LEFT($AG10,FIND(" – ",$AG10)-1),$AG10),ProdTbl,3,0),"کد ناشناخته")) | AM10: =IF($AL10="","",IFERROR(VLOOKUP(IFERROR(VLOOKUP(IF(ISNUMBER(FIND(" – ",$AL10)),LEFT($AL10,FIND(" – ",$AL10)-1),$AL10),ProdTbl,5,0),""),BasketTbl,2,0),"کد ناشناخته")) | AN10: =IF($AL10="","",IFERROR(VLOOKUP(IF(ISNUMBER(FIND(" – ",$AL10)),LEFT($AL10,FIND(" – ",$AL10)-1),$AL10),ProdTbl,3,0),"کد ناشناخته")) | AR10: =IF($AQ10="","",IFERROR(VLOOKUP(IFERROR(VLOOKUP(IF(ISNUMBER(FIND(" – ",$AQ10)),LEFT($AQ10,FIND(" – ",$AQ10)-1),$AQ10),ProdTbl,5,0),""),BasketTbl,2,0),"کد ناشناخته")) | AS10: =IF($AQ10="","",IFERROR(VLOOKUP(IF(ISNUMBER(FIND(" – ",$AQ10)),LEFT($AQ10,FIND(" – ",$AQ10)-1),$AQ10),ProdTbl,3,0),"کد ناشناخته")) | AW10: =IF($AV10="","",IFERROR(VLOOKUP(IFERROR(VLOOKUP(IF(ISNUMBER(FIND(" – ",$AV10)),LEFT($AV10,FIND(" – ",$AV10)-1),$AV10),ProdTbl,5,0),""),BasketTbl,2,0),"کد ناشناخته")) | AX10: =IF($AV10="","",IFERROR(VLOOKUP(IF(ISNUMBER(FIND(" – ",$AV10)),LEFT($AV10,FIND(" – ",$AV10)-1),$AV10),ProdTbl,3,0),"کد ناشناخته")) | BB10: =IF($BA10="","",IFERROR(VLOOKUP(IFERROR(VLOOKUP(IF(ISNUMBER(FIND(" – ",$BA10)),LEFT($BA10,FIND(" – ",$BA10)-1),$BA10),ProdTbl,5,0),""),BasketTbl,2,0),"کد ناشناخته")) | BC10: =IF($BA10="","",IFERROR(VLOOKUP(IF(ISNUMBER(FIND(" – ",$BA10)),LEFT($BA10,FIND(" – ",$BA10)-1),$BA10),ProdTbl,3,0),"کد ناشناخته")) | BG10: =IF($BF10="","",IFERROR(VLOOKUP(IFERROR(VLOOKUP(IF(ISNUMBER(FIND(" – ",$BF10)),LEFT($BF10,FIND(" – ",$BF10)-1),$BF10),ProdTbl,5,0),""),BasketTbl,2,0),"کد ناشناخته")) | BH10: =IF($BF10="","",IFERROR(VLOOKUP(IF(ISNUMBER(FIND(" – ",$BF10)),LEFT($BF10,FIND(" – ",$BF10)-1),$BF10),ProdTbl,3,0),"کد ناشناخته")) | BL10: =IF($BK10="","",IFERROR(VLOOKUP(IFERROR(VLOOKUP(IF(ISNUMBER(FIND(" – ",$BK10)),LEFT($BK10,FIND(" – ",$BK10)-1),$BK10),ProdTbl,5,0),""),BasketTbl,2,0),"کد ناشناخته")) | BM10: =IF($BK10="","",IFERROR(VLOOKUP(IF(ISNUMBER(FIND(" – ",$BK10)),LEFT($BK10,FIND(" – ",$BK10)-1),$BK10),ProdTbl,3,0),"کد ناشناخته")) | BQ10: =IF($BP10="","",IFERROR(VLOOKUP(IFERROR(VLOOKUP(IF(ISNUMBER(FIND(" – ",$BP10)),LEFT($BP10,FIND(" – ",$BP10)-1),$BP10),ProdTbl,5,0),""),BasketTbl,2,0),"کد ناشناخته")) | BR10: =IF($BP10="","",IFERROR(VLOOKUP(IF(ISNUMBER(FIND(" – ",$BP10)),LEFT($BP10,FIND(" – ",$BP10)-1),$BP10),ProdTbl,3,0),"کد ناشناخته")) | BV10: =IF($BU10="","",IFERROR(VLOOKUP(IFERROR(VLOOKUP(IF(ISNUMBER(FIND(" – ",$BU10)),LEFT($BU10,FIND(" – ",$BU10)-1),$BU10),ProdTbl,5,0),""),BasketTbl,2,0),"کد ناشناخته")) | BW10: =IF($BU10="","",IFERROR(VLOOKUP(IF(ISNUMBER(FIND(" – ",$BU10)),LEFT($BU10,FIND(" – ",$BU10)-1),$BU10),ProdTbl,3,0),"کد ناشناخته")) | CA10: =IF($BZ10="","",IFERROR(VLOOKUP(IFERROR(VLOOKUP(IF(ISNUMBER(FIND(" – ",$BZ10)),LEFT($BZ10,FIND(" – ",$BZ10)-1),$BZ10),ProdTbl,5,0),""),BasketTbl,2,0),"کد ناشناخته")) | CB10: =IF($BZ10="","",IFERROR(VLOOKUP(IF(ISNUMBER(FIND(" – ",$BZ10)),LEFT($BZ10,FIND(" – ",$BZ10)-1),$BZ10),ProdTbl,3,0),"کد ناشناخته")) | CF10: =IF($CE10="","",IFERROR(VLOOKUP(IFERROR(VLOOKUP(IF(ISNUMBER(FIND(" – ",$CE10)),LEFT($CE10,FIND(" – ",$CE10)-1),$CE10),ProdTbl,5,0),""),BasketTbl,2,0),"کد ناشناخته")) | CG10: =IF($CE10="","",IFERROR(VLOOKUP(IF(ISNUMBER(FIND(" – ",$CE10)),LEFT($CE10,FIND(" – ",$CE10)-1),$CE10),ProdTbl,3,0),"کد ناشناخته"))
A11: =IF($B11="","",COUNTA($B$10:$B11)) | B11: 1405/07/06 | C11: 1002 | D11: SL002 – شرکت گلسرای شمال (نمونه — صادراتی) | E11: =IF($D11="","",IFERROR(VLOOKUP(IF(ISNUMBER(FIND(" – ",$D11)),LEFT($D11,FIND(" – ",$D11)-1),$D11),SellerTbl,2,0),"کد ناشناخته")) | F11: 20000 | G11: 19500 | H11: 1600000000 | I11: =IF(OR($F11="",$G11=""),"",$F11-$G11) | J11: =IF($I11="","",IF(ABS($I11)<=0.01*$F11,"√","×")) | K11: =IF(COUNT($Q11,$V11,$AA11,$AF11,$AK11,$AP11,$AU11,$AZ11,$BE11,$BJ11,$BO11,$BT11,$BY11,$CD11,$CI11)=0,"",SUM($Q11,$V11,$AA11,$AF11,$AK11,$AP11,$AU11,$AZ11,$BE11,$BJ11,$BO11,$BT11,$BY11,$CD11,$CI11)) | L11: =IF(OR($F11="",$K11=""),"",$F11-$K11) | M11: PS03 – نارنگی درجه ۱ — بسته‌بندی | N11: =IF($M11="","",IFERROR(VLOOKUP(IFERROR(VLOOKUP(IF(ISNUMBER(FIND(" – ",$M11)),LEFT($M11,FIND(" – ",$M11)-1),$M11),ProdTbl,5,0),""),BasketTbl,2,0),"کد ناشناخته")) | O11: =IF($M11="","",IFERROR(VLOOKUP(IF(ISNUMBER(FIND(" – ",$M11)),LEFT($M11,FIND(" – ",$M11)-1),$M11),ProdTbl,3,0),"کد ناشناخته")) | P11: 1000 | Q11: 10000 | R11: PS04 – نارنگی عمومی | S11: =IF($R11="","",IFERROR(VLOOKUP(IFERROR(VLOOKUP(IF(ISNUMBER(FIND(" – ",$R11)),LEFT($R11,FIND(" – ",$R11)-1),$R11),ProdTbl,5,0),""),BasketTbl,2,0),"کد ناشناخته")) | T11: =IF($R11="","",IFERROR(VLOOKUP(IF(ISNUMBER(FIND(" – ",$R11)),LEFT($R11,FIND(" – ",$R11)-1),$R11),ProdTbl,3,0),"کد ناشناخته")) | U11: 950 | V11: 9500 | X11: =IF($W11="","",IFERROR(VLOOKUP(IFERROR(VLOOKUP(IF(ISNUMBER(FIND(" – ",$W11)),LEFT($W11,FIND(" – ",$W11)-1),$W11),ProdTbl,5,0),""),BasketTbl,2,0),"کد ناشناخته")) | Y11: =IF($W11="","",IFERROR(VLOOKUP(IF(ISNUMBER(FIND(" – ",$W11)),LEFT($W11,FIND(" – ",$W11)-1),$W11),ProdTbl,3,0),"کد ناشناخته")) | AC11: =IF($AB11="","",IFERROR(VLOOKUP(IFERROR(VLOOKUP(IF(ISNUMBER(FIND(" – ",$AB11)),LEFT($AB11,FIND(" – ",$AB11)-1),$AB11),ProdTbl,5,0),""),BasketTbl,2,0),"کد ناشناخته")) | AD11: =IF($AB11="","",IFERROR(VLOOKUP(IF(ISNUMBER(FIND(" – ",$AB11)),LEFT($AB11,FIND(" – ",$AB11)-1),$AB11),ProdTbl,3,0),"کد ناشناخته")) | AH11: =IF($AG11="","",IFERROR(VLOOKUP(IFERROR(VLOOKUP(IF(ISNUMBER(FIND(" – ",$AG11)),LEFT($AG11,FIND(" – ",$AG11)-1),$AG11),ProdTbl,5,0),""),BasketTbl,2,0),"کد ناشناخته")) | AI11: =IF($AG11="","",IFERROR(VLOOKUP(IF(ISNUMBER(FIND(" – ",$AG11)),LEFT($AG11,FIND(" – ",$AG11)-1),$AG11),ProdTbl,3,0),"کد ناشناخته")) | AM11: =IF($AL11="","",IFERROR(VLOOKUP(IFERROR(VLOOKUP(IF(ISNUMBER(FIND(" – ",$AL11)),LEFT($AL11,FIND(" – ",$AL11)-1),$AL11),ProdTbl,5,0),""),BasketTbl,2,0),"کد ناشناخته")) | AN11: =IF($AL11="","",IFERROR(VLOOKUP(IF(ISNUMBER(FIND(" – ",$AL11)),LEFT($AL11,FIND(" – ",$AL11)-1),$AL11),ProdTbl,3,0),"کد ناشناخته")) | AR11: =IF($AQ11="","",IFERROR(VLOOKUP(IFERROR(VLOOKUP(IF(ISNUMBER(FIND(" – ",$AQ11)),LEFT($AQ11,FIND(" – ",$AQ11)-1),$AQ11),ProdTbl,5,0),""),BasketTbl,2,0),"کد ناشناخته")) | AS11: =IF($AQ11="","",IFERROR(VLOOKUP(IF(ISNUMBER(FIND(" – ",$AQ11)),LEFT($AQ11,FIND(" – ",$AQ11)-1),$AQ11),ProdTbl,3,0),"کد ناشناخته")) | AW11: =IF($AV11="","",IFERROR(VLOOKUP(IFERROR(VLOOKUP(IF(ISNUMBER(FIND(" – ",$AV11)),LEFT($AV11,FIND(" – ",$AV11)-1),$AV11),ProdTbl,5,0),""),BasketTbl,2,0),"کد ناشناخته")) | AX11: =IF($AV11="","",IFERROR(VLOOKUP(IF(ISNUMBER(FIND(" – ",$AV11)),LEFT($AV11,FIND(" – ",$AV11)-1),$AV11),ProdTbl,3,0),"کد ناشناخته")) | BB11: =IF($BA11="","",IFERROR(VLOOKUP(IFERROR(VLOOKUP(IF(ISNUMBER(FIND(" – ",$BA11)),LEFT($BA11,FIND(" – ",$BA11)-1),$BA11),ProdTbl,5,0),""),BasketTbl,2,0),"کد ناشناخته")) | BC11: =IF($BA11="","",IFERROR(VLOOKUP(IF(ISNUMBER(FIND(" – ",$BA11)),LEFT($BA11,FIND(" – ",$BA11)-1),$BA11),ProdTbl,3,0),"کد ناشناخته")) | BG11: =IF($BF11="","",IFERROR(VLOOKUP(IFERROR(VLOOKUP(IF(ISNUMBER(FIND(" – ",$BF11)),LEFT($BF11,FIND(" – ",$BF11)-1),$BF11),ProdTbl,5,0),""),BasketTbl,2,0),"کد ناشناخته")) | BH11: =IF($BF11="","",IFERROR(VLOOKUP(IF(ISNUMBER(FIND(" – ",$BF11)),LEFT($BF11,FIND(" – ",$BF11)-1),$BF11),ProdTbl,3,0),"کد ناشناخته")) | BL11: =IF($BK11="","",IFERROR(VLOOKUP(IFERROR(VLOOKUP(IF(ISNUMBER(FIND(" – ",$BK11)),LEFT($BK11,FIND(" – ",$BK11)-1),$BK11),ProdTbl,5,0),""),BasketTbl,2,0),"کد ناشناخته")) | BM11: =IF($BK11="","",IFERROR(VLOOKUP(IF(ISNUMBER(FIND(" – ",$BK11)),LEFT($BK11,FIND(" – ",$BK11)-1),$BK11),ProdTbl,3,0),"کد ناشناخته")) | BQ11: =IF($BP11="","",IFERROR(VLOOKUP(IFERROR(VLOOKUP(IF(ISNUMBER(FIND(" – ",$BP11)),LEFT($BP11,FIND(" – ",$BP11)-1),$BP11),ProdTbl,5,0),""),BasketTbl,2,0),"کد ناشناخته")) | BR11: =IF($BP11="","",IFERROR(VLOOKUP(IF(ISNUMBER(FIND(" – ",$BP11)),LEFT($BP11,FIND(" – ",$BP11)-1),$BP11),ProdTbl,3,0),"کد ناشناخته")) | BV11: =IF($BU11="","",IFERROR(VLOOKUP(IFERROR(VLOOKUP(IF(ISNUMBER(FIND(" – ",$BU11)),LEFT($BU11,FIND(" – ",$BU11)-1),$BU11),ProdTbl,5,0),""),BasketTbl,2,0),"کد ناشناخته")) | BW11: =IF($BU11="","",IFERROR(VLOOKUP(IF(ISNUMBER(FIND(" – ",$BU11)),LEFT($BU11,FIND(" – ",$BU11)-1),$BU11),ProdTbl,3,0),"کد ناشناخته")) | CA11: =IF($BZ11="","",IFERROR(VLOOKUP(IFERROR(VLOOKUP(IF(ISNUMBER(FIND(" – ",$BZ11)),LEFT($BZ11,FIND(" – ",$BZ11)-1),$BZ11),ProdTbl,5,0),""),BasketTbl,2,0),"کد ناشناخته")) | CB11: =IF($BZ11="","",IFERROR(VLOOKUP(IF(ISNUMBER(FIND(" – ",$BZ11)),LEFT($BZ11,FIND(" – ",$BZ11)-1),$BZ11),ProdTbl,3,0),"کد ناشناخته")) | CF11: =IF($CE11="","",IFERROR(VLOOKUP(IFERROR(VLOOKUP(IF(ISNUMBER(FIND(" – ",$CE11)),LEFT($CE11,FIND(" – ",$CE11)-1),$CE11),ProdTbl,5,0),""),BasketTbl,2,0),"کد ناشناخته")) | CG11: =IF($CE11="","",IFERROR(VLOOKUP(IF(ISNUMBER(FIND(" – ",$CE11)),LEFT($CE11,FIND(" – ",$CE11)-1),$CE11),ProdTbl,3,0),"کد ناشناخته"))
A12: =IF($B12="","",COUNTA($B$10:$B12)) | B12: 1405/07/08 | C12: 1003 | D12: SL003 – عباس نیک‌پی (نمونه — واسطه) | E12: =IF($D12="","",IFERROR(VLOOKUP(IF(ISNUMBER(FIND(" – ",$D12)),LEFT($D12,FIND(" – ",$D12)-1),$D12),SellerTbl,2,0),"کد ناشناخته")) | F12: 8000 | G12: 8000 | H12: 640000000 | I12: =IF(OR($F12="",$G12=""),"",$F12-$G12) | J12: =IF($I12="","",IF(ABS($I12)<=0.01*$F12,"√","×")) | K12: =IF(COUNT($Q12,$V12,$AA12,$AF12,$AK12,$AP12,$AU12,$AZ12,$BE12,$BJ12,$BO12,$BT12,$BY12,$CD12,$CI12)=0,"",SUM($Q12,$V12,$AA12,$AF12,$AK12,$AP12,$AU12,$AZ12,$BE12,$BJ12,$BO12,$BT12,$BY12,$CD12,$CI12)) | L12: =IF(OR($F12="",$K12=""),"",$F12-$K12) | M12: PS02 – پرتقال درجه ۲ — عمومی | N12: =IF($M12="","",IFERROR(VLOOKUP(IFERROR(VLOOKUP(IF(ISNUMBER(FIND(" – ",$M12)),LEFT($M12,FIND(" – ",$M12)-1),$M12),ProdTbl,5,0),""),BasketTbl,2,0),"کد ناشناخته")) | O12: =IF($M12="","",IFERROR(VLOOKUP(IF(ISNUMBER(FIND(" – ",$M12)),LEFT($M12,FIND(" – ",$M12)-1),$M12),ProdTbl,3,0),"کد ناشناخته")) | P12: 800 | Q12: 8000 | S12: =IF($R12="","",IFERROR(VLOOKUP(IFERROR(VLOOKUP(IF(ISNUMBER(FIND(" – ",$R12)),LEFT($R12,FIND(" – ",$R12)-1),$R12),ProdTbl,5,0),""),BasketTbl,2,0),"کد ناشناخته")) | T12: =IF($R12="","",IFERROR(VLOOKUP(IF(ISNUMBER(FIND(" – ",$R12)),LEFT($R12,FIND(" – ",$R12)-1),$R12),ProdTbl,3,0),"کد ناشناخته")) | X12: =IF($W12="","",IFERROR(VLOOKUP(IFERROR(VLOOKUP(IF(ISNUMBER(FIND(" – ",$W12)),LEFT($W12,FIND(" – ",$W12)-1),$W12),ProdTbl,5,0),""),BasketTbl,2,0),"کد ناشناخته")) | Y12: =IF($W12="","",IFERROR(VLOOKUP(IF(ISNUMBER(FIND(" – ",$W12)),LEFT($W12,FIND(" – ",$W12)-1),$W12),ProdTbl,3,0),"کد ناشناخته")) | AC12: =IF($AB12="","",IFERROR(VLOOKUP(IFERROR(VLOOKUP(IF(ISNUMBER(FIND(" – ",$AB12)),LEFT($AB12,FIND(" – ",$AB12)-1),$AB12),ProdTbl,5,0),""),BasketTbl,2,0),"کد ناشناخته")) | AD12: =IF($AB12="","",IFERROR(VLOOKUP(IF(ISNUMBER(FIND(" – ",$AB12)),LEFT($AB12,FIND(" – ",$AB12)-1),$AB12),ProdTbl,3,0),"کد ناشناخته")) | AH12: =IF($AG12="","",IFERROR(VLOOKUP(IFERROR(VLOOKUP(IF(ISNUMBER(FIND(" – ",$AG12)),LEFT($AG12,FIND(" – ",$AG12)-1),$AG12),ProdTbl,5,0),""),BasketTbl,2,0),"کد ناشناخته")) | AI12: =IF($AG12="","",IFERROR(VLOOKUP(IF(ISNUMBER(FIND(" – ",$AG12)),LEFT($AG12,FIND(" – ",$AG12)-1),$AG12),ProdTbl,3,0),"کد ناشناخته")) | AM12: =IF($AL12="","",IFERROR(VLOOKUP(IFERROR(VLOOKUP(IF(ISNUMBER(FIND(" – ",$AL12)),LEFT($AL12,FIND(" – ",$AL12)-1),$AL12),ProdTbl,5,0),""),BasketTbl,2,0),"کد ناشناخته")) | AN12: =IF($AL12="","",IFERROR(VLOOKUP(IF(ISNUMBER(FIND(" – ",$AL12)),LEFT($AL12,FIND(" – ",$AL12)-1),$AL12),ProdTbl,3,0),"کد ناشناخته")) | AR12: =IF($AQ12="","",IFERROR(VLOOKUP(IFERROR(VLOOKUP(IF(ISNUMBER(FIND(" – ",$AQ12)),LEFT($AQ12,FIND(" – ",$AQ12)-1),$AQ12),ProdTbl,5,0),""),BasketTbl,2,0),"کد ناشناخته")) | AS12: =IF($AQ12="","",IFERROR(VLOOKUP(IF(ISNUMBER(FIND(" – ",$AQ12)),LEFT($AQ12,FIND(" – ",$AQ12)-1),$AQ12),ProdTbl,3,0),"کد ناشناخته")) | AW12: =IF($AV12="","",IFERROR(VLOOKUP(IFERROR(VLOOKUP(IF(ISNUMBER(FIND(" – ",$AV12)),LEFT($AV12,FIND(" – ",$AV12)-1),$AV12),ProdTbl,5,0),""),BasketTbl,2,0),"کد ناشناخته")) | AX12: =IF($AV12="","",IFERROR(VLOOKUP(IF(ISNUMBER(FIND(" – ",$AV12)),LEFT($AV12,FIND(" – ",$AV12)-1),$AV12),ProdTbl,3,0),"کد ناشناخته")) | BB12: =IF($BA12="","",IFERROR(VLOOKUP(IFERROR(VLOOKUP(IF(ISNUMBER(FIND(" – ",$BA12)),LEFT($BA12,FIND(" – ",$BA12)-1),$BA12),ProdTbl,5,0),""),BasketTbl,2,0),"کد ناشناخته")) | BC12: =IF($BA12="","",IFERROR(VLOOKUP(IF(ISNUMBER(FIND(" – ",$BA12)),LEFT($BA12,FIND(" – ",$BA12)-1),$BA12),ProdTbl,3,0),"کد ناشناخته")) | BG12: =IF($BF12="","",IFERROR(VLOOKUP(IFERROR(VLOOKUP(IF(ISNUMBER(FIND(" – ",$BF12)),LEFT($BF12,FIND(" – ",$BF12)-1),$BF12),ProdTbl,5,0),""),BasketTbl,2,0),"کد ناشناخته")) | BH12: =IF($BF12="","",IFERROR(VLOOKUP(IF(ISNUMBER(FIND(" – ",$BF12)),LEFT($BF12,FIND(" – ",$BF12)-1),$BF12),ProdTbl,3,0),"کد ناشناخته")) | BL12: =IF($BK12="","",IFERROR(VLOOKUP(IFERROR(VLOOKUP(IF(ISNUMBER(FIND(" – ",$BK12)),LEFT($BK12,FIND(" – ",$BK12)-1),$BK12),ProdTbl,5,0),""),BasketTbl,2,0),"کد ناشناخته")) | BM12: =IF($BK12="","",IFERROR(VLOOKUP(IF(ISNUMBER(FIND(" – ",$BK12)),LEFT($BK12,FIND(" – ",$BK12)-1),$BK12),ProdTbl,3,0),"کد ناشناخته")) | BQ12: =IF($BP12="","",IFERROR(VLOOKUP(IFERROR(VLOOKUP(IF(ISNUMBER(FIND(" – ",$BP12)),LEFT($BP12,FIND(" – ",$BP12)-1),$BP12),ProdTbl,5,0),""),BasketTbl,2,0),"کد ناشناخته")) | BR12: =IF($BP12="","",IFERROR(VLOOKUP(IF(ISNUMBER(FIND(" – ",$BP12)),LEFT($BP12,FIND(" – ",$BP12)-1),$BP12),ProdTbl,3,0),"کد ناشناخته")) | BV12: =IF($BU12="","",IFERROR(VLOOKUP(IFERROR(VLOOKUP(IF(ISNUMBER(FIND(" – ",$BU12)),LEFT($BU12,FIND(" – ",$BU12)-1),$BU12),ProdTbl,5,0),""),BasketTbl,2,0),"کد ناشناخته")) | BW12: =IF($BU12="","",IFERROR(VLOOKUP(IF(ISNUMBER(FIND(" – ",$BU12)),LEFT($BU12,FIND(" – ",$BU12)-1),$BU12),ProdTbl,3,0),"کد ناشناخته")) | CA12: =IF($BZ12="","",IFERROR(VLOOKUP(IFERROR(VLOOKUP(IF(ISNUMBER(FIND(" – ",$BZ12)),LEFT($BZ12,FIND(" – ",$BZ12)-1),$BZ12),ProdTbl,5,0),""),BasketTbl,2,0),"کد ناشناخته")) | CB12: =IF($BZ12="","",IFERROR(VLOOKUP(IF(ISNUMBER(FIND(" – ",$BZ12)),LEFT($BZ12,FIND(" – ",$BZ12)-1),$BZ12),ProdTbl,3,0),"کد ناشناخته")) | CF12: =IF($CE12="","",IFERROR(VLOOKUP(IFERROR(VLOOKUP(IF(ISNUMBER(FIND(" – ",$CE12)),LEFT($CE12,FIND(" – ",$CE12)-1),$CE12),ProdTbl,5,0),""),BasketTbl,2,0),"کد ناشناخته")) | CG12: =IF($CE12="","",IFERROR(VLOOKUP(IF(ISNUMBER(FIND(" – ",$CE12)),LEFT($CE12,FIND(" – ",$CE12)-1),$CE12),ProdTbl,3,0),"کد ناشناخته"))
A13: =IF($B13="","",COUNTA($B$10:$B13)) | B13: 1405/07/10 | C13: 1004 | D13: SL004 | E13: =IF($D13="","",IFERROR(VLOOKUP(IF(ISNUMBER(FIND(" – ",$D13)),LEFT($D13,FIND(" – ",$D13)-1),$D13),SellerTbl,2,0),"کد ناشناخته")) | F13: 5000 | G13: 4990 | H13: 400000000 | I13: =IF(OR($F13="",$G13=""),"",$F13-$G13) | J13: =IF($I13="","",IF(ABS($I13)<=0.01*$F13,"√","×")) | K13: =IF(COUNT($Q13,$V13,$AA13,$AF13,$AK13,$AP13,$AU13,$AZ13,$BE13,$BJ13,$BO13,$BT13,$BY13,$CD13,$CI13)=0,"",SUM($Q13,$V13,$AA13,$AF13,$AK13,$AP13,$AU13,$AZ13,$BE13,$BJ13,$BO13,$BT13,$BY13,$CD13,$CI13)) | L13: =IF(OR($F13="",$K13=""),"",$F13-$K13) | M13: PS01 | N13: =IF($M13="","",IFERROR(VLOOKUP(IFERROR(VLOOKUP(IF(ISNUMBER(FIND(" – ",$M13)),LEFT($M13,FIND(" – ",$M13)-1),$M13),ProdTbl,5,0),""),BasketTbl,2,0),"کد ناشناخته")) | O13: =IF($M13="","",IFERROR(VLOOKUP(IF(ISNUMBER(FIND(" – ",$M13)),LEFT($M13,FIND(" – ",$M13)-1),$M13),ProdTbl,3,0),"کد ناشناخته")) | P13: 499 | Q13: 4990 | S13: =IF($R13="","",IFERROR(VLOOKUP(IFERROR(VLOOKUP(IF(ISNUMBER(FIND(" – ",$R13)),LEFT($R13,FIND(" – ",$R13)-1),$R13),ProdTbl,5,0),""),BasketTbl,2,0),"کد ناشناخته")) | T13: =IF($R13="","",IFERROR(VLOOKUP(IF(ISNUMBER(FIND(" – ",$R13)),LEFT($R13,FIND(" – ",$R13)-1),$R13),ProdTbl,3,0),"کد ناشناخته")) | X13: =IF($W13="","",IFERROR(VLOOKUP(IFERROR(VLOOKUP(IF(ISNUMBER(FIND(" – ",$W13)),LEFT($W13,FIND(" – ",$W13)-1),$W13),ProdTbl,5,0),""),BasketTbl,2,0),"کد ناشناخته")) | Y13: =IF($W13="","",IFERROR(VLOOKUP(IF(ISNUMBER(FIND(" – ",$W13)),LEFT($W13,FIND(" – ",$W13)-1),$W13),ProdTbl,3,0),"کد ناشناخته")) | AC13: =IF($AB13="","",IFERROR(VLOOKUP(IFERROR(VLOOKUP(IF(ISNUMBER(FIND(" – ",$AB13)),LEFT($AB13,FIND(" – ",$AB13)-1),$AB13),ProdTbl,5,0),""),BasketTbl,2,0),"کد ناشناخته")) | AD13: =IF($AB13="","",IFERROR(VLOOKUP(IF(ISNUMBER(FIND(" – ",$AB13)),LEFT($AB13,FIND(" – ",$AB13)-1),$AB13),ProdTbl,3,0),"کد ناشناخته")) | AH13: =IF($AG13="","",IFERROR(VLOOKUP(IFERROR(VLOOKUP(IF(ISNUMBER(FIND(" – ",$AG13)),LEFT($AG13,FIND(" – ",$AG13)-1),$AG13),ProdTbl,5,0),""),BasketTbl,2,0),"کد ناشناخته")) | AI13: =IF($AG13="","",IFERROR(VLOOKUP(IF(ISNUMBER(FIND(" – ",$AG13)),LEFT($AG13,FIND(" – ",$AG13)-1),$AG13),ProdTbl,3,0),"کد ناشناخته")) | AM13: =IF($AL13="","",IFERROR(VLOOKUP(IFERROR(VLOOKUP(IF(ISNUMBER(FIND(" – ",$AL13)),LEFT($AL13,FIND(" – ",$AL13)-1),$AL13),ProdTbl,5,0),""),BasketTbl,2,0),"کد ناشناخته")) | AN13: =IF($AL13="","",IFERROR(VLOOKUP(IF(ISNUMBER(FIND(" – ",$AL13)),LEFT($AL13,FIND(" – ",$AL13)-1),$AL13),ProdTbl,3,0),"کد ناشناخته")) | AR13: =IF($AQ13="","",IFERROR(VLOOKUP(IFERROR(VLOOKUP(IF(ISNUMBER(FIND(" – ",$AQ13)),LEFT($AQ13,FIND(" – ",$AQ13)-1),$AQ13),ProdTbl,5,0),""),BasketTbl,2,0),"کد ناشناخته")) | AS13: =IF($AQ13="","",IFERROR(VLOOKUP(IF(ISNUMBER(FIND(" – ",$AQ13)),LEFT($AQ13,FIND(" – ",$AQ13)-1),$AQ13),ProdTbl,3,0),"کد ناشناخته")) | AW13: =IF($AV13="","",IFERROR(VLOOKUP(IFERROR(VLOOKUP(IF(ISNUMBER(FIND(" – ",$AV13)),LEFT($AV13,FIND(" – ",$AV13)-1),$AV13),ProdTbl,5,0),""),BasketTbl,2,0),"کد ناشناخته")) | AX13: =IF($AV13="","",IFERROR(VLOOKUP(IF(ISNUMBER(FIND(" – ",$AV13)),LEFT($AV13,FIND(" – ",$AV13)-1),$AV13),ProdTbl,3,0),"کد ناشناخته")) | BB13: =IF($BA13="","",IFERROR(VLOOKUP(IFERROR(VLOOKUP(IF(ISNUMBER(FIND(" – ",$BA13)),LEFT($BA13,FIND(" – ",$BA13)-1),$BA13),ProdTbl,5,0),""),BasketTbl,2,0),"کد ناشناخته")) | BC13: =IF($BA13="","",IFERROR(VLOOKUP(IF(ISNUMBER(FIND(" – ",$BA13)),LEFT($BA13,FIND(" – ",$BA13)-1),$BA13),ProdTbl,3,0),"کد ناشناخته")) | BG13: =IF($BF13="","",IFERROR(VLOOKUP(IFERROR(VLOOKUP(IF(ISNUMBER(FIND(" – ",$BF13)),LEFT($BF13,FIND(" – ",$BF13)-1),$BF13),ProdTbl,5,0),""),BasketTbl,2,0),"کد ناشناخته")) | BH13: =IF($BF13="","",IFERROR(VLOOKUP(IF(ISNUMBER(FIND(" – ",$BF13)),LEFT($BF13,FIND(" – ",$BF13)-1),$BF13),ProdTbl,3,0),"کد ناشناخته")) | BL13: =IF($BK13="","",IFERROR(VLOOKUP(IFERROR(VLOOKUP(IF(ISNUMBER(FIND(" – ",$BK13)),LEFT($BK13,FIND(" – ",$BK13)-1),$BK13),ProdTbl,5,0),""),BasketTbl,2,0),"کد ناشناخته")) | BM13: =IF($BK13="","",IFERROR(VLOOKUP(IF(ISNUMBER(FIND(" – ",$BK13)),LEFT($BK13,FIND(" – ",$BK13)-1),$BK13),ProdTbl,3,0),"کد ناشناخته")) | BQ13: =IF($BP13="","",IFERROR(VLOOKUP(IFERROR(VLOOKUP(IF(ISNUMBER(FIND(" – ",$BP13)),LEFT($BP13,FIND(" – ",$BP13)-1),$BP13),ProdTbl,5,0),""),BasketTbl,2,0),"کد ناشناخته")) | BR13: =IF($BP13="","",IFERROR(VLOOKUP(IF(ISNUMBER(FIND(" – ",$BP13)),LEFT($BP13,FIND(" – ",$BP13)-1),$BP13),ProdTbl,3,0),"کد ناشناخته")) | BV13: =IF($BU13="","",IFERROR(VLOOKUP(IFERROR(VLOOKUP(IF(ISNUMBER(FIND(" – ",$BU13)),LEFT($BU13,FIND(" – ",$BU13)-1),$BU13),ProdTbl,5,0),""),BasketTbl,2,0),"کد ناشناخته")) | BW13: =IF($BU13="","",IFERROR(VLOOKUP(IF(ISNUMBER(FIND(" – ",$BU13)),LEFT($BU13,FIND(" – ",$BU13)-1),$BU13),ProdTbl,3,0),"کد ناشناخته")) | CA13: =IF($BZ13="","",IFERROR(VLOOKUP(IFERROR(VLOOKUP(IF(ISNUMBER(FIND(" – ",$BZ13)),LEFT($BZ13,FIND(" – ",$BZ13)-1),$BZ13),ProdTbl,5,0),""),BasketTbl,2,0),"کد ناشناخته")) | CB13: =IF($BZ13="","",IFERROR(VLOOKUP(IF(ISNUMBER(FIND(" – ",$BZ13)),LEFT($BZ13,FIND(" – ",$BZ13)-1),$BZ13),ProdTbl,3,0),"کد ناشناخته")) | CF13: =IF($CE13="","",IFERROR(VLOOKUP(IFERROR(VLOOKUP(IF(ISNUMBER(FIND(" – ",$CE13)),LEFT($CE13,FIND(" – ",$CE13)-1),$CE13),ProdTbl,5,0),""),BasketTbl,2,0),"کد ناشناخته")) | CG13: =IF($CE13="","",IFERROR(VLOOKUP(IF(ISNUMBER(FIND(" – ",$CE13)),LEFT($CE13,FIND(" – ",$CE13)-1),$CE13),ProdTbl,3,0),"کد ناشناخته"))
A14: =IF($B14="","",COUNTA($B$10:$B14)) | E14: =IF($D14="","",IFERROR(VLOOKUP(IF(ISNUMBER(FIND(" – ",$D14)),LEFT($D14,FIND(" – ",$D14)-1),$D14),SellerTbl,2,0),"کد ناشناخته")) | I14: =IF(OR($F14="",$G14=""),"",$F14-$G14) | J14: =IF($I14="","",IF(ABS($I14)<=0.01*$F14,"√","×")) | K14: =IF(COUNT($Q14,$V14,$AA14,$AF14,$AK14,$AP14,$AU14,$AZ14,$BE14,$BJ14,$BO14,$BT14,$BY14,$CD14,$CI14)=0,"",SUM($Q14,$V14,$AA14,$AF14,$AK14,$AP14,$AU14,$AZ14,$BE14,$BJ14,$BO14,$BT14,$BY14,$CD14,$CI14)) | L14: =IF(OR($F14="",$K14=""),"",$F14-$K14) | N14: =IF($M14="","",IFERROR(VLOOKUP(IFERROR(VLOOKUP(IF(ISNUMBER(FIND(" – ",$M14)),LEFT($M14,FIND(" – ",$M14)-1),$M14),ProdTbl,5,0),""),BasketTbl,2,0),"کد ناشناخته")) | O14: =IF($M14="","",IFERROR(VLOOKUP(IF(ISNUMBER(FIND(" – ",$M14)),LEFT($M14,FIND(" – ",$M14)-1),$M14),ProdTbl,3,0),"کد ناشناخته")) | S14: =IF($R14="","",IFERROR(VLOOKUP(IFERROR(VLOOKUP(IF(ISNUMBER(FIND(" – ",$R14)),LEFT($R14,FIND(" – ",$R14)-1),$R14),ProdTbl,5,0),""),BasketTbl,2,0),"کد ناشناخته")) | T14: =IF($R14="","",IFERROR(VLOOKUP(IF(ISNUMBER(FIND(" – ",$R14)),LEFT($R14,FIND(" – ",$R14)-1),$R14),ProdTbl,3,0),"کد ناشناخته")) | X14: =IF($W14="","",IFERROR(VLOOKUP(IFERROR(VLOOKUP(IF(ISNUMBER(FIND(" – ",$W14)),LEFT($W14,FIND(" – ",$W14)-1),$W14),ProdTbl,5,0),""),BasketTbl,2,0),"کد ناشناخته")) | Y14: =IF($W14="","",IFERROR(VLOOKUP(IF(ISNUMBER(FIND(" – ",$W14)),LEFT($W14,FIND(" – ",$W14)-1),$W14),ProdTbl,3,0),"کد ناشناخته")) | AC14: =IF($AB14="","",IFERROR(VLOOKUP(IFERROR(VLOOKUP(IF(ISNUMBER(FIND(" – ",$AB14)),LEFT($AB14,FIND(" – ",$AB14)-1),$AB14),ProdTbl,5,0),""),BasketTbl,2,0),"کد ناشناخته")) | AD14: =IF($AB14="","",IFERROR(VLOOKUP(IF(ISNUMBER(FIND(" – ",$AB14)),LEFT($AB14,FIND(" – ",$AB14)-1),$AB14),ProdTbl,3,0),"کد ناشناخته")) | AH14: =IF($AG14="","",IFERROR(VLOOKUP(IFERROR(VLOOKUP(IF(ISNUMBER(FIND(" – ",$AG14)),LEFT($AG14,FIND(" – ",$AG14)-1),$AG14),ProdTbl,5,0),""),BasketTbl,2,0),"کد ناشناخته")) | AI14: =IF($AG14="","",IFERROR(VLOOKUP(IF(ISNUMBER(FIND(" – ",$AG14)),LEFT($AG14,FIND(" – ",$AG14)-1),$AG14),ProdTbl,3,0),"کد ناشناخته")) | AM14: =IF($AL14="","",IFERROR(VLOOKUP(IFERROR(VLOOKUP(IF(ISNUMBER(FIND(" – ",$AL14)),LEFT($AL14,FIND(" – ",$AL14)-1),$AL14),ProdTbl,5,0),""),BasketTbl,2,0),"کد ناشناخته")) | AN14: =IF($AL14="","",IFERROR(VLOOKUP(IF(ISNUMBER(FIND(" – ",$AL14)),LEFT($AL14,FIND(" – ",$AL14)-1),$AL14),ProdTbl,3,0),"کد ناشناخته")) | AR14: =IF($AQ14="","",IFERROR(VLOOKUP(IFERROR(VLOOKUP(IF(ISNUMBER(FIND(" – ",$AQ14)),LEFT($AQ14,FIND(" – ",$AQ14)-1),$AQ14),ProdTbl,5,0),""),BasketTbl,2,0),"کد ناشناخته")) | AS14: =IF($AQ14="","",IFERROR(VLOOKUP(IF(ISNUMBER(FIND(" – ",$AQ14)),LEFT($AQ14,FIND(" – ",$AQ14)-1),$AQ14),ProdTbl,3,0),"کد ناشناخته")) | AW14: =IF($AV14="","",IFERROR(VLOOKUP(IFERROR(VLOOKUP(IF(ISNUMBER(FIND(" – ",$AV14)),LEFT($AV14,FIND(" – ",$AV14)-1),$AV14),ProdTbl,5,0),""),BasketTbl,2,0),"کد ناشناخته")) | AX14: =IF($AV14="","",IFERROR(VLOOKUP(IF(ISNUMBER(FIND(" – ",$AV14)),LEFT($AV14,FIND(" – ",$AV14)-1),$AV14),ProdTbl,3,0),"کد ناشناخته")) | BB14: =IF($BA14="","",IFERROR(VLOOKUP(IFERROR(VLOOKUP(IF(ISNUMBER(FIND(" – ",$BA14)),LEFT($BA14,FIND(" – ",$BA14)-1),$BA14),ProdTbl,5,0),""),BasketTbl,2,0),"کد ناشناخته")) | BC14: =IF($BA14="","",IFERROR(VLOOKUP(IF(ISNUMBER(FIND(" – ",$BA14)),LEFT($BA14,FIND(" – ",$BA14)-1),$BA14),ProdTbl,3,0),"کد ناشناخته")) | BG14: =IF($BF14="","",IFERROR(VLOOKUP(IFERROR(VLOOKUP(IF(ISNUMBER(FIND(" – ",$BF14)),LEFT($BF14,FIND(" – ",$BF14)-1),$BF14),ProdTbl,5,0),""),BasketTbl,2,0),"کد ناشناخته")) | BH14: =IF($BF14="","",IFERROR(VLOOKUP(IF(ISNUMBER(FIND(" – ",$BF14)),LEFT($BF14,FIND(" – ",$BF14)-1),$BF14),ProdTbl,3,0),"کد ناشناخته")) | BL14: =IF($BK14="","",IFERROR(VLOOKUP(IFERROR(VLOOKUP(IF(ISNUMBER(FIND(" – ",$BK14)),LEFT($BK14,FIND(" – ",$BK14)-1),$BK14),ProdTbl,5,0),""),BasketTbl,2,0),"کد ناشناخته")) | BM14: =IF($BK14="","",IFERROR(VLOOKUP(IF(ISNUMBER(FIND(" – ",$BK14)),LEFT($BK14,FIND(" – ",$BK14)-1),$BK14),ProdTbl,3,0),"کد ناشناخته")) | BQ14: =IF($BP14="","",IFERROR(VLOOKUP(IFERROR(VLOOKUP(IF(ISNUMBER(FIND(" – ",$BP14)),LEFT($BP14,FIND(" – ",$BP14)-1),$BP14),ProdTbl,5,0),""),BasketTbl,2,0),"کد ناشناخته")) | BR14: =IF($BP14="","",IFERROR(VLOOKUP(IF(ISNUMBER(FIND(" – ",$BP14)),LEFT($BP14,FIND(" – ",$BP14)-1),$BP14),ProdTbl,3,0),"کد ناشناخته")) | BV14: =IF($BU14="","",IFERROR(VLOOKUP(IFERROR(VLOOKUP(IF(ISNUMBER(FIND(" – ",$BU14)),LEFT($BU14,FIND(" – ",$BU14)-1),$BU14),ProdTbl,5,0),""),BasketTbl,2,0),"کد ناشناخته")) | BW14: =IF($BU14="","",IFERROR(VLOOKUP(IF(ISNUMBER(FIND(" – ",$BU14)),LEFT($BU14,FIND(" – ",$BU14)-1),$BU14),ProdTbl,3,0),"کد ناشناخته")) | CA14: =IF($BZ14="","",IFERROR(VLOOKUP(IFERROR(VLOOKUP(IF(ISNUMBER(FIND(" – ",$BZ14)),LEFT($BZ14,FIND(" – ",$BZ14)-1),$BZ14),ProdTbl,5,0),""),BasketTbl,2,0),"کد ناشناخته")) | CB14: =IF($BZ14="","",IFERROR(VLOOKUP(IF(ISNUMBER(FIND(" – ",$BZ14)),LEFT($BZ14,FIND(" – ",$BZ14)-1),$BZ14),ProdTbl,3,0),"کد ناشناخته")) | CF14: =IF($CE14="","",IFERROR(VLOOKUP(IFERROR(VLOOKUP(IF(ISNUMBER(FIND(" – ",$CE14)),LEFT($CE14,FIND(" – ",$CE14)-1),$CE14),ProdTbl,5,0),""),BasketTbl,2,0),"کد ناشناخته")) | CG14: =IF($CE14="","",IFERROR(VLOOKUP(IF(ISNUMBER(FIND(" – ",$CE14)),LEFT($CE14,FIND(" – ",$CE14)-1),$CE14),ProdTbl,3,0),"کد ناشناخته"))
A15: =IF($B15="","",COUNTA($B$10:$B15)) | E15: =IF($D15="","",IFERROR(VLOOKUP(IF(ISNUMBER(FIND(" – ",$D15)),LEFT($D15,FIND(" – ",$D15)-1),$D15),SellerTbl,2,0),"کد ناشناخته")) | I15: =IF(OR($F15="",$G15=""),"",$F15-$G15) | J15: =IF($I15="","",IF(ABS($I15)<=0.01*$F15,"√","×")) | K15: =IF(COUNT($Q15,$V15,$AA15,$AF15,$AK15,$AP15,$AU15,$AZ15,$BE15,$BJ15,$BO15,$BT15,$BY15,$CD15,$CI15)=0,"",SUM($Q15,$V15,$AA15,$AF15,$AK15,$AP15,$AU15,$AZ15,$BE15,$BJ15,$BO15,$BT15,$BY15,$CD15,$CI15)) | L15: =IF(OR($F15="",$K15=""),"",$F15-$K15) | N15: =IF($M15="","",IFERROR(VLOOKUP(IFERROR(VLOOKUP(IF(ISNUMBER(FIND(" – ",$M15)),LEFT($M15,FIND(" – ",$M15)-1),$M15),ProdTbl,5,0),""),BasketTbl,2,0),"کد ناشناخته")) | O15: =IF($M15="","",IFERROR(VLOOKUP(IF(ISNUMBER(FIND(" – ",$M15)),LEFT($M15,FIND(" – ",$M15)-1),$M15),ProdTbl,3,0),"کد ناشناخته")) | S15: =IF($R15="","",IFERROR(VLOOKUP(IFERROR(VLOOKUP(IF(ISNUMBER(FIND(" – ",$R15)),LEFT($R15,FIND(" – ",$R15)-1),$R15),ProdTbl,5,0),""),BasketTbl,2,0),"کد ناشناخته")) | T15: =IF($R15="","",IFERROR(VLOOKUP(IF(ISNUMBER(FIND(" – ",$R15)),LEFT($R15,FIND(" – ",$R15)-1),$R15),ProdTbl,3,0),"کد ناشناخته")) | X15: =IF($W15="","",IFERROR(VLOOKUP(IFERROR(VLOOKUP(IF(ISNUMBER(FIND(" – ",$W15)),LEFT($W15,FIND(" – ",$W15)-1),$W15),ProdTbl,5,0),""),BasketTbl,2,0),"کد ناشناخته")) | Y15: =IF($W15="","",IFERROR(VLOOKUP(IF(ISNUMBER(FIND(" – ",$W15)),LEFT($W15,FIND(" – ",$W15)-1),$W15),ProdTbl,3,0),"کد ناشناخته")) | AC15: =IF($AB15="","",IFERROR(VLOOKUP(IFERROR(VLOOKUP(IF(ISNUMBER(FIND(" – ",$AB15)),LEFT($AB15,FIND(" – ",$AB15)-1),$AB15),ProdTbl,5,0),""),BasketTbl,2,0),"کد ناشناخته")) | AD15: =IF($AB15="","",IFERROR(VLOOKUP(IF(ISNUMBER(FIND(" – ",$AB15)),LEFT($AB15,FIND(" – ",$AB15)-1),$AB15),ProdTbl,3,0),"کد ناشناخته")) | AH15: =IF($AG15="","",IFERROR(VLOOKUP(IFERROR(VLOOKUP(IF(ISNUMBER(FIND(" – ",$AG15)),LEFT($AG15,FIND(" – ",$AG15)-1),$AG15),ProdTbl,5,0),""),BasketTbl,2,0),"کد ناشناخته")) | AI15: =IF($AG15="","",IFERROR(VLOOKUP(IF(ISNUMBER(FIND(" – ",$AG15)),LEFT($AG15,FIND(" – ",$AG15)-1),$AG15),ProdTbl,3,0),"کد ناشناخته")) | AM15: =IF($AL15="","",IFERROR(VLOOKUP(IFERROR(VLOOKUP(IF(ISNUMBER(FIND(" – ",$AL15)),LEFT($AL15,FIND(" – ",$AL15)-1),$AL15),ProdTbl,5,0),""),BasketTbl,2,0),"کد ناشناخته")) | AN15: =IF($AL15="","",IFERROR(VLOOKUP(IF(ISNUMBER(FIND(" – ",$AL15)),LEFT($AL15,FIND(" – ",$AL15)-1),$AL15),ProdTbl,3,0),"کد ناشناخته")) | AR15: =IF($AQ15="","",IFERROR(VLOOKUP(IFERROR(VLOOKUP(IF(ISNUMBER(FIND(" – ",$AQ15)),LEFT($AQ15,FIND(" – ",$AQ15)-1),$AQ15),ProdTbl,5,0),""),BasketTbl,2,0),"کد ناشناخته")) | AS15: =IF($AQ15="","",IFERROR(VLOOKUP(IF(ISNUMBER(FIND(" – ",$AQ15)),LEFT($AQ15,FIND(" – ",$AQ15)-1),$AQ15),ProdTbl,3,0),"کد ناشناخته")) | AW15: =IF($AV15="","",IFERROR(VLOOKUP(IFERROR(VLOOKUP(IF(ISNUMBER(FIND(" – ",$AV15)),LEFT($AV15,FIND(" – ",$AV15)-1),$AV15),ProdTbl,5,0),""),BasketTbl,2,0),"کد ناشناخته")) | AX15: =IF($AV15="","",IFERROR(VLOOKUP(IF(ISNUMBER(FIND(" – ",$AV15)),LEFT($AV15,FIND(" – ",$AV15)-1),$AV15),ProdTbl,3,0),"کد ناشناخته")) | BB15: =IF($BA15="","",IFERROR(VLOOKUP(IFERROR(VLOOKUP(IF(ISNUMBER(FIND(" – ",$BA15)),LEFT($BA15,FIND(" – ",$BA15)-1),$BA15),ProdTbl,5,0),""),BasketTbl,2,0),"کد ناشناخته")) | BC15: =IF($BA15="","",IFERROR(VLOOKUP(IF(ISNUMBER(FIND(" – ",$BA15)),LEFT($BA15,FIND(" – ",$BA15)-1),$BA15),ProdTbl,3,0),"کد ناشناخته")) | BG15: =IF($BF15="","",IFERROR(VLOOKUP(IFERROR(VLOOKUP(IF(ISNUMBER(FIND(" – ",$BF15)),LEFT($BF15,FIND(" – ",$BF15)-1),$BF15),ProdTbl,5,0),""),BasketTbl,2,0),"کد ناشناخته")) | BH15: =IF($BF15="","",IFERROR(VLOOKUP(IF(ISNUMBER(FIND(" – ",$BF15)),LEFT($BF15,FIND(" – ",$BF15)-1),$BF15),ProdTbl,3,0),"کد ناشناخته")) | BL15: =IF($BK15="","",IFERROR(VLOOKUP(IFERROR(VLOOKUP(IF(ISNUMBER(FIND(" – ",$BK15)),LEFT($BK15,FIND(" – ",$BK15)-1),$BK15),ProdTbl,5,0),""),BasketTbl,2,0),"کد ناشناخته")) | BM15: =IF($BK15="","",IFERROR(VLOOKUP(IF(ISNUMBER(FIND(" – ",$BK15)),LEFT($BK15,FIND(" – ",$BK15)-1),$BK15),ProdTbl,3,0),"کد ناشناخته")) | BQ15: =IF($BP15="","",IFERROR(VLOOKUP(IFERROR(VLOOKUP(IF(ISNUMBER(FIND(" – ",$BP15)),LEFT($BP15,FIND(" – ",$BP15)-1),$BP15),ProdTbl,5,0),""),BasketTbl,2,0),"کد ناشناخته")) | BR15: =IF($BP15="","",IFERROR(VLOOKUP(IF(ISNUMBER(FIND(" – ",$BP15)),LEFT($BP15,FIND(" – ",$BP15)-1),$BP15),ProdTbl,3,0),"کد ناشناخته")) | BV15: =IF($BU15="","",IFERROR(VLOOKUP(IFERROR(VLOOKUP(IF(ISNUMBER(FIND(" – ",$BU15)),LEFT($BU15,FIND(" – ",$BU15)-1),$BU15),ProdTbl,5,0),""),BasketTbl,2,0),"کد ناشناخته")) | BW15: =IF($BU15="","",IFERROR(VLOOKUP(IF(ISNUMBER(FIND(" – ",$BU15)),LEFT($BU15,FIND(" – ",$BU15)-1),$BU15),ProdTbl,3,0),"کد ناشناخته")) | CA15: =IF($BZ15="","",IFERROR(VLOOKUP(IFERROR(VLOOKUP(IF(ISNUMBER(FIND(" – ",$BZ15)),LEFT($BZ15,FIND(" – ",$BZ15)-1),$BZ15),ProdTbl,5,0),""),BasketTbl,2,0),"کد ناشناخته")) | CB15: =IF($BZ15="","",IFERROR(VLOOKUP(IF(ISNUMBER(FIND(" – ",$BZ15)),LEFT($BZ15,FIND(" – ",$BZ15)-1),$BZ15),ProdTbl,3,0),"کد ناشناخته")) | CF15: =IF($CE15="","",IFERROR(VLOOKUP(IFERROR(VLOOKUP(IF(ISNUMBER(FIND(" – ",$CE15)),LEFT($CE15,FIND(" – ",$CE15)-1),$CE15),ProdTbl,5,0),""),BasketTbl,2,0),"کد ناشناخته")) | CG15: =IF($CE15="","",IFERROR(VLOOKUP(IF(ISNUMBER(FIND(" – ",$CE15)),LEFT($CE15,FIND(" – ",$CE15)-1),$CE15),ProdTbl,3,0),"کد ناشناخته"))
A16: =IF($B16="","",COUNTA($B$10:$B16)) | E16: =IF($D16="","",IFERROR(VLOOKUP(IF(ISNUMBER(FIND(" – ",$D16)),LEFT($D16,FIND(" – ",$D16)-1),$D16),SellerTbl,2,0),"کد ناشناخته")) | I16: =IF(OR($F16="",$G16=""),"",$F16-$G16) | J16: =IF($I16="","",IF(ABS($I16)<=0.01*$F16,"√","×")) | K16: =IF(COUNT($Q16,$V16,$AA16,$AF16,$AK16,$AP16,$AU16,$AZ16,$BE16,$BJ16,$BO16,$BT16,$BY16,$CD16,$CI16)=0,"",SUM($Q16,$V16,$AA16,$AF16,$AK16,$AP16,$AU16,$AZ16,$BE16,$BJ16,$BO16,$BT16,$BY16,$CD16,$CI16)) | L16: =IF(OR($F16="",$K16=""),"",$F16-$K16) | N16: =IF($M16="","",IFERROR(VLOOKUP(IFERROR(VLOOKUP(IF(ISNUMBER(FIND(" – ",$M16)),LEFT($M16,FIND(" – ",$M16)-1),$M16),ProdTbl,5,0),""),BasketTbl,2,0),"کد ناشناخته")) | O16: =IF($M16="","",IFERROR(VLOOKUP(IF(ISNUMBER(FIND(" – ",$M16)),LEFT($M16,FIND(" – ",$M16)-1),$M16),ProdTbl,3,0),"کد ناشناخته")) | S16: =IF($R16="","",IFERROR(VLOOKUP(IFERROR(VLOOKUP(IF(ISNUMBER(FIND(" – ",$R16)),LEFT($R16,FIND(" – ",$R16)-1),$R16),ProdTbl,5,0),""),BasketTbl,2,0),"کد ناشناخته")) | T16: =IF($R16="","",IFERROR(VLOOKUP(IF(ISNUMBER(FIND(" – ",$R16)),LEFT($R16,FIND(" – ",$R16)-1),$R16),ProdTbl,3,0),"کد ناشناخته")) | X16: =IF($W16="","",IFERROR(VLOOKUP(IFERROR(VLOOKUP(IF(ISNUMBER(FIND(" – ",$W16)),LEFT($W16,FIND(" – ",$W16)-1),$W16),ProdTbl,5,0),""),BasketTbl,2,0),"کد ناشناخته")) | Y16: =IF($W16="","",IFERROR(VLOOKUP(IF(ISNUMBER(FIND(" – ",$W16)),LEFT($W16,FIND(" – ",$W16)-1),$W16),ProdTbl,3,0),"کد ناشناخته")) | AC16: =IF($AB16="","",IFERROR(VLOOKUP(IFERROR(VLOOKUP(IF(ISNUMBER(FIND(" – ",$AB16)),LEFT($AB16,FIND(" – ",$AB16)-1),$AB16),ProdTbl,5,0),""),BasketTbl,2,0),"کد ناشناخته")) | AD16: =IF($AB16="","",IFERROR(VLOOKUP(IF(ISNUMBER(FIND(" – ",$AB16)),LEFT($AB16,FIND(" – ",$AB16)-1),$AB16),ProdTbl,3,0),"کد ناشناخته")) | AH16: =IF($AG16="","",IFERROR(VLOOKUP(IFERROR(VLOOKUP(IF(ISNUMBER(FIND(" – ",$AG16)),LEFT($AG16,FIND(" – ",$AG16)-1),$AG16),ProdTbl,5,0),""),BasketTbl,2,0),"کد ناشناخته")) | AI16: =IF($AG16="","",IFERROR(VLOOKUP(IF(ISNUMBER(FIND(" – ",$AG16)),LEFT($AG16,FIND(" – ",$AG16)-1),$AG16),ProdTbl,3,0),"کد ناشناخته")) | AM16: =IF($AL16="","",IFERROR(VLOOKUP(IFERROR(VLOOKUP(IF(ISNUMBER(FIND(" – ",$AL16)),LEFT($AL16,FIND(" – ",$AL16)-1),$AL16),ProdTbl,5,0),""),BasketTbl,2,0),"کد ناشناخته")) | AN16: =IF($AL16="","",IFERROR(VLOOKUP(IF(ISNUMBER(FIND(" – ",$AL16)),LEFT($AL16,FIND(" – ",$AL16)-1),$AL16),ProdTbl,3,0),"کد ناشناخته")) | AR16: =IF($AQ16="","",IFERROR(VLOOKUP(IFERROR(VLOOKUP(IF(ISNUMBER(FIND(" – ",$AQ16)),LEFT($AQ16,FIND(" – ",$AQ16)-1),$AQ16),ProdTbl,5,0),""),BasketTbl,2,0),"کد ناشناخته")) | AS16: =IF($AQ16="","",IFERROR(VLOOKUP(IF(ISNUMBER(FIND(" – ",$AQ16)),LEFT($AQ16,FIND(" – ",$AQ16)-1),$AQ16),ProdTbl,3,0),"کد ناشناخته")) | AW16: =IF($AV16="","",IFERROR(VLOOKUP(IFERROR(VLOOKUP(IF(ISNUMBER(FIND(" – ",$AV16)),LEFT($AV16,FIND(" – ",$AV16)-1),$AV16),ProdTbl,5,0),""),BasketTbl,2,0),"کد ناشناخته")) | AX16: =IF($AV16="","",IFERROR(VLOOKUP(IF(ISNUMBER(FIND(" – ",$AV16)),LEFT($AV16,FIND(" – ",$AV16)-1),$AV16),ProdTbl,3,0),"کد ناشناخته")) | BB16: =IF($BA16="","",IFERROR(VLOOKUP(IFERROR(VLOOKUP(IF(ISNUMBER(FIND(" – ",$BA16)),LEFT($BA16,FIND(" – ",$BA16)-1),$BA16),ProdTbl,5,0),""),BasketTbl,2,0),"کد ناشناخته")) | BC16: =IF($BA16="","",IFERROR(VLOOKUP(IF(ISNUMBER(FIND(" – ",$BA16)),LEFT($BA16,FIND(" – ",$BA16)-1),$BA16),ProdTbl,3,0),"کد ناشناخته")) | BG16: =IF($BF16="","",IFERROR(VLOOKUP(IFERROR(VLOOKUP(IF(ISNUMBER(FIND(" – ",$BF16)),LEFT($BF16,FIND(" – ",$BF16)-1),$BF16),ProdTbl,5,0),""),BasketTbl,2,0),"کد ناشناخته")) | BH16: =IF($BF16="","",IFERROR(VLOOKUP(IF(ISNUMBER(FIND(" – ",$BF16)),LEFT($BF16,FIND(" – ",$BF16)-1),$BF16),ProdTbl,3,0),"کد ناشناخته")) | BL16: =IF($BK16="","",IFERROR(VLOOKUP(IFERROR(VLOOKUP(IF(ISNUMBER(FIND(" – ",$BK16)),LEFT($BK16,FIND(" – ",$BK16)-1),$BK16),ProdTbl,5,0),""),BasketTbl,2,0),"کد ناشناخته")) | BM16: =IF($BK16="","",IFERROR(VLOOKUP(IF(ISNUMBER(FIND(" – ",$BK16)),LEFT($BK16,FIND(" – ",$BK16)-1),$BK16),ProdTbl,3,0),"کد ناشناخته")) | BQ16: =IF($BP16="","",IFERROR(VLOOKUP(IFERROR(VLOOKUP(IF(ISNUMBER(FIND(" – ",$BP16)),LEFT($BP16,FIND(" – ",$BP16)-1),$BP16),ProdTbl,5,0),""),BasketTbl,2,0),"کد ناشناخته")) | BR16: =IF($BP16="","",IFERROR(VLOOKUP(IF(ISNUMBER(FIND(" – ",$BP16)),LEFT($BP16,FIND(" – ",$BP16)-1),$BP16),ProdTbl,3,0),"کد ناشناخته")) | BV16: =IF($BU16="","",IFERROR(VLOOKUP(IFERROR(VLOOKUP(IF(ISNUMBER(FIND(" – ",$BU16)),LEFT($BU16,FIND(" – ",$BU16)-1),$BU16),ProdTbl,5,0),""),BasketTbl,2,0),"کد ناشناخته")) | BW16: =IF($BU16="","",IFERROR(VLOOKUP(IF(ISNUMBER(FIND(" – ",$BU16)),LEFT($BU16,FIND(" – ",$BU16)-1),$BU16),ProdTbl,3,0),"کد ناشناخته")) | CA16: =IF($BZ16="","",IFERROR(VLOOKUP(IFERROR(VLOOKUP(IF(ISNUMBER(FIND(" – ",$BZ16)),LEFT($BZ16,FIND(" – ",$BZ16)-1),$BZ16),ProdTbl,5,0),""),BasketTbl,2,0),"کد ناشناخته")) | CB16: =IF($BZ16="","",IFERROR(VLOOKUP(IF(ISNUMBER(FIND(" – ",$BZ16)),LEFT($BZ16,FIND(" – ",$BZ16)-1),$BZ16),ProdTbl,3,0),"کد ناشناخته")) | CF16: =IF($CE16="","",IFERROR(VLOOKUP(IFERROR(VLOOKUP(IF(ISNUMBER(FIND(" – ",$CE16)),LEFT($CE16,FIND(" – ",$CE16)-1),$CE16),ProdTbl,5,0),""),BasketTbl,2,0),"کد ناشناخته")) | CG16: =IF($CE16="","",IFERROR(VLOOKUP(IF(ISNUMBER(FIND(" – ",$CE16)),LEFT($CE16,FIND(" – ",$CE16)-1),$CE16),ProdTbl,3,0),"کد ناشناخته"))
A17: =IF($B17="","",COUNTA($B$10:$B17)) | E17: =IF($D17="","",IFERROR(VLOOKUP(IF(ISNUMBER(FIND(" – ",$D17)),LEFT($D17,FIND(" – ",$D17)-1),$D17),SellerTbl,2,0),"کد ناشناخته")) | I17: =IF(OR($F17="",$G17=""),"",$F17-$G17) | J17: =IF($I17="","",IF(ABS($I17)<=0.01*$F17,"√","×")) | K17: =IF(COUNT($Q17,$V17,$AA17,$AF17,$AK17,$AP17,$AU17,$AZ17,$BE17,$BJ17,$BO17,$BT17,$BY17,$CD17,$CI17)=0,"",SUM($Q17,$V17,$AA17,$AF17,$AK17,$AP17,$AU17,$AZ17,$BE17,$BJ17,$BO17,$BT17,$BY17,$CD17,$CI17)) | L17: =IF(OR($F17="",$K17=""),"",$F17-$K17) | N17: =IF($M17="","",IFERROR(VLOOKUP(IFERROR(VLOOKUP(IF(ISNUMBER(FIND(" – ",$M17)),LEFT($M17,FIND(" – ",$M17)-1),$M17),ProdTbl,5,0),""),BasketTbl,2,0),"کد ناشناخته")) | O17: =IF($M17="","",IFERROR(VLOOKUP(IF(ISNUMBER(FIND(" – ",$M17)),LEFT($M17,FIND(" – ",$M17)-1),$M17),ProdTbl,3,0),"کد ناشناخته")) | S17: =IF($R17="","",IFERROR(VLOOKUP(IFERROR(VLOOKUP(IF(ISNUMBER(FIND(" – ",$R17)),LEFT($R17,FIND(" – ",$R17)-1),$R17),ProdTbl,5,0),""),BasketTbl,2,0),"کد ناشناخته")) | T17: =IF($R17="","",IFERROR(VLOOKUP(IF(ISNUMBER(FIND(" – ",$R17)),LEFT($R17,FIND(" – ",$R17)-1),$R17),ProdTbl,3,0),"کد ناشناخته")) | X17: =IF($W17="","",IFERROR(VLOOKUP(IFERROR(VLOOKUP(IF(ISNUMBER(FIND(" – ",$W17)),LEFT($W17,FIND(" – ",$W17)-1),$W17),ProdTbl,5,0),""),BasketTbl,2,0),"کد ناشناخته")) | Y17: =IF($W17="","",IFERROR(VLOOKUP(IF(ISNUMBER(FIND(" – ",$W17)),LEFT($W17,FIND(" – ",$W17)-1),$W17),ProdTbl,3,0),"کد ناشناخته")) | AC17: =IF($AB17="","",IFERROR(VLOOKUP(IFERROR(VLOOKUP(IF(ISNUMBER(FIND(" – ",$AB17)),LEFT($AB17,FIND(" – ",$AB17)-1),$AB17),ProdTbl,5,0),""),BasketTbl,2,0),"کد ناشناخته")) | AD17: =IF($AB17="","",IFERROR(VLOOKUP(IF(ISNUMBER(FIND(" – ",$AB17)),LEFT($AB17,FIND(" – ",$AB17)-1),$AB17),ProdTbl,3,0),"کد ناشناخته")) | AH17: =IF($AG17="","",IFERROR(VLOOKUP(IFERROR(VLOOKUP(IF(ISNUMBER(FIND(" – ",$AG17)),LEFT($AG17,FIND(" – ",$AG17)-1),$AG17),ProdTbl,5,0),""),BasketTbl,2,0),"کد ناشناخته")) | AI17: =IF($AG17="","",IFERROR(VLOOKUP(IF(ISNUMBER(FIND(" – ",$AG17)),LEFT($AG17,FIND(" – ",$AG17)-1),$AG17),ProdTbl,3,0),"کد ناشناخته")) | AM17: =IF($AL17="","",IFERROR(VLOOKUP(IFERROR(VLOOKUP(IF(ISNUMBER(FIND(" – ",$AL17)),LEFT($AL17,FIND(" – ",$AL17)-1),$AL17),ProdTbl,5,0),""),BasketTbl,2,0),"کد ناشناخته")) | AN17: =IF($AL17="","",IFERROR(VLOOKUP(IF(ISNUMBER(FIND(" – ",$AL17)),LEFT($AL17,FIND(" – ",$AL17)-1),$AL17),ProdTbl,3,0),"کد ناشناخته")) | AR17: =IF($AQ17="","",IFERROR(VLOOKUP(IFERROR(VLOOKUP(IF(ISNUMBER(FIND(" – ",$AQ17)),LEFT($AQ17,FIND(" – ",$AQ17)-1),$AQ17),ProdTbl,5,0),""),BasketTbl,2,0),"کد ناشناخته")) | AS17: =IF($AQ17="","",IFERROR(VLOOKUP(IF(ISNUMBER(FIND(" – ",$AQ17)),LEFT($AQ17,FIND(" – ",$AQ17)-1),$AQ17),ProdTbl,3,0),"کد ناشناخته")) | AW17: =IF($AV17="","",IFERROR(VLOOKUP(IFERROR(VLOOKUP(IF(ISNUMBER(FIND(" – ",$AV17)),LEFT($AV17,FIND(" – ",$AV17)-1),$AV17),ProdTbl,5,0),""),BasketTbl,2,0),"کد ناشناخته")) | AX17: =IF($AV17="","",IFERROR(VLOOKUP(IF(ISNUMBER(FIND(" – ",$AV17)),LEFT($AV17,FIND(" – ",$AV17)-1),$AV17),ProdTbl,3,0),"کد ناشناخته")) | BB17: =IF($BA17="","",IFERROR(VLOOKUP(IFERROR(VLOOKUP(IF(ISNUMBER(FIND(" – ",$BA17)),LEFT($BA17,FIND(" – ",$BA17)-1),$BA17),ProdTbl,5,0),""),BasketTbl,2,0),"کد ناشناخته")) | BC17: =IF($BA17="","",IFERROR(VLOOKUP(IF(ISNUMBER(FIND(" – ",$BA17)),LEFT($BA17,FIND(" – ",$BA17)-1),$BA17),ProdTbl,3,0),"کد ناشناخته")) | BG17: =IF($BF17="","",IFERROR(VLOOKUP(IFERROR(VLOOKUP(IF(ISNUMBER(FIND(" – ",$BF17)),LEFT($BF17,FIND(" – ",$BF17)-1),$BF17),ProdTbl,5,0),""),BasketTbl,2,0),"کد ناشناخته")) | BH17: =IF($BF17="","",IFERROR(VLOOKUP(IF(ISNUMBER(FIND(" – ",$BF17)),LEFT($BF17,FIND(" – ",$BF17)-1),$BF17),ProdTbl,3,0),"کد ناشناخته")) | BL17: =IF($BK17="","",IFERROR(VLOOKUP(IFERROR(VLOOKUP(IF(ISNUMBER(FIND(" – ",$BK17)),LEFT($BK17,FIND(" – ",$BK17)-1),$BK17),ProdTbl,5,0),""),BasketTbl,2,0),"کد ناشناخته")) | BM17: =IF($BK17="","",IFERROR(VLOOKUP(IF(ISNUMBER(FIND(" – ",$BK17)),LEFT($BK17,FIND(" – ",$BK17)-1),$BK17),ProdTbl,3,0),"کد ناشناخته")) | BQ17: =IF($BP17="","",IFERROR(VLOOKUP(IFERROR(VLOOKUP(IF(ISNUMBER(FIND(" – ",$BP17)),LEFT($BP17,FIND(" – ",$BP17)-1),$BP17),ProdTbl,5,0),""),BasketTbl,2,0),"کد ناشناخته")) | BR17: =IF($BP17="","",IFERROR(VLOOKUP(IF(ISNUMBER(FIND(" – ",$BP17)),LEFT($BP17,FIND(" – ",$BP17)-1),$BP17),ProdTbl,3,0),"کد ناشناخته")) | BV17: =IF($BU17="","",IFERROR(VLOOKUP(IFERROR(VLOOKUP(IF(ISNUMBER(FIND(" – ",$BU17)),LEFT($BU17,FIND(" – ",$BU17)-1),$BU17),ProdTbl,5,0),""),BasketTbl,2,0),"کد ناشناخته")) | BW17: =IF($BU17="","",IFERROR(VLOOKUP(IF(ISNUMBER(FIND(" – ",$BU17)),LEFT($BU17,FIND(" – ",$BU17)-1),$BU17),ProdTbl,3,0),"کد ناشناخته")) | CA17: =IF($BZ17="","",IFERROR(VLOOKUP(IFERROR(VLOOKUP(IF(ISNUMBER(FIND(" – ",$BZ17)),LEFT($BZ17,FIND(" – ",$BZ17)-1),$BZ17),ProdTbl,5,0),""),BasketTbl,2,0),"کد ناشناخته")) | CB17: =IF($BZ17="","",IFERROR(VLOOKUP(IF(ISNUMBER(FIND(" – ",$BZ17)),LEFT($BZ17,FIND(" – ",$BZ17)-1),$BZ17),ProdTbl,3,0),"کد ناشناخته")) | CF17: =IF($CE17="","",IFERROR(VLOOKUP(IFERROR(VLOOKUP(IF(ISNUMBER(FIND(" – ",$CE17)),LEFT($CE17,FIND(" – ",$CE17)-1),$CE17),ProdTbl,5,0),""),BasketTbl,2,0),"کد ناشناخته")) | CG17: =IF($CE17="","",IFERROR(VLOOKUP(IF(ISNUMBER(FIND(" – ",$CE17)),LEFT($CE17,FIND(" – ",$CE17)-1),$CE17),ProdTbl,3,0),"کد ناشناخته"))
A18: =IF($B18="","",COUNTA($B$10:$B18)) | E18: =IF($D18="","",IFERROR(VLOOKUP(IF(ISNUMBER(FIND(" – ",$D18)),LEFT($D18,FIND(" – ",$D18)-1),$D18),SellerTbl,2,0),"کد ناشناخته")) | I18: =IF(OR($F18="",$G18=""),"",$F18-$G18) | J18: =IF($I18="","",IF(ABS($I18)<=0.01*$F18,"√","×")) | K18: =IF(COUNT($Q18,$V18,$AA18,$AF18,$AK18,$AP18,$AU18,$AZ18,$BE18,$BJ18,$BO18,$BT18,$BY18,$CD18,$CI18)=0,"",SUM($Q18,$V18,$AA18,$AF18,$AK18,$AP18,$AU18,$AZ18,$BE18,$BJ18,$BO18,$BT18,$BY18,$CD18,$CI18)) | L18: =IF(OR($F18="",$K18=""),"",$F18-$K18) | N18: =IF($M18="","",IFERROR(VLOOKUP(IFERROR(VLOOKUP(IF(ISNUMBER(FIND(" – ",$M18)),LEFT($M18,FIND(" – ",$M18)-1),$M18),ProdTbl,5,0),""),BasketTbl,2,0),"کد ناشناخته")) | O18: =IF($M18="","",IFERROR(VLOOKUP(IF(ISNUMBER(FIND(" – ",$M18)),LEFT($M18,FIND(" – ",$M18)-1),$M18),ProdTbl,3,0),"کد ناشناخته")) | S18: =IF($R18="","",IFERROR(VLOOKUP(IFERROR(VLOOKUP(IF(ISNUMBER(FIND(" – ",$R18)),LEFT($R18,FIND(" – ",$R18)-1),$R18),ProdTbl,5,0),""),BasketTbl,2,0),"کد ناشناخته")) | T18: =IF($R18="","",IFERROR(VLOOKUP(IF(ISNUMBER(FIND(" – ",$R18)),LEFT($R18,FIND(" – ",$R18)-1),$R18),ProdTbl,3,0),"کد ناشناخته")) | X18: =IF($W18="","",IFERROR(VLOOKUP(IFERROR(VLOOKUP(IF(ISNUMBER(FIND(" – ",$W18)),LEFT($W18,FIND(" – ",$W18)-1),$W18),ProdTbl,5,0),""),BasketTbl,2,0),"کد ناشناخته")) | Y18: =IF($W18="","",IFERROR(VLOOKUP(IF(ISNUMBER(FIND(" – ",$W18)),LEFT($W18,FIND(" – ",$W18)-1),$W18),ProdTbl,3,0),"کد ناشناخته")) | AC18: =IF($AB18="","",IFERROR(VLOOKUP(IFERROR(VLOOKUP(IF(ISNUMBER(FIND(" – ",$AB18)),LEFT($AB18,FIND(" – ",$AB18)-1),$AB18),ProdTbl,5,0),""),BasketTbl,2,0),"کد ناشناخته")) | AD18: =IF($AB18="","",IFERROR(VLOOKUP(IF(ISNUMBER(FIND(" – ",$AB18)),LEFT($AB18,FIND(" – ",$AB18)-1),$AB18),ProdTbl,3,0),"کد ناشناخته")) | AH18: =IF($AG18="","",IFERROR(VLOOKUP(IFERROR(VLOOKUP(IF(ISNUMBER(FIND(" – ",$AG18)),LEFT($AG18,FIND(" – ",$AG18)-1),$AG18),ProdTbl,5,0),""),BasketTbl,2,0),"کد ناشناخته")) | AI18: =IF($AG18="","",IFERROR(VLOOKUP(IF(ISNUMBER(FIND(" – ",$AG18)),LEFT($AG18,FIND(" – ",$AG18)-1),$AG18),ProdTbl,3,0),"کد ناشناخته")) | AM18: =IF($AL18="","",IFERROR(VLOOKUP(IFERROR(VLOOKUP(IF(ISNUMBER(FIND(" – ",$AL18)),LEFT($AL18,FIND(" – ",$AL18)-1),$AL18),ProdTbl,5,0),""),BasketTbl,2,0),"کد ناشناخته")) | AN18: =IF($AL18="","",IFERROR(VLOOKUP(IF(ISNUMBER(FIND(" – ",$AL18)),LEFT($AL18,FIND(" – ",$AL18)-1),$AL18),ProdTbl,3,0),"کد ناشناخته")) | AR18: =IF($AQ18="","",IFERROR(VLOOKUP(IFERROR(VLOOKUP(IF(ISNUMBER(FIND(" – ",$AQ18)),LEFT($AQ18,FIND(" – ",$AQ18)-1),$AQ18),ProdTbl,5,0),""),BasketTbl,2,0),"کد ناشناخته")) | AS18: =IF($AQ18="","",IFERROR(VLOOKUP(IF(ISNUMBER(FIND(" – ",$AQ18)),LEFT($AQ18,FIND(" – ",$AQ18)-1),$AQ18),ProdTbl,3,0),"کد ناشناخته")) | AW18: =IF($AV18="","",IFERROR(VLOOKUP(IFERROR(VLOOKUP(IF(ISNUMBER(FIND(" – ",$AV18)),LEFT($AV18,FIND(" – ",$AV18)-1),$AV18),ProdTbl,5,0),""),BasketTbl,2,0),"کد ناشناخته")) | AX18: =IF($AV18="","",IFERROR(VLOOKUP(IF(ISNUMBER(FIND(" – ",$AV18)),LEFT($AV18,FIND(" – ",$AV18)-1),$AV18),ProdTbl,3,0),"کد ناشناخته")) | BB18: =IF($BA18="","",IFERROR(VLOOKUP(IFERROR(VLOOKUP(IF(ISNUMBER(FIND(" – ",$BA18)),LEFT($BA18,FIND(" – ",$BA18)-1),$BA18),ProdTbl,5,0),""),BasketTbl,2,0),"کد ناشناخته")) | BC18: =IF($BA18="","",IFERROR(VLOOKUP(IF(ISNUMBER(FIND(" – ",$BA18)),LEFT($BA18,FIND(" – ",$BA18)-1),$BA18),ProdTbl,3,0),"کد ناشناخته")) | BG18: =IF($BF18="","",IFERROR(VLOOKUP(IFERROR(VLOOKUP(IF(ISNUMBER(FIND(" – ",$BF18)),LEFT($BF18,FIND(" – ",$BF18)-1),$BF18),ProdTbl,5,0),""),BasketTbl,2,0),"کد ناشناخته")) | BH18: =IF($BF18="","",IFERROR(VLOOKUP(IF(ISNUMBER(FIND(" – ",$BF18)),LEFT($BF18,FIND(" – ",$BF18)-1),$BF18),ProdTbl,3,0),"کد ناشناخته")) | BL18: =IF($BK18="","",IFERROR(VLOOKUP(IFERROR(VLOOKUP(IF(ISNUMBER(FIND(" – ",$BK18)),LEFT($BK18,FIND(" – ",$BK18)-1),$BK18),ProdTbl,5,0),""),BasketTbl,2,0),"کد ناشناخته")) | BM18: =IF($BK18="","",IFERROR(VLOOKUP(IF(ISNUMBER(FIND(" – ",$BK18)),LEFT($BK18,FIND(" – ",$BK18)-1),$BK18),ProdTbl,3,0),"کد ناشناخته")) | BQ18: =IF($BP18="","",IFERROR(VLOOKUP(IFERROR(VLOOKUP(IF(ISNUMBER(FIND(" – ",$BP18)),LEFT($BP18,FIND(" – ",$BP18)-1),$BP18),ProdTbl,5,0),""),BasketTbl,2,0),"کد ناشناخته")) | BR18: =IF($BP18="","",IFERROR(VLOOKUP(IF(ISNUMBER(FIND(" – ",$BP18)),LEFT($BP18,FIND(" – ",$BP18)-1),$BP18),ProdTbl,3,0),"کد ناشناخته")) | BV18: =IF($BU18="","",IFERROR(VLOOKUP(IFERROR(VLOOKUP(IF(ISNUMBER(FIND(" – ",$BU18)),LEFT($BU18,FIND(" – ",$BU18)-1),$BU18),ProdTbl,5,0),""),BasketTbl,2,0),"کد ناشناخته")) | BW18: =IF($BU18="","",IFERROR(VLOOKUP(IF(ISNUMBER(FIND(" – ",$BU18)),LEFT($BU18,FIND(" – ",$BU18)-1),$BU18),ProdTbl,3,0),"کد ناشناخته")) | CA18: =IF($BZ18="","",IFERROR(VLOOKUP(IFERROR(VLOOKUP(IF(ISNUMBER(FIND(" – ",$BZ18)),LEFT($BZ18,FIND(" – ",$BZ18)-1),$BZ18),ProdTbl,5,0),""),BasketTbl,2,0),"کد ناشناخته")) | CB18: =IF($BZ18="","",IFERROR(VLOOKUP(IF(ISNUMBER(FIND(" – ",$BZ18)),LEFT($BZ18,FIND(" – ",$BZ18)-1),$BZ18),ProdTbl,3,0),"کد ناشناخته")) | CF18: =IF($CE18="","",IFERROR(VLOOKUP(IFERROR(VLOOKUP(IF(ISNUMBER(FIND(" – ",$CE18)),LEFT($CE18,FIND(" – ",$CE18)-1),$CE18),ProdTbl,5,0),""),BasketTbl,2,0),"کد ناشناخته")) | CG18: =IF($CE18="","",IFERROR(VLOOKUP(IF(ISNUMBER(FIND(" – ",$CE18)),LEFT($CE18,FIND(" – ",$CE18)-1),$CE18),ProdTbl,3,0),"کد ناشناخته"))
A19: =IF($B19="","",COUNTA($B$10:$B19)) | E19: =IF($D19="","",IFERROR(VLOOKUP(IF(ISNUMBER(FIND(" – ",$D19)),LEFT($D19,FIND(" – ",$D19)-1),$D19),SellerTbl,2,0),"کد ناشناخته")) | I19: =IF(OR($F19="",$G19=""),"",$F19-$G19) | J19: =IF($I19="","",IF(ABS($I19)<=0.01*$F19,"√","×")) | K19: =IF(COUNT($Q19,$V19,$AA19,$AF19,$AK19,$AP19,$AU19,$AZ19,$BE19,$BJ19,$BO19,$BT19,$BY19,$CD19,$CI19)=0,"",SUM($Q19,$V19,$AA19,$AF19,$AK19,$AP19,$AU19,$AZ19,$BE19,$BJ19,$BO19,$BT19,$BY19,$CD19,$CI19)) | L19: =IF(OR($F19="",$K19=""),"",$F19-$K19) | N19: =IF($M19="","",IFERROR(VLOOKUP(IFERROR(VLOOKUP(IF(ISNUMBER(FIND(" – ",$M19)),LEFT($M19,FIND(" – ",$M19)-1),$M19),ProdTbl,5,0),""),BasketTbl,2,0),"کد ناشناخته")) | O19: =IF($M19="","",IFERROR(VLOOKUP(IF(ISNUMBER(FIND(" – ",$M19)),LEFT($M19,FIND(" – ",$M19)-1),$M19),ProdTbl,3,0),"کد ناشناخته")) | S19: =IF($R19="","",IFERROR(VLOOKUP(IFERROR(VLOOKUP(IF(ISNUMBER(FIND(" – ",$R19)),LEFT($R19,FIND(" – ",$R19)-1),$R19),ProdTbl,5,0),""),BasketTbl,2,0),"کد ناشناخته")) | T19: =IF($R19="","",IFERROR(VLOOKUP(IF(ISNUMBER(FIND(" – ",$R19)),LEFT($R19,FIND(" – ",$R19)-1),$R19),ProdTbl,3,0),"کد ناشناخته")) | X19: =IF($W19="","",IFERROR(VLOOKUP(IFERROR(VLOOKUP(IF(ISNUMBER(FIND(" – ",$W19)),LEFT($W19,FIND(" – ",$W19)-1),$W19),ProdTbl,5,0),""),BasketTbl,2,0),"کد ناشناخته")) | Y19: =IF($W19="","",IFERROR(VLOOKUP(IF(ISNUMBER(FIND(" – ",$W19)),LEFT($W19,FIND(" – ",$W19)-1),$W19),ProdTbl,3,0),"کد ناشناخته")) | AC19: =IF($AB19="","",IFERROR(VLOOKUP(IFERROR(VLOOKUP(IF(ISNUMBER(FIND(" – ",$AB19)),LEFT($AB19,FIND(" – ",$AB19)-1),$AB19),ProdTbl,5,0),""),BasketTbl,2,0),"کد ناشناخته")) | AD19: =IF($AB19="","",IFERROR(VLOOKUP(IF(ISNUMBER(FIND(" – ",$AB19)),LEFT($AB19,FIND(" – ",$AB19)-1),$AB19),ProdTbl,3,0),"کد ناشناخته")) | AH19: =IF($AG19="","",IFERROR(VLOOKUP(IFERROR(VLOOKUP(IF(ISNUMBER(FIND(" – ",$AG19)),LEFT($AG19,FIND(" – ",$AG19)-1),$AG19),ProdTbl,5,0),""),BasketTbl,2,0),"کد ناشناخته")) | AI19: =IF($AG19="","",IFERROR(VLOOKUP(IF(ISNUMBER(FIND(" – ",$AG19)),LEFT($AG19,FIND(" – ",$AG19)-1),$AG19),ProdTbl,3,0),"کد ناشناخته")) | AM19: =IF($AL19="","",IFERROR(VLOOKUP(IFERROR(VLOOKUP(IF(ISNUMBER(FIND(" – ",$AL19)),LEFT($AL19,FIND(" – ",$AL19)-1),$AL19),ProdTbl,5,0),""),BasketTbl,2,0),"کد ناشناخته")) | AN19: =IF($AL19="","",IFERROR(VLOOKUP(IF(ISNUMBER(FIND(" – ",$AL19)),LEFT($AL19,FIND(" – ",$AL19)-1),$AL19),ProdTbl,3,0),"کد ناشناخته")) | AR19: =IF($AQ19="","",IFERROR(VLOOKUP(IFERROR(VLOOKUP(IF(ISNUMBER(FIND(" – ",$AQ19)),LEFT($AQ19,FIND(" – ",$AQ19)-1),$AQ19),ProdTbl,5,0),""),BasketTbl,2,0),"کد ناشناخته")) | AS19: =IF($AQ19="","",IFERROR(VLOOKUP(IF(ISNUMBER(FIND(" – ",$AQ19)),LEFT($AQ19,FIND(" – ",$AQ19)-1),$AQ19),ProdTbl,3,0),"کد ناشناخته")) | AW19: =IF($AV19="","",IFERROR(VLOOKUP(IFERROR(VLOOKUP(IF(ISNUMBER(FIND(" – ",$AV19)),LEFT($AV19,FIND(" – ",$AV19)-1),$AV19),ProdTbl,5,0),""),BasketTbl,2,0),"کد ناشناخته")) | AX19: =IF($AV19="","",IFERROR(VLOOKUP(IF(ISNUMBER(FIND(" – ",$AV19)),LEFT($AV19,FIND(" – ",$AV19)-1),$AV19),ProdTbl,3,0),"کد ناشناخته")) | BB19: =IF($BA19="","",IFERROR(VLOOKUP(IFERROR(VLOOKUP(IF(ISNUMBER(FIND(" – ",$BA19)),LEFT($BA19,FIND(" – ",$BA19)-1),$BA19),ProdTbl,5,0),""),BasketTbl,2,0),"کد ناشناخته")) | BC19: =IF($BA19="","",IFERROR(VLOOKUP(IF(ISNUMBER(FIND(" – ",$BA19)),LEFT($BA19,FIND(" – ",$BA19)-1),$BA19),ProdTbl,3,0),"کد ناشناخته")) | BG19: =IF($BF19="","",IFERROR(VLOOKUP(IFERROR(VLOOKUP(IF(ISNUMBER(FIND(" – ",$BF19)),LEFT($BF19,FIND(" – ",$BF19)-1),$BF19),ProdTbl,5,0),""),BasketTbl,2,0),"کد ناشناخته")) | BH19: =IF($BF19="","",IFERROR(VLOOKUP(IF(ISNUMBER(FIND(" – ",$BF19)),LEFT($BF19,FIND(" – ",$BF19)-1),$BF19),ProdTbl,3,0),"کد ناشناخته")) | BL19: =IF($BK19="","",IFERROR(VLOOKUP(IFERROR(VLOOKUP(IF(ISNUMBER(FIND(" – ",$BK19)),LEFT($BK19,FIND(" – ",$BK19)-1),$BK19),ProdTbl,5,0),""),BasketTbl,2,0),"کد ناشناخته")) | BM19: =IF($BK19="","",IFERROR(VLOOKUP(IF(ISNUMBER(FIND(" – ",$BK19)),LEFT($BK19,FIND(" – ",$BK19)-1),$BK19),ProdTbl,3,0),"کد ناشناخته")) | BQ19: =IF($BP19="","",IFERROR(VLOOKUP(IFERROR(VLOOKUP(IF(ISNUMBER(FIND(" – ",$BP19)),LEFT($BP19,FIND(" – ",$BP19)-1),$BP19),ProdTbl,5,0),""),BasketTbl,2,0),"کد ناشناخته")) | BR19: =IF($BP19="","",IFERROR(VLOOKUP(IF(ISNUMBER(FIND(" – ",$BP19)),LEFT($BP19,FIND(" – ",$BP19)-1),$BP19),ProdTbl,3,0),"کد ناشناخته")) | BV19: =IF($BU19="","",IFERROR(VLOOKUP(IFERROR(VLOOKUP(IF(ISNUMBER(FIND(" – ",$BU19)),LEFT($BU19,FIND(" – ",$BU19)-1),$BU19),ProdTbl,5,0),""),BasketTbl,2,0),"کد ناشناخته")) | BW19: =IF($BU19="","",IFERROR(VLOOKUP(IF(ISNUMBER(FIND(" – ",$BU19)),LEFT($BU19,FIND(" – ",$BU19)-1),$BU19),ProdTbl,3,0),"کد ناشناخته")) | CA19: =IF($BZ19="","",IFERROR(VLOOKUP(IFERROR(VLOOKUP(IF(ISNUMBER(FIND(" – ",$BZ19)),LEFT($BZ19,FIND(" – ",$BZ19)-1),$BZ19),ProdTbl,5,0),""),BasketTbl,2,0),"کد ناشناخته")) | CB19: =IF($BZ19="","",IFERROR(VLOOKUP(IF(ISNUMBER(FIND(" – ",$BZ19)),LEFT($BZ19,FIND(" – ",$BZ19)-1),$BZ19),ProdTbl,3,0),"کد ناشناخته")) | CF19: =IF($CE19="","",IFERROR(VLOOKUP(IFERROR(VLOOKUP(IF(ISNUMBER(FIND(" – ",$CE19)),LEFT($CE19,FIND(" – ",$CE19)-1),$CE19),ProdTbl,5,0),""),BasketTbl,2,0),"کد ناشناخته")) | CG19: =IF($CE19="","",IFERROR(VLOOKUP(IF(ISNUMBER(FIND(" – ",$CE19)),LEFT($CE19,FIND(" – ",$CE19)-1),$CE19),ProdTbl,3,0),"کد ناشناخته"))
